Workbook

Sheet Delivery_Log
A1: S&K OIL SALES — DELIVERY LOG ↓ Append new deliveries in date order
A2: Add rows in chronological order (oldest first). Optimizer_Input updates automatically. Do NOT re-sort.
A3: Date | B3: Customer | C3: Zone | D3: Zone Code | E3: Product | F3: Tank (lbs) | G3: Qty Delivered (lbs) | H3: Days Since Last | I3: Lbs/Day This Delivery | J3: Invoice # | K3: Running Avg Lbs/Day ←auto | L3: Name Check
A4: 45955 | B4: AME - 1073 - AMELIO C ENTERPRISES, INC (CACTUS CANDY) | C4: =IF(B4="","",IFERROR(INDEX(Client_List!$C:$C,MATCH(B4,Client_List!$B:$B,0)),"")) -> 4 | D4: =IF(B4="","",IFERROR(INDEX(Client_List!$D:$D,MATCH(B4,Client_List!$B:$B,0)),"")) -> 4C | E4: =IF(B4="","",IFERROR(INDEX(Client_List!$K:$K,MATCH(B4,Client_List!$B:$B,0)),"")) -> CANOLA OIL | F4: =IF(B4="","",IFERROR(INDEX(Client_List!$J:$J,MATCH(B4,Client_List!$B:$B,0)),"")) -> 2000 | G4: 1903 | H4: =IF(B4="","",IFERROR(A4-LOOKUP(2,1/($B3:$B$4=B4),$A3:$A$4),"")) -> 0 | I4: =IF(B4="","",IFERROR(G4/H4,"")) | J4: 7825-1 | K4: =IF(B4="","",IFERROR(AVERAGEIFS($I$4:$I4,$B$4:$B4,B4,$I$4:$I4,">"&0),"")) | L4: =IF(B4="","",IF(ISNA(MATCH(B4,Client_List!$B:$B,0)),"⚠ NOT FOUND","✓")) -> ✓
A5: 45965 | B5: SHA - 19107 - SHARKO'S CATERING | C5: =IF(B5="","",IFERROR(INDEX(Client_List!$C:$C,MATCH(B5,Client_List!$B:$B,0)),"")) -> 3 | D5: =IF(B5="","",IFERROR(INDEX(Client_List!$D:$D,MATCH(B5,Client_List!$B:$B,0)),"")) -> 3D | E5: =IF(B5="","",IFERROR(INDEX(Client_List!$K:$K,MATCH(B5,Client_List!$B:$B,0)),"")) -> CANOLA OIL | F5: =IF(B5="","",IFERROR(INDEX(Client_List!$J:$J,MATCH(B5,Client_List!$B:$B,0)),"")) -> 450 | G5: 228 | H5: =IF(B5="","",IFERROR(A5-LOOKUP(2,1/($B$4:$B4=B5),$A$4:$A4),"")) | I5: =IF(B5="","",IFERROR(G5/H5,"")) | J5: 141811 | K5: =IF(B5="","",IFERROR(AVERAGEIFS($I$4:$I5,$B$4:$B5,B5,$I$4:$I5,">"&0),"")) | L5: =IF(B5="","",IF(ISNA(MATCH(B5,Client_List!$B:$B,0)),"⚠ NOT FOUND","✓")) -> ✓
A6: 46024 | B6: ATL - 1083 - ATL WINGS MESA | C6: =IF(B6="","",IFERROR(INDEX(Client_List!$C:$C,MATCH(B6,Client_List!$B:$B,0)),"")) -> 5 | D6: =IF(B6="","",IFERROR(INDEX(Client_List!$D:$D,MATCH(B6,Client_List!$B:$B,0)),"")) -> 5D | E6: =IF(B6="","",IFERROR(INDEX(Client_List!$K:$K,MATCH(B6,Client_List!$B:$B,0)),"")) -> CANOLA OIL | F6: =IF(B6="","",IFERROR(INDEX(Client_List!$J:$J,MATCH(B6,Client_List!$B:$B,0)),"")) -> 425 | G6: 354 | H6: =IF(B6="","",IFERROR(A6-LOOKUP(2,1/($B$4:$B5=B6),$A$4:$A5),"")) | I6: =IF(B6="","",IFERROR(G6/H6,"")) | J6: 140983 | K6: =IF(B6="","",IFERROR(AVERAGEIFS($I$4:$I6,$B$4:$B6,B6,$I$4:$I6,">"&0),"")) | L6: =IF(B6="","",IF(ISNA(MATCH(B6,Client_List!$B:$B,0)),"⚠ NOT FOUND","✓")) -> ✓
A7: 46024 | B7: CAR - 3063 - CARDINAL STADIUM | C7: =IF(B7="","",IFERROR(INDEX(Client_List!$C:$C,MATCH(B7,Client_List!$B:$B,0)),"")) -> 2 | D7: =IF(B7="","",IFERROR(INDEX(Client_List!$D:$D,MATCH(B7,Client_List!$B:$B,0)),"")) -> 2D | E7: =IF(B7="","",IFERROR(INDEX(Client_List!$K:$K,MATCH(B7,Client_List!$B:$B,0)),"")) -> CANOLA OIL | F7: =IF(B7="","",IFERROR(INDEX(Client_List!$J:$J,MATCH(B7,Client_List!$B:$B,0)),"")) -> 2500 | G7: 1596 | H7: =IF(B7="","",IFERROR(A7-LOOKUP(2,1/($B$4:$B6=B7),$A$4:$A6),"")) | I7: =IF(B7="","",IFERROR(G7/H7,"")) | J7: 140988 | K7: =IF(B7="","",IFERROR(AVERAGEIFS($I$4:$I7,$B$4:$B7,B7,$I$4:$I7,">"&0),"")) | L7: =IF(B7="","",IF(ISNA(MATCH(B7,Client_List!$B:$B,0)),"⚠ NOT FOUND","✓")) -> ✓
A8: 46024 | B8: DAR 4037 - DARUMA RAMEN AND BOWL | C8: =IF(B8="","",IFERROR(INDEX(Client_List!$C:$C,MATCH(B8,Client_List!$B:$B,0)),"")) -> 4 | D8: =IF(B8="","",IFERROR(INDEX(Client_List!$D:$D,MATCH(B8,Client_List!$B:$B,0)),"")) -> 4E | E8: =IF(B8="","",IFERROR(INDEX(Client_List!$K:$K,MATCH(B8,Client_List!$B:$B,0)),"")) -> CANOLA OIL | F8: =IF(B8="","",IFERROR(INDEX(Client_List!$J:$J,MATCH(B8,Client_List!$B:$B,0)),"")) -> 350 | G8: 361 | H8: =IF(B8="","",IFERROR(A8-LOOKUP(2,1/($B$4:$B7=B8),$A$4:$A7),"")) | I8: =IF(B8="","",IFERROR(G8/H8,"")) | J8: 140985 | K8: =IF(B8="","",IFERROR(AVERAGEIFS($I$4:$I8,$B$4:$B8,B8,$I$4:$I8,">"&0),"")) | L8: =IF(B8="","",IF(ISNA(MATCH(B8,Client_List!$B:$B,0)),"⚠ NOT FOUND","✓")) -> ✓
A9: 46024 | B9: HAR - 8031 - HAROLDS | C9: =IF(B9="","",IFERROR(INDEX(Client_List!$C:$C,MATCH(B9,Client_List!$B:$B,0)),"")) -> 4 | D9: =IF(B9="","",IFERROR(INDEX(Client_List!$D:$D,MATCH(B9,Client_List!$B:$B,0)),"")) -> 4A | E9: =IF(B9="","",IFERROR(INDEX(Client_List!$K:$K,MATCH(B9,Client_List!$B:$B,0)),"")) -> FRYERS CHOICE BLEND | F9: =IF(B9="","",IFERROR(INDEX(Client_List!$J:$J,MATCH(B9,Client_List!$B:$B,0)),"")) -> 1050 | G9: 705 | H9: =IF(B9="","",IFERROR(A9-LOOKUP(2,1/($B$4:$B8=B9),$A$4:$A8),"")) | I9: =IF(B9="","",IFERROR(G9/H9,"")) | J9: 140986 | K9: =IF(B9="","",IFERROR(AVERAGEIFS($I$4:$I9,$B$4:$B9,B9,$I$4:$I9,">"&0),"")) | L9: =IF(B9="","",IF(ISNA(MATCH(B9,Client_List!$B:$B,0)),"⚠ NOT FOUND","✓")) -> ✓
A10: 46024 | B10: JALS - 10001 - JALAPENOS INFERNO SCOTTS | C10: =IF(B10="","",IFERROR(INDEX(Client_List!$C:$C,MATCH(B10,Client_List!$B:$B,0)),"")) -> 4 | D10: =IF(B10="","",IFERROR(INDEX(Client_List!$D:$D,MATCH(B10,Client_List!$B:$B,0)),"")) -> 4B | E10: =IF(B10="","",IFERROR(INDEX(Client_List!$K:$K,MATCH(B10,Client_List!$B:$B,0)),"")) -> FRYERS CHOICE BLEND | F10: =IF(B10="","",IFERROR(INDEX(Client_List!$J:$J,MATCH(B10,Client_List!$B:$B,0)),"")) -> 950 | G10: 882 | H10: =IF(B10="","",IFERROR(A10-LOOKUP(2,1/($B$4:$B9=B10),$A$4:$A9),"")) | I10: =IF(B10="","",IFERROR(G10/H10,"")) | J10: 140987 | K10: =IF(B10="","",IFERROR(AVERAGEIFS($I$4:$I10,$B$4:$B10,B10,$I$4:$I10,">"&0),"")) | L10: =IF(B10="","",IF(ISNA(MATCH(B10,Client_List!$B:$B,0)),"⚠ NOT FOUND","✓")) -> ✓
A11: 46024 | B11: NOU - 14008 - NOURISH KITCHEN | C11: =IF(B11="","",IFERROR(INDEX(Client_List!$C:$C,MATCH(B11,Client_List!$B:$B,0)),"")) -> 4 | D11: =IF(B11="","",IFERROR(INDEX(Client_List!$D:$D,MATCH(B11,Client_List!$B:$B,0)),"")) -> 4E | E11: =IF(B11="","",IFERROR(INDEX(Client_List!$K:$K,MATCH(B11,Client_List!$B:$B,0)),"")) -> CANOLA OIL | F11: =IF(B11="","",IFERROR(INDEX(Client_List!$J:$J,MATCH(B11,Client_List!$B:$B,0)),"")) -> 2000 | G11: 1151 | H11: =IF(B11="","",IFERROR(A11-LOOKUP(2,1/($B$4:$B10=B11),$A$4:$A10),"")) | I11: =IF(B11="","",IFERROR(G11/H11,"")) | J11: 140984 | K11: =IF(B11="","",IFERROR(AVERAGEIFS($I$4:$I11,$B$4:$B11,B11,$I$4:$I11,">"&0),"")) | L11: =IF(B11="","",IF(ISNA(MATCH(B11,Client_List!$B:$B,0)),"⚠ NOT FOUND","✓")) -> ✓
A12: 46024 | B12: OHS - 15035 - OHSO GILBERT | C12: =IF(B12="","",IFERROR(INDEX(Client_List!$C:$C,MATCH(B12,Client_List!$B:$B,0)),"")) -> 5 | D12: =IF(B12="","",IFERROR(INDEX(Client_List!$D:$D,MATCH(B12,Client_List!$B:$B,0)),"")) -> 5E | E12: =IF(B12="","",IFERROR(INDEX(Client_List!$K:$K,MATCH(B12,Client_List!$B:$B,0)),"")) -> CANOLA OIL | F12: =IF(B12="","",IFERROR(INDEX(Client_List!$J:$J,MATCH(B12,Client_List!$B:$B,0)),"")) -> 1800 | G12: 1401 | H12: =IF(B12="","",IFERROR(A12-LOOKUP(2,1/($B$4:$B11=B12),$A$4:$A11),"")) | I12: =IF(B12="","",IFERROR(G12/H12,"")) | J12: 140981 | K12: =IF(B12="","",IFERROR(AVERAGEIFS($I$4:$I12,$B$4:$B12,B12,$I$4:$I12,">"&0),"")) | L12: =IF(B12="","",IF(ISNA(MATCH(B12,Client_List!$B:$B,0)),"⚠ NOT FOUND","✓")) -> ✓
A13: 46024 | B13: PETTOL - 16010 - PETES TOLLESON | C13: =IF(B13="","",IFERROR(INDEX(Client_List!$C:$C,MATCH(B13,Client_List!$B:$B,0)),"")) -> 2 | D13: =IF(B13="","",IFERROR(INDEX(Client_List!$D:$D,MATCH(B13,Client_List!$B:$B,0)),"")) -> 2E | E13: =IF(B13="","",IFERROR(INDEX(Client_List!$K:$K,MATCH(B13,Client_List!$B:$B,0)),"")) -> FRYERS CHOICE BLEND | F13: =IF(B13="","",IFERROR(INDEX(Client_List!$J:$J,MATCH(B13,Client_List!$B:$B,0)),"")) -> 1950 | G13: 1737 | H13: =IF(B13="","",IFERROR(A13-LOOKUP(2,1/($B$4:$B12=B13),$A$4:$A12),"")) | I13: =IF(B13="","",IFERROR(G13/H13,"")) | J13: 140982 | K13: =IF(B13="","",IFERROR(AVERAGEIFS($I$4:$I13,$B$4:$B13,B13,$I$4:$I13,">"&0),"")) | L13: =IF(B13="","",IF(ISNA(MATCH(B13,Client_List!$B:$B,0)),"⚠ NOT FOUND","✓")) -> ✓
A14: 46025 | B14: ANG - 1057 - ANGRY CRAB TUCSON | C14: =IF(B14="","",IFERROR(INDEX(Client_List!$C:$C,MATCH(B14,Client_List!$B:$B,0)),"")) -> 0 | D14: =IF(B14="","",IFERROR(INDEX(Client_List!$D:$D,MATCH(B14,Client_List!$B:$B,0)),"")) -> TU | E14: =IF(B14="","",IFERROR(INDEX(Client_List!$K:$K,MATCH(B14,Client_List!$B:$B,0)),"")) -> FRYERS CHOICE BLEND | F14: =IF(B14="","",IFERROR(INDEX(Client_List!$J:$J,MATCH(B14,Client_List!$B:$B,0)),"")) -> 1000 | G14: 591 | H14: =IF(B14="","",IFERROR(A14-LOOKUP(2,1/($B$4:$B13=B14),$A$4:$A13),"")) | I14: =IF(B14="","",IFERROR(G14/H14,"")) | J14: 141024 | K14: =IF(B14="","",IFERROR(AVERAGEIFS($I$4:$I14,$B$4:$B14,B14,$I$4:$I14,">"&0),"")) | L14: =IF(B14="","",IF(ISNA(MATCH(B14,Client_List!$B:$B,0)),"⚠ NOT FOUND","✓")) -> ✓
A15: 46025 | B15: BOO - 2016 - BOOTY'S SURPRISE | C15: =IF(B15="","",IFERROR(INDEX(Client_List!$C:$C,MATCH(B15,Client_List!$B:$B,0)),"")) -> 0 | D15: =IF(B15="","",IFERROR(INDEX(Client_List!$D:$D,MATCH(B15,Client_List!$B:$B,0)),"")) -> 0 | E15: =IF(B15="","",IFERROR(INDEX(Client_List!$K:$K,MATCH(B15,Client_List!$B:$B,0)),"")) -> CANOLA OIL | F15: =IF(B15="","",IFERROR(INDEX(Client_List!$J:$J,MATCH(B15,Client_List!$B:$B,0)),"")) -> 700 | G15: 265 | H15: =IF(B15="","",IFERROR(A15-LOOKUP(2,1/($B$4:$B14=B15),$A$4:$A14),"")) | I15: =IF(B15="","",IFERROR(G15/H15,"")) | J15: 141011 | K15: =IF(B15="","",IFERROR(AVERAGEIFS($I$4:$I15,$B$4:$B15,B15,$I$4:$I15,">"&0),"")) | L15: =IF(B15="","",IF(ISNA(MATCH(B15,Client_List!$B:$B,0)),"⚠ NOT FOUND","✓")) -> ✓
A16: 46025 | B16: CHA - 3056 - CHARLEYS AT THE LAKE | C16: =IF(B16="","",IFERROR(INDEX(Client_List!$C:$C,MATCH(B16,Client_List!$B:$B,0)),"")) -> 2 | D16: =IF(B16="","",IFERROR(INDEX(Client_List!$D:$D,MATCH(B16,Client_List!$B:$B,0)),"")) -> 2C | E16: =IF(B16="","",IFERROR(INDEX(Client_List!$K:$K,MATCH(B16,Client_List!$B:$B,0)),"")) -> CANOLA OIL | F16: =IF(B16="","",IFERROR(INDEX(Client_List!$J:$J,MATCH(B16,Client_List!$B:$B,0)),"")) -> 350 | G16: 223 | H16: =IF(B16="","",IFERROR(A16-LOOKUP(2,1/($B$4:$B15=B16),$A$4:$A15),"")) | I16: =IF(B16="","",IFERROR(G16/H16,"")) | J16: 141010 | K16: =IF(B16="","",IFERROR(AVERAGEIFS($I$4:$I16,$B$4:$B16,B16,$I$4:$I16,">"&0),"")) | L16: =IF(B16="","",IF(ISNA(MATCH(B16,Client_List!$B:$B,0)),"⚠ NOT FOUND","✓")) -> ✓
... A57: 46029 | B57: BRU - 2073 - BRUNCH SNOB | C57: =IF(B57="","",IFERROR(INDEX(Client_List!$C:$C,MATCH(B57,Client_List!$B:$B,0)),"")) -> 4 | D57: =IF(B57="","",IFERROR(INDEX(Client_List!$D:$D,MATCH(B57,Client_List!$B:$B,0)),"")) -> 4D | E57: =IF(B57="","",IFERROR(INDEX(Client_List!$K:$K,MATCH(B57,Client_List!$B:$B,0)),"")) -> FRYERS CHOICE BLEND | F57: =IF(B57="","",IFERROR(INDEX(Client_List!$J:$J,MATCH(B57,Client_List!$B:$B,0)),"")) -> 350 | G57: 315 | H57: =IF(B57="","",IFERROR(A57-LOOKUP(2,1/($B$4:$B56=B57),$A$4:$A56),"")) | I57: =IF(B57="","",IFERROR(G57/H57,"")) | J57: 141134 | K57: =IF(B57="","",IFERROR(AVERAGEIFS($I$4:$I57,$B$4:$B57,B57,$I$4:$I57,">"&0),"")) | L57: =IF(B57="","",IF(ISNA(MATCH(B57,Client_List!$B:$B,0)),"⚠ NOT FOUND","✓")) -> ✓
A58: 46029 | B58: DUR - 4029 - DURVILL FOODS | C58: =IF(B58="","",IFERROR(INDEX(Client_List!$C:$C,MATCH(B58,Client_List!$B:$B,0)),"")) -> 4 | D58: =IF(B58="","",IFERROR(INDEX(Client_List!$D:$D,MATCH(B58,Client_List!$B:$B,0)),"")) -> 4E | E58: =IF(B58="","",IFERROR(INDEX(Client_List!$K:$K,MATCH(B58,Client_List!$B:$B,0)),"")) -> CANOLA OIL | F58: =IF(B58="","",IFERROR(INDEX(Client_List!$J:$J,MATCH(B58,Client_List!$B:$B,0)),"")) -> 2500 | G58: 1900 | H58: =IF(B58="","",IFERROR(A58-LOOKUP(2,1/($B$4:$B57=B58),$A$4:$A57),"")) | I58: =IF(B58="","",IFERROR(G58/H58,"")) | J58: 7570-1 | K58: =IF(B58="","",IFERROR(AVERAGEIFS($I$4:$I58,$B$4:$B58,B58,$I$4:$I58,">"&0),"")) | L58: =IF(B58="","",IF(ISNA(MATCH(B58,Client_List!$B:$B,0)),"⚠ NOT FOUND","✓")) -> ✓
A59: 46029 | B59: GIL - 7002 - GILBERT PIZZA | C59: =IF(B59="","",IFERROR(INDEX(Client_List!$C:$C,MATCH(B59,Client_List!$B:$B,0)),"")) -> 5 | D59: =IF(B59="","",IFERROR(INDEX(Client_List!$D:$D,MATCH(B59,Client_List!$B:$B,0)),"")) -> 5F | E59: =IF(B59="","",IFERROR(INDEX(Client_List!$K:$K,MATCH(B59,Client_List!$B:$B,0)),"")) -> FRYERS CHOICE BLEND | F59: =IF(B59="","",IFERROR(INDEX(Client_List!$J:$J,MATCH(B59,Client_List!$B:$B,0)),"")) -> 480 | G59: 318 | H59: =IF(B59="","",IFERROR(A59-LOOKUP(2,1/($B$4:$B58=B59),$A$4:$A58),"")) | I59: =IF(B59="","",IFERROR(G59/H59,"")) | J59: 141131 | K59: =IF(B59="","",IFERROR(AVERAGEIFS($I$4:$I59,$B$4:$B59,B59,$I$4:$I59,">"&0),"")) | L59: =IF(B59="","",IF(ISNA(MATCH(B59,Client_List!$B:$B,0)),"⚠ NOT FOUND","✓")) -> ✓
A60: 46029 | B60: HOR - 8034 - HORNY TOAD | C60: =IF(B60="","",IFERROR(INDEX(Client_List!$C:$C,MATCH(B60,Client_List!$B:$B,0)),"")) -> 4 | D60: =IF(B60="","",IFERROR(INDEX(Client_List!$D:$D,MATCH(B60,Client_List!$B:$B,0)),"")) -> 4A | E60: =IF(B60="","",IFERROR(INDEX(Client_List!$K:$K,MATCH(B60,Client_List!$B:$B,0)),"")) -> FRYERS CHOICE BLEND | F60: =IF(B60="","",IFERROR(INDEX(Client_List!$J:$J,MATCH(B60,Client_List!$B:$B,0)),"")) -> 900 | G60: 684 | H60: =IF(B60="","",IFERROR(A60-LOOKUP(2,1/($B$4:$B59=B60),$A$4:$A59),"")) | I60: =IF(B60="","",IFERROR(G60/H60,"")) | J60: 141142 | K60: =IF(B60="","",IFERROR(AVERAGEIFS($I$4:$I60,$B$4:$B60,B60,$I$4:$I60,">"&0),"")) | L60: =IF(B60="","",IF(ISNA(MATCH(B60,Client_List!$B:$B,0)),"⚠ NOT FOUND","✓")) -> ✓
A61: 46029 | B61: MAN3 - 13011 - MANUEL INDIAN SCHOOL | C61: =IF(B61="","",IFERROR(INDEX(Client_List!$C:$C,MATCH(B61,Client_List!$B:$B,0)),"")) -> 3 | D61: =IF(B61="","",IFERROR(INDEX(Client_List!$D:$D,MATCH(B61,Client_List!$B:$B,0)),"")) -> 3D | E61: =IF(B61="","",IFERROR(INDEX(Client_List!$K:$K,MATCH(B61,Client_List!$B:$B,0)),"")) -> CANOLA OIL | F61: =IF(B61="","",IFERROR(INDEX(Client_List!$J:$J,MATCH(B61,Client_List!$B:$B,0)),"")) -> 1000 | G61: 686 | H61: =IF(B61="","",IFERROR(A61-LOOKUP(2,1/($B$4:$B60=B61),$A$4:$A60),"")) | I61: =IF(B61="","",IFERROR(G61/H61,"")) | J61: 141135 | K61: =IF(B61="","",IFERROR(AVERAGEIFS($I$4:$I61,$B$4:$B61,B61,$I$4:$I61,">"&0),"")) | L61: =IF(B61="","",IF(ISNA(MATCH(B61,Client_List!$B:$B,0)),"⚠ NOT FOUND","✓")) -> ✓
A62: 46029 | B62: MVP - 2021 - MVP SPORTS BAR & GRILL | C62: =IF(B62="","",IFERROR(INDEX(Client_List!$C:$C,MATCH(B62,Client_List!$B:$B,0)),"")) -> 4 | D62: =IF(B62="","",IFERROR(INDEX(Client_List!$D:$D,MATCH(B62,Client_List!$B:$B,0)),"")) -> 4F | E62: =IF(B62="","",IFERROR(INDEX(Client_List!$K:$K,MATCH(B62,Client_List!$B:$B,0)),"")) -> FRYERS CHOICE BLEND | F62: =IF(B62="","",IFERROR(INDEX(Client_List!$J:$J,MATCH(B62,Client_List!$B:$B,0)),"")) -> 620 | G62: 511 | H62: =IF(B62="","",IFERROR(A62-LOOKUP(2,1/($B$4:$B61=B62),$A$4:$A61),"")) | I62: =IF(B62="","",IFERROR(G62/H62,"")) | J62: 141133 | K62: =IF(B62="","",IFERROR(AVERAGEIFS($I$4:$I62,$B$4:$B62,B62,$I$4:$I62,">"&0),"")) | L62: =IF(B62="","",IF(ISNA(MATCH(B62,Client_List!$B:$B,0)),"⚠ NOT FOUND","✓")) -> ✓
A63: 46029 | B63: OHS - 15000 - OHSO INDIAN SCHOOL | C63: =IF(B63="","",IFERROR(INDEX(Client_List!$C:$C,MATCH(B63,Client_List!$B:$B,0)),"")) -> 4 | D63: =IF(B63="","",IFERROR(INDEX(Client_List!$D:$D,MATCH(B63,Client_List!$B:$B,0)),"")) -> 4D | E63: =IF(B63="","",IFERROR(INDEX(Client_List!$K:$K,MATCH(B63,Client_List!$B:$B,0)),"")) -> CANOLA OIL | F63: =IF(B63="","",IFERROR(INDEX(Client_List!$J:$J,MATCH(B63,Client_List!$B:$B,0)),"")) -> 1050 | G63: 823 | H63: =IF(B63="","",IFERROR(A63-LOOKUP(2,1/($B$4:$B62=B63),$A$4:$A62),"")) | I63: =IF(B63="","",IFERROR(G63/H63,"")) | J63: 141129 | K63: =IF(B63="","",IFERROR(AVERAGEIFS($I$4:$I63,$B$4:$B63,B63,$I$4:$I63,">"&0),"")) | L63: =IF(B63="","",IF(ISNA(MATCH(B63,Client_List!$B:$B,0)),"⚠ NOT FOUND","✓")) -> ✓
A64: 46029 | B64: OREM - 15009 - OREGANO QUEEN CREEK | C64: =IF(B64="","",IFERROR(INDEX(Client_List!$C:$C,MATCH(B64,Client_List!$B:$B,0)),"")) -> 5 | D64: =IF(B64="","",IFERROR(INDEX(Client_List!$D:$D,MATCH(B64,Client_List!$B:$B,0)),"")) -> 5F | E64: =IF(B64="","",IFERROR(INDEX(Client_List!$K:$K,MATCH(B64,Client_List!$B:$B,0)),"")) -> CANOLA OIL | F64: =IF(B64="","",IFERROR(INDEX(Client_List!$J:$J,MATCH(B64,Client_List!$B:$B,0)),"")) -> 500 | G64: 434 | H64: =IF(B64="","",IFERROR(A64-LOOKUP(2,1/($B$4:$B63=B64),$A$4:$A63),"")) | I64: =IF(B64="","",IFERROR(G64/H64,"")) | J64: 141128 | K64: =IF(B64="","",IFERROR(AVERAGEIFS($I$4:$I64,$B$4:$B64,B64,$I$4:$I64,">"&0),"")) | L64: =IF(B64="","",IF(ISNA(MATCH(B64,Client_List!$B:$B,0)),"⚠ NOT FOUND","✓")) -> ✓
A65: 46029 | B65: ORES - 15015 - OREGANO SUPERSTITION | C65: =IF(B65="","",IFERROR(INDEX(Client_List!$C:$C,MATCH(B65,Client_List!$B:$B,0)),"")) -> 5 | D65: =IF(B65="","",IFERROR(INDEX(Client_List!$D:$D,MATCH(B65,Client_List!$B:$B,0)),"")) -> 5E | E65: =IF(B65="","",IFERROR(INDEX(Client_List!$K:$K,MATCH(B65,Client_List!$B:$B,0)),"")) -> CANOLA OIL | F65: =IF(B65="","",IFERROR(INDEX(Client_List!$J:$J,MATCH(B65,Client_List!$B:$B,0)),"")) -> 500 | G65: 441 | H65: =IF(B65="","",IFERROR(A65-LOOKUP(2,1/($B$4:$B64=B65),$A$4:$A64),"")) | I65: =IF(B65="","",IFERROR(G65/H65,"")) | J65: 141137 | K65: =IF(B65="","",IFERROR(AVERAGEIFS($I$4:$I65,$B$4:$B65,B65,$I$4:$I65,">"&0),"")) | L65: =IF(B65="","",IF(ISNA(MATCH(B65,Client_List!$B:$B,0)),"⚠ NOT FOUND","✓")) -> ✓
A66: 46029 | B66: PET44 - 16006 - PETES FISH 44TH ST | C66: =IF(B66="","",IFERROR(INDEX(Client_List!$C:$C,MATCH(B66,Client_List!$B:$B,0)),"")) -> 4 | D66: =IF(B66="","",IFERROR(INDEX(Client_List!$D:$D,MATCH(B66,Client_List!$B:$B,0)),"")) -> 4D | E66: =IF(B66="","",IFERROR(INDEX(Client_List!$K:$K,MATCH(B66,Client_List!$B:$B,0)),"")) -> FRYERS CHOICE BLEND | F66: =IF(B66="","",IFERROR(INDEX(Client_List!$J:$J,MATCH(B66,Client_List!$B:$B,0)),"")) -> 950 | G66: 872 | H66: =IF(B66="","",IFERROR(A66-LOOKUP(2,1/($B$4:$B65=B66),$A$4:$A65),"")) | I66: =IF(B66="","",IFERROR(G66/H66,"")) | J66: 141130 | K66: =IF(B66="","",IFERROR(AVERAGEIFS($I$4:$I66,$B$4:$B66,B66,$I$4:$I66,">"&0),"")) | L66: =IF(B66="","",IF(ISNA(MATCH(B66,Client_List!$B:$B,0)),"⚠ NOT FOUND","✓")) -> ✓
A67: 46029 | B67: PIRA - 16019 - PIRATES ARIZONA AVE | C67: =IF(B67="","",IFERROR(INDEX(Client_List!$C:$C,MATCH(B67,Client_List!$B:$B,0)),"")) -> 4 | D67: =IF(B67="","",IFERROR(INDEX(Client_List!$D:$D,MATCH(B67,Client_List!$B:$B,0)),"")) -> 4F | E67: =IF(B67="","",IFERROR(INDEX(Client_List!$K:$K,MATCH(B67,Client_List!$B:$B,0)),"")) -> FRYERS CHOICE BLEND | F67: =IF(B67="","",IFERROR(INDEX(Client_List!$J:$J,MATCH(B67,Client_List!$B:$B,0)),"")) -> 950 | G67: 661 | H67: =IF(B67="","",IFERROR(A67-LOOKUP(2,1/($B$4:$B66=B67),$A$4:$A66),"")) | I67: =IF(B67="","",IFERROR(G67/H67,"")) | J67: 141132 | K67: =IF(B67="","",IFERROR(AVERAGEIFS($I$4:$I67,$B$4:$B67,B67,$I$4:$I67,">"&0),"")) | L67: =IF(B67="","",IF(ISNA(MATCH(B67,Client_List!$B:$B,0)),"⚠ NOT FOUND","✓")) -> ✓
A68: 46029 | B68: PIRL - 16018 - PIRATES MESA | C68: =IF(B68="","",IFERROR(INDEX(Client_List!$C:$C,MATCH(B68,Client_List!$B:$B,0)),"")) -> 5 | D68: =IF(B68="","",IFERROR(INDEX(Client_List!$D:$D,MATCH(B68,Client_List!$B:$B,0)),"")) -> 5E | E68: =IF(B68="","",IFERROR(INDEX(Client_List!$K:$K,MATCH(B68,Client_List!$B:$B,0)),"")) -> FRYERS CHOICE BLEND | F68: =IF(B68="","",IFERROR(INDEX(Client_List!$J:$J,MATCH(B68,Client_List!$B:$B,0)),"")) -> 950 | G68: 668 | H68: =IF(B68="","",IFERROR(A68-LOOKUP(2,1/($B$4:$B67=B68),$A$4:$A67),"")) | I68: =IF(B68="","",IFERROR(G68/H68,"")) | J68: 141139 | K68: =IF(B68="","",IFERROR(AVERAGEIFS($I$4:$I68,$B$4:$B68,B68,$I$4:$I68,">"&0),"")) | L68: =IF(B68="","",IF(ISNA(MATCH(B68,Client_List!$B:$B,0)),"⚠ NOT FOUND","✓")) -> ✓
A69: 46029 | B69: THE - 20088 - THE VIG BELL | C69: =IF(B69="","",IFERROR(INDEX(Client_List!$C:$C,MATCH(B69,Client_List!$B:$B,0)),"")) -> 4 | D69: =IF(B69="","",IFERROR(INDEX(Client_List!$D:$D,MATCH(B69,Client_List!$B:$B,0)),"")) -> 4D | E69: =IF(B69="","",IFERROR(INDEX(Client_List!$K:$K,MATCH(B69,Client_List!$B:$B,0)),"")) -> CANOLA OIL | F69: =IF(B69="","",IFERROR(INDEX(Client_List!$J:$J,MATCH(B69,Client_List!$B:$B,0)),"")) -> 1050 | G69: 979 | H69: =IF(B69="","",IFERROR(A69-LOOKUP(2,1/($B$4:$B68=B69),$A$4:$A68),"")) | I69: =IF(B69="","",IFERROR(G69/H69,"")) | J69: 141140 | K69: =IF(B69="","",IFERROR(AVERAGEIFS($I$4:$I69,$B$4:$B69,B69,$I$4:$I69,">"&0),"")) | L69: =IF(B69="","",IF(ISNA(MATCH(B69,Client_List!$B:$B,0)),"⚠ NOT FOUND","✓")) -> ✓
A70: 46030 | B70: AJO ALS 1018 | C70: =IF(B70="","",IFERROR(INDEX(Client_List!$C:$C,MATCH(B70,Client_List!$B:$B,0)),"")) -> 2 | D70: =IF(B70="","",IFERROR(INDEX(Client_List!$D:$D,MATCH(B70,Client_List!$B:$B,0)),"")) -> 2C | E70: =IF(B70="","",IFERROR(INDEX(Client_List!$K:$K,MATCH(B70,Client_List!$B:$B,0)),"")) -> CANOLA OIL | F70: =IF(B70="","",IFERROR(INDEX(Client_List!$J:$J,MATCH(B70,Client_List!$B:$B,0)),"")) -> 950 | G70: 631 | H70: =IF(B70="","",IFERROR(A70-LOOKUP(2,1/($B$4:$B69=B70),$A$4:$A69),"")) | I70: =IF(B70="","",IFERROR(G70/H70,"")) | J70: 141184 | K70: =IF(B70="","",IFERROR(AVERAGEIFS($I$4:$I70,$B$4:$B70,B70,$I$4:$I70,">"&0),"")) | L70: =IF(B70="","",IF(ISNA(MATCH(B70,Client_List!$B:$B,0)),"⚠ NOT FOUND","✓")) -> ✓
... A91: 46032 | B91: ORER - 15004 - OREGANO FLAGSTAFF | C91: =IF(B91="","",IFERROR(INDEX(Client_List!$C:$C,MATCH(B91,Client_List!$B:$B,0)),"")) -> 0 | D91: =IF(B91="","",IFERROR(INDEX(Client_List!$D:$D,MATCH(B91,Client_List!$B:$B,0)),"")) -> F | E91: =IF(B91="","",IFERROR(INDEX(Client_List!$K:$K,MATCH(B91,Client_List!$B:$B,0)),"")) -> CANOLA OIL | F91: =IF(B91="","",IFERROR(INDEX(Client_List!$J:$J,MATCH(B91,Client_List!$B:$B,0)),"")) -> 700 | G91: 386 | H91: =IF(B91="","",IFERROR(A91-LOOKUP(2,1/($B$4:$B90=B91),$A$4:$A90),"")) | I91: =IF(B91="","",IFERROR(G91/H91,"")) | J91: 141246 | K91: =IF(B91="","",IFERROR(AVERAGEIFS($I$4:$I91,$B$4:$B91,B91,$I$4:$I91,">"&0),"")) | L91: =IF(B91="","",IF(ISNA(MATCH(B91,Client_List!$B:$B,0)),"⚠ NOT FOUND","✓")) -> ✓
A92: 46033 | B92: ARR79 - 1000 - ARRIBAS 79TH AVE. | C92: =IF(B92="","",IFERROR(INDEX(Client_List!$C:$C,MATCH(B92,Client_List!$B:$B,0)),"")) -> 2 | D92: =IF(B92="","",IFERROR(INDEX(Client_List!$D:$D,MATCH(B92,Client_List!$B:$B,0)),"")) -> 2C | E92: =IF(B92="","",IFERROR(INDEX(Client_List!$K:$K,MATCH(B92,Client_List!$B:$B,0)),"")) -> CANOLA OIL | F92: =IF(B92="","",IFERROR(INDEX(Client_List!$J:$J,MATCH(B92,Client_List!$B:$B,0)),"")) -> 950 | G92: 938 | H92: =IF(B92="","",IFERROR(A92-LOOKUP(2,1/($B$4:$B91=B92),$A$4:$A91),"")) | I92: =IF(B92="","",IFERROR(G92/H92,"")) | K92: =IF(B92="","",IFERROR(AVERAGEIFS($I$4:$I92,$B$4:$B92,B92,$I$4:$I92,">"&0),"")) | L92: =IF(B92="","",IF(ISNA(MATCH(B92,Client_List!$B:$B,0)),"⚠ NOT FOUND","✓")) -> ✓
A93: 46033 | B93: DAR - 4026 - DARUMA BY RIE | C93: =IF(B93="","",IFERROR(INDEX(Client_List!$C:$C,MATCH(B93,Client_List!$B:$B,0)),"")) -> 4 | D93: =IF(B93="","",IFERROR(INDEX(Client_List!$D:$D,MATCH(B93,Client_List!$B:$B,0)),"")) -> 4E | E93: =IF(B93="","",IFERROR(INDEX(Client_List!$K:$K,MATCH(B93,Client_List!$B:$B,0)),"")) -> CANOLA OIL | F93: =IF(B93="","",IFERROR(INDEX(Client_List!$J:$J,MATCH(B93,Client_List!$B:$B,0)),"")) -> 350 | G93: 336 | H93: =IF(B93="","",IFERROR(A93-LOOKUP(2,1/($B$4:$B92=B93),$A$4:$A92),"")) | I93: =IF(B93="","",IFERROR(G93/H93,"")) | J93: 141276 | K93: =IF(B93="","",IFERROR(AVERAGEIFS($I$4:$I93,$B$4:$B93,B93,$I$4:$I93,">"&0),"")) | L93: =IF(B93="","",IF(ISNA(MATCH(B93,Client_List!$B:$B,0)),"⚠ NOT FOUND","✓")) -> ✓
A94: 46033 | B94: FAT - 6101 - FATE BREWERY | C94: =IF(B94="","",IFERROR(INDEX(Client_List!$C:$C,MATCH(B94,Client_List!$B:$B,0)),"")) -> 4 | D94: =IF(B94="","",IFERROR(INDEX(Client_List!$D:$D,MATCH(B94,Client_List!$B:$B,0)),"")) -> 4D | E94: =IF(B94="","",IFERROR(INDEX(Client_List!$K:$K,MATCH(B94,Client_List!$B:$B,0)),"")) -> CANOLA OIL | F94: =IF(B94="","",IFERROR(INDEX(Client_List!$J:$J,MATCH(B94,Client_List!$B:$B,0)),"")) -> 700 | G94: 611 | H94: =IF(B94="","",IFERROR(A94-LOOKUP(2,1/($B$4:$B93=B94),$A$4:$A93),"")) -> 8 | I94: =IF(B94="","",IFERROR(G94/H94,"")) -> 76.375 | J94: 141211 | K94: =IF(B94="","",IFERROR(AVERAGEIFS($I$4:$I94,$B$4:$B94,B94,$I$4:$I94,">"&0),"")) -> 76.375 | L94: =IF(B94="","",IF(ISNA(MATCH(B94,Client_List!$B:$B,0)),"⚠ NOT FOUND","✓")) -> ✓
A95: 46033 | B95: HUN - 8005 - HUNGRY MONK | C95: =IF(B95="","",IFERROR(INDEX(Client_List!$C:$C,MATCH(B95,Client_List!$B:$B,0)),"")) -> 4 | D95: =IF(B95="","",IFERROR(INDEX(Client_List!$D:$D,MATCH(B95,Client_List!$B:$B,0)),"")) -> 4F | E95: =IF(B95="","",IFERROR(INDEX(Client_List!$K:$K,MATCH(B95,Client_List!$B:$B,0)),"")) -> CANOLA OIL | F95: =IF(B95="","",IFERROR(INDEX(Client_List!$J:$J,MATCH(B95,Client_List!$B:$B,0)),"")) -> 950 | G95: 915 | H95: =IF(B95="","",IFERROR(A95-LOOKUP(2,1/($B$4:$B94=B95),$A$4:$A94),"")) | I95: =IF(B95="","",IFERROR(G95/H95,"")) | J95: 141270 | K95: =IF(B95="","",IFERROR(AVERAGEIFS($I$4:$I95,$B$4:$B95,B95,$I$4:$I95,">"&0),"")) | L95: =IF(B95="","",IF(ISNA(MATCH(B95,Client_List!$B:$B,0)),"⚠ NOT FOUND","✓")) -> ✓
A96: 46033 | B96: MAN7 - 13015 - MANUEL SOUTHERN | C96: =IF(B96="","",IFERROR(INDEX(Client_List!$C:$C,MATCH(B96,Client_List!$B:$B,0)),"")) -> 4 | D96: =IF(B96="","",IFERROR(INDEX(Client_List!$D:$D,MATCH(B96,Client_List!$B:$B,0)),"")) -> 4E | E96: =IF(B96="","",IFERROR(INDEX(Client_List!$K:$K,MATCH(B96,Client_List!$B:$B,0)),"")) -> CANOLA OIL | F96: =IF(B96="","",IFERROR(INDEX(Client_List!$J:$J,MATCH(B96,Client_List!$B:$B,0)),"")) -> 950 | G96: 911 | H96: =IF(B96="","",IFERROR(A96-LOOKUP(2,1/($B$4:$B95=B96),$A$4:$A95),"")) | I96: =IF(B96="","",IFERROR(G96/H96,"")) | J96: 141275 | K96: =IF(B96="","",IFERROR(AVERAGEIFS($I$4:$I96,$B$4:$B96,B96,$I$4:$I96,">"&0),"")) | L96: =IF(B96="","",IF(ISNA(MATCH(B96,Client_List!$B:$B,0)),"⚠ NOT FOUND","✓")) -> ✓
A97: 46033 | B97: TAI - 20098 - IL PRIMO BELL CAVE CREEK | C97: =IF(B97="","",IFERROR(INDEX(Client_List!$C:$C,MATCH(B97,Client_List!$B:$B,0)),"")) -> 4 | D97: =IF(B97="","",IFERROR(INDEX(Client_List!$D:$D,MATCH(B97,Client_List!$B:$B,0)),"")) -> 4B | E97: =IF(B97="","",IFERROR(INDEX(Client_List!$K:$K,MATCH(B97,Client_List!$B:$B,0)),"")) -> CANOLA OIL | F97: =IF(B97="","",IFERROR(INDEX(Client_List!$J:$J,MATCH(B97,Client_List!$B:$B,0)),"")) -> 1050 | G97: 150 | H97: =IF(B97="","",IFERROR(A97-LOOKUP(2,1/($B$4:$B96=B97),$A$4:$A96),"")) | I97: =IF(B97="","",IFERROR(G97/H97,"")) | J97: 141274 | K97: =IF(B97="","",IFERROR(AVERAGEIFS($I$4:$I97,$B$4:$B97,B97,$I$4:$I97,">"&0),"")) | L97: =IF(B97="","",IF(ISNA(MATCH(B97,Client_List!$B:$B,0)),"⚠ NOT FOUND","✓")) -> ✓
A98: 46033 | B98: THE - 20021 - THE VIG VAL VISTA | C98: =IF(B98="","",IFERROR(INDEX(Client_List!$C:$C,MATCH(B98,Client_List!$B:$B,0)),"")) -> 5 | D98: =IF(B98="","",IFERROR(INDEX(Client_List!$D:$D,MATCH(B98,Client_List!$B:$B,0)),"")) -> 5E | E98: =IF(B98="","",IFERROR(INDEX(Client_List!$K:$K,MATCH(B98,Client_List!$B:$B,0)),"")) -> CANOLA OIL | F98: =IF(B98="","",IFERROR(INDEX(Client_List!$J:$J,MATCH(B98,Client_List!$B:$B,0)),"")) -> 1050 | G98: 1005 | H98: =IF(B98="","",IFERROR(A98-LOOKUP(2,1/($B$4:$B97=B98),$A$4:$A97),"")) | I98: =IF(B98="","",IFERROR(G98/H98,"")) | J98: 141271 | K98: =IF(B98="","",IFERROR(AVERAGEIFS($I$4:$I98,$B$4:$B98,B98,$I$4:$I98,">"&0),"")) | L98: =IF(B98="","",IF(ISNA(MATCH(B98,Client_List!$B:$B,0)),"⚠ NOT FOUND","✓")) -> ✓
A99: 46035 | B99: BOO - 2023 - BOOTY GOODYEAR | C99: =IF(B99="","",IFERROR(INDEX(Client_List!$C:$C,MATCH(B99,Client_List!$B:$B,0)),"")) -> 1 | D99: =IF(B99="","",IFERROR(INDEX(Client_List!$D:$D,MATCH(B99,Client_List!$B:$B,0)),"")) -> 1D | E99: =IF(B99="","",IFERROR(INDEX(Client_List!$K:$K,MATCH(B99,Client_List!$B:$B,0)),"")) -> CANOLA OIL | F99: =IF(B99="","",IFERROR(INDEX(Client_List!$J:$J,MATCH(B99,Client_List!$B:$B,0)),"")) -> 620 | G99: 690 | H99: =IF(B99="","",IFERROR(A99-LOOKUP(2,1/($B$4:$B98=B99),$A$4:$A98),"")) -> 7 | I99: =IF(B99="","",IFERROR(G99/H99,"")) -> 98.571429 | J99: 141328 | K99: =IF(B99="","",IFERROR(AVERAGEIFS($I$4:$I99,$B$4:$B99,B99,$I$4:$I99,">"&0),"")) -> 98.571429 | L99: =IF(B99="","",IF(ISNA(MATCH(B99,Client_List!$B:$B,0)),"⚠ NOT FOUND","✓")) -> ✓
A100: 46035 | B100: CAS - 3069 - CASA DE FALAFEL | C100: =IF(B100="","",IFERROR(INDEX(Client_List!$C:$C,MATCH(B100,Client_List!$B:$B,0)),"")) -> 2 | D100: =IF(B100="","",IFERROR(INDEX(Client_List!$D:$D,MATCH(B100,Client_List!$B:$B,0)),"")) -> 2C | E100: =IF(B100="","",IFERROR(INDEX(Client_List!$K:$K,MATCH(B100,Client_List!$B:$B,0)),"")) -> CANOLA OIL | F100: =IF(B100="","",IFERROR(INDEX(Client_List!$J:$J,MATCH(B100,Client_List!$B:$B,0)),"")) -> 1000 | G100: 1079 | H100: =IF(B100="","",IFERROR(A100-LOOKUP(2,1/($B$4:$B99=B100),$A$4:$A99),"")) | I100: =IF(B100="","",IFERROR(G100/H100,"")) | J100: 141329 | K100: =IF(B100="","",IFERROR(AVERAGEIFS($I$4:$I100,$B$4:$B100,B100,$I$4:$I100,">"&0),"")) | L100: =IF(B100="","",IF(ISNA(MATCH(B100,Client_List!$B:$B,0)),"⚠ NOT FOUND","✓")) -> ✓
...

Sheet Client_List
A1: S&K CLIENT LIST — Edit Address, Lat, Lon, Tank Size and Product here
A2: YELLOW columns = edit freely. Changes here flow automatically into Optimizer_Input via VLOOKUP. Customer name in col B must match Delivery_Log exactly.
A3: ID | B3: Customer Name | C3: Zone | D3: Zone Code | E3: Street Address | F3: City | G3: State | H3: Latitude | I3: Longitude | J3: Tank Size (lbs) | K3: Product
A4: C001 | B4: 51ST - 0001 - 51ST AVE CAFE | C4: 2 | D4: 2D | E4: 5511 N 51St Ave | F4: Glendale | G4: AZ | H4: 33.517199 | I4: -112.16811 | J4: 350 | K4: FRYERS CHOICE BLEND | N4: 254-237-3350
A5: C002 | B5: AJO ALS 1018 | C5: 2 | D5: 2C | E5: 7458 W Bell Rd | F5: Glendale | G5: AZ | H5: 33.639017 | I5: -112.21978 | J5: 950 | K5: CANOLA OIL | N5: 623-334-9899
A6: C003 | B6: ALL - 1063 - ALL AMERICAN MODERN SPORTS GRILL | C6: 4 | D6: 4C | E6: 20751 N PIMA RD #105 | F6: Scottsdale | G6: AZ | H6: 33.674519 | I6: -111.88803 | J6: 900 | K6: CANOLA OIL | N6: (480) 887-0652
A7: C004 | B7: AME - 1073 - AMELIO C ENTERPRISES, INC (CACTUS CANDY) | C7: 4 | D7: 4C | E7: 2656 N 37TH DR | F7: PHOENIX | G7: AZ | H7: 33.478277 | I7: -112.14051 | J7: 2000 | K7: CANOLA OIL | N7: (602) 956-4833
A8: C005 | B8: ANG - 1054 - ANGRY CRAB SURPRISE | C8: 1 | D8: 1C | E8: 11340 W BELL RD SUITE 118 | F8: SURPRISE | G8: AZ | H8: 33.639939 | I8: -112.30419 | J8: 620 | K8: FRYERS CHOICE BLEND | N8: (623) 248-9190
A9: C007 | B9: ARR79 - 1000 - ARRIBAS 79TH AVE. | C9: 2 | D9: 2C | E9: 17211 N 79Th Ave | F9: Glendale | G9: AZ | H9: 33.640214 | I9: -112.22941 | J9: 950 | K9: CANOLA OIL | N9: 623-878-5777
A10: C008 | B10: ARRC - 1001 - ARRIBAS CAMELBACK | C10: 3 | D10: 3D | E10: 1812 E Camelback Rd | F10: Phoenix | G10: AZ | H10: 33.50958 | I10: -112.04259 | J10: 700 | K10: CANOLA OIL | N10: 480-948-9969
A11: C009 | B11: ARRC - 1011 - ARRIBAS CHANDLER | C11: 4 | D11: 4F | E11: 4649 E Chandler Blvd | F11: Phoenix | G11: AZ | H11: 33.304826 | I11: -111.98161 | J11: 1000 | K11: CANOLA OIL | N11: 623-878-5777
A12: C010 | B12: ARRC - 1014 - ARRIBA GILBERT | C12: 5 | D12: 5F | E12: 2855 S Market St, Gilbert, AZ 85295 | F12: Gilbert | G12: AZ | H12: 33.29809 | I12: -111.74427 | J12: 900 | K12: CANOLA OIL | N12: 480-899-7337
A13: C011 | B13: ARRM - 1013 - ARRIBAS GOODYEAR | C13: 1 | D13: 1D | E13: 15370 W McDowell Rd | F13: Goodyear | G13: AZ | H13: 33.46499 | I13: -112.3899 | J13: 900 | K13: CANOLA OIL | N13: 623-223-1735
A14: C012 | B14: ATL - 1081 - ATL WINGS ROOSEVELT | C14: 3 | D14: 3D | E14: 330 E ROOSEVELT RD | F14: PHOENIX | G14: AZ | H14: 33.458941 | I14: -112.06855 | J14: 350 | K14: CANOLA OIL | N14: (602) 741-9554
A15: C013 | B15: ATL - 1083 - ATL WINGS MESA | C15: 5 | D15: 5D | E15: 6837 E MAIN ST | F15: Mesa | G15: AZ | H15: 33.415147 | I15: -111.68318 | J15: 425 | K15: CANOLA OIL | N15: (480) 722-9464
... A26: C024 | B26: BUR - 4038 - BURGERS & BREWS GLENDALE | C26: 2 | D26: 2C | E26: 6670 W CACTUS RD | F26: GLENDALE | G26: AZ | H26: 33.597456 | I26: -112.20202 | J26: 1050 | K26: CANOLA OIL | N26: (623) 776-2266
A27: C025 | B27: CAR - 3063 - CARDINAL STADIUM | C27: 2 | D27: 2D | E27: 1 CARDINAL DR | F27: GLENDALE | G27: ARIZONA | H27: 33.526233 | I27: -112.26611 | J27: 2500 | K27: CANOLA OIL
A28: C026 | B28: CAS - 3069 - CASA DE FALAFEL | C28: 2 | D28: 2C | E28: 4920 W Thunderbird Rd | F28: Glendale | G28: AZ | H28: 33.611633 | I28: -112.16541 | J28: 1000 | K28: CANOLA OIL | N28: (480) 689-0514
A29: C028 | B29: CRA - 3021 - JC FOOD TRADING/GLEN | C29: 2 | D29: 2C | E29: CRAZY MIKES CHICKEN | F29: Glendale | G29: AZ | H29: 33.639787 | I29: -112.17386 | J29: 450 | K29: CANOLA OIL | N29: 623-463-6881
A30: C029 | B30: CRA - 3046 - JC FOOD TRADING /GOODYEAR | C30: 2 | D30: 2C | E30: CRAZY MIKE'S GOODYEAR | F30: Goodyear | G30: AZ | H30: 33.483996 | I30: -112.36512 | J30: 1000 | K30: CANOLA OIL | N30: 213-700-4092
A31: C030 | B31: CRA - 3065 - CRAFTED CUISINE | C31: 4 | D31: 4D | E31: 6736 E Avalon Dr | F31: Scottsdale | G31: AZ | H31: 33.483076 | I31: -111.93581 | J31: 350 | K31: CANOLA OIL | N31: (210) 529-1900
A32: C031 | B32: CRO - 3064 - CROWNE PLAZA RESORT | C32: 4 | D32: 4F | E32: One N San Marcos Pl | F32: Chandler | G32: Arizona | H32: 33.320637 | I32: -111.84377 | J32: 700 | K32: CANOLA OIL | N32: (480) 812-0900
A33: C032 | B33: DAI - 4015A - DAIRY QUEEN BELL | C33: 3 | D33: 3C | E33: 3550 E BELL ROAD | F33: PHOENIX | G33: AZ | H33: 33.641001 | I33: -112.00519 | J33: 500 | K33: CANOLA OIL | N33: 602-788-0261 (JACIE M
A34: C033 | B34: DAR - 4026 - DARUMA BY RIE | C34: 4 | D34: 4E | E34: 1116 E DOBSON RD | F34: MESA | G34: AZ | H34: 33.39476 | I34: -111.87536 | J34: 350 | K34: CANOLA OIL | N34: (480) 590-7979
A35: C034 | B35: DAR 4037 - DARUMA RAMEN AND BOWL | C35: 4 | D35: 4E | E35: 2650 E UNIVERSITY DR | F35: MESA | G35: AZ | H35: 33.423457 | I35: -111.7736 | J35: 350 | K35: CANOLA OIL | N35: (562) 760-8262
A36: C035 | B36: DIL - 4009 - DILLONS BBQ | C36: 1 | D36: 1D | E36: 16335 W Northern Ave | F36: Litchfield Pk | G36: AZ | H36: 33.549985 | I36: -112.41071 | J36: 1050 | K36: FRYERS CHOICE BLEND | N36: 623-535-4249
A37: C036 | B37: DIL - 4025 - DILLON WESTERN TRAILS | C37: 1 | D37: 1B | E37: 37838 W GRAND AVE | F37: MORISTOWN | G37: AZ | H37: 33.82904 | I37: -112.59487 | J37: 1050 | K37: FRYERS CHOICE BLEND | N37: 623-521-0367
A38: C037 | B38: DIL- 4014 - DILLONS BAYOU | C38: 2 | D38: 2A | E38: 40202 N 87Th Ave | F38: Peoria | G38: AZ | H38: 33.852793 | I38: -112.24698 | J38: 450 | K38: FRYERS CHOICE BLEND | N38: 623-498-5427
A39: C038 | B39: DIL59 - 4010 - DILLONS 59TH AVE | C39: 2 | D39: 2A | E39: 20585 N 59Th Ave | F39: Glendale | G39: AZ | H39: 33.67218 | I39: -112.18631 | J39: 500 | K39: FRYERS CHOICE BLEND | N39: 623-979-5353
A40: C039 | B40: DIR - 4027 - DIRTWATER | C40: 5 | D40: 5E | E40: 586 W APACHE | F40: APACHE JUNCTION | G40: AZ | H40: 33.415492 | I40: -111.55237 | J40: 900 | K40: FRYERS CHOICE BLEND | N40: 480-983-3478
A41: C040 | B41: DUR - 4029 - DURVILL FOODS | C41: 4 | D41: 4E | E41: DURVILL FOODS | F41: Phoenix | G41: AZ | H41: 33.406637 | I41: -112.01103 | J41: 2500 | K41: CANOLA OIL
A42: C041 | B42: ECH - 5006 - ECHO 5 SPORTS BAR | C42: 5 | D42: 5D | E42: ECHO 5 SPORTS BAR | F42: Mesa | G42: AZ | H42: 33.468258 | I42: -111.68292 | J42: 450 | K42: FRYERS CHOICE BLEND | N42: 602-391-7707
A43: C042 | B43: ELT - 5004 - EL TACO TOTE | C43: 3 | D43: 3D | E43: 3464 W Camelback Rd | F43: Phoenix | G43: AZ | H43: 33.509715 | I43: -112.13384 | J43: 500 | K43: CANOLA OIL | N43: 602-866-8683
A44: C043 | B44: ENR - 5018 - ENROUTE COFFEE AND TEA | C44: 1 | D44: 1D | E44: 15605 W ROOSEVELT ST | F44: GOODYEAR | G44: AZ | H44: 33.456415 | I44: -112.39449 | J44: 350 | K44: CANOLA OIL | N44: (253) 359-7081
A45: C044 | B45: FAT - 6101 - FATE BREWERY | C45: 4 | D45: 4D | E45: 1312 N SCOTTSDALE RD | F45: SCOTTSDALE | G45: AZ | H45: 33.462701 | I45: -111.92684 | J45: 700 | K45: CANOLA OIL | N45: 480-656-9100
A46: C045 | B46: FAT - 6109 - FATE BREWING TEMPE | C46: 4 | D46: 4E | E46: 201 E SOUTHERN AVE | F46: TEMPE | G46: AZ | H46: 33.392382 | I46: -111.93649 | J46: 700 | K46: CANOLA OIL
A47: C046 | B47: FOU - 6077 - FOUR PEAKS BREWING | C47: 4 | D47: 4E | E47: 1340 E 8Th St | F47: Tempe | G47: AZ | H47: 33.41968 | I47: -111.91592 | J47: 2500 | K47: FRYERS CHOICE BLEND | N47: 480-303-9967
A48: C047 | B48: FUN - 12047 - FUNKY FRIDAS | C48: 3 | D48: 3C | E48: 4910 E Indian School Rd | F48: Phoenix | G48: AZ | H48: 33.494903 | I48: -111.97541 | J48: 630 | K48: CANOLA OIL | N48: (602) 955-0358
A49: C048 | B49: GAR - 7001 - GARCIAS MEXICAN RESTAURANT | C49: 3 | D49: 3D | E49: 2212 N 35Th Ave | F49: Phoenix | G49: AZ | H49: 33.471653 | I49: -112.13482 | J49: 1850 | K49: CANOLA OIL | N49: 602-272-5584
A50: C049 | B50: GIL - 7002 - GILBERT PIZZA | C50: 5 | D50: 5F | E50: GILBERT PIZZA | F50: Gilbert | G50: AZ | H50: 33.328977 | I50: -111.79051 | J50: 480 | K50: FRYERS CHOICE BLEND | N50: 999-999-9999
...

Sheet Optimizer_Input
A1: S&K OIL SALES — OPTIMIZER INPUT (all calculations auto-update from Delivery_Log)
A2: Min Oil % | C2: Visit Window (days) | D2: 7 | E2: Shift Min | F2: 600 | G2: Svc Min/Stop | H2: 30
A3: ■ Red=Critical(≤2d) ■ Amber=Urgent(3–5d) ■ Green=Normal(6–7d) ■ Grey=Not needed │ Blue italic = live formula pulling from Delivery_Log │ Trend ▲INCREASING ▼DECREASING ●STABLE
A4: CLIENT & LOCATION | F4: TANK & CONSUMPTION | I4: LAST DELIVERY ← from log | K4: CALCULATED | O4: TREND | Q4: SCHEDULE
A5: ID | B5: Customer | C5: Zone | D5: Address | E5: Lat / Lon | F5: Tank (lbs) | G5: Avg Cons (lbs/day) | H5: Product | I5: Last Delivery | J5: Days Since | K5: Est. Current (lbs) | L5: Refill (lbs) | M5: Days Until Empty | N5: This Week? | O5: Trend | P5: # Deliveries | Q5: Priority | R5: Notes
A6: C001 | B6: 51ST - 0001 - 51ST AVE CAFE | C6: 2 | D6: =IFERROR(VLOOKUP(B6,Client_List!$B:$K,4,0)&", "&VLOOKUP(B6,Client_List!$B:$K,5,0)&" AZ","") -> 5511 N 51St Ave, Glendale AZ | E6: =IFERROR(VLOOKUP(B6,Client_List!$B:$K,7,0)&", "&VLOOKUP(B6,Client_List!$B:$K,8,0),"") -> 33.5171994, -112.1681115 | F6: =IFERROR(VLOOKUP(B6,Client_List!$B:$K,9,0),"") -> 350 | G6: =IFERROR(AVERAGEIFS(Delivery_Log!$I$4:$I$5000,Delivery_Log!$B$4:$B$5000,B6,Delivery_Log!$I$4:$I$5000,">"&0),"") -> 6.8965517 | H6: =IFERROR(VLOOKUP(B6,Client_List!$B:$K,10,0),"") -> FRYERS CHOICE BLEND | I6: =IFERROR(_xlfn.MAXIFS(Delivery_Log!$A$4:$A$5000,Delivery_Log!$B$4:$B$5000,B6),"—") -> 46084 | J6: =IFERROR(IF(I6="—","",TODAY()-I6),"") -> 45 | K6: =IFERROR(IF(OR(J6="",G6=""),"",MAX(F6*0.03,F6-J6*G6)),"") -> 39.655172 | L6: =IFERROR(IF(K6="","",F6-K6),"") -> 310.34483 | M6: =IFERROR(IF(OR(K6="",G6=""),"",MIN(21,MAX(0,(K6-F6*$B$2)/G6))),"") -> 5.75 | N6: =IFERROR(IF(M6="","—",IF(M6<=$D$2,"YES","—")),"—") -> YES | O6: insufficient data | P6: 2
A7: C002 | B7: AJO ALS 1018 | C7: 2 | D7: =IFERROR(VLOOKUP(B7,Client_List!$B:$K,4,0)&", "&VLOOKUP(B7,Client_List!$B:$K,5,0)&" AZ","") -> 7458 W Bell Rd, Glendale AZ | E7: =IFERROR(VLOOKUP(B7,Client_List!$B:$K,7,0)&", "&VLOOKUP(B7,Client_List!$B:$K,8,0),"") -> 33.6390173, -112.2197838 | F7: =IFERROR(VLOOKUP(B7,Client_List!$B:$K,9,0),"") -> 950 | G7: =IFERROR(AVERAGEIFS(Delivery_Log!$I$4:$I$5000,Delivery_Log!$B$4:$B$5000,B7,Delivery_Log!$I$4:$I$5000,">"&0),"") -> 77.324204 | H7: =IFERROR(VLOOKUP(B7,Client_List!$B:$K,10,0),"") -> CANOLA OIL | I7: =IFERROR(_xlfn.MAXIFS(Delivery_Log!$A$4:$A$5000,Delivery_Log!$B$4:$B$5000,B7),"—") -> 46119 | J7: =IFERROR(IF(I7="—","",TODAY()-I7),"") -> 10 | K7: =IFERROR(IF(OR(J7="",G7=""),"",MAX(F7*0.03,F7-J7*G7)),"") -> 176.75796 | L7: =IFERROR(IF(K7="","",F7-K7),"") -> 773.24204 | M7: =IFERROR(IF(OR(K7="",G7=""),"",MIN(21,MAX(0,(K7-F7*$B$2)/G7))),"") -> 2.2859332 | N7: =IFERROR(IF(M7="","—",IF(M7<=$D$2,"YES","—")),"—") -> YES | O7: STABLE | P7: 9
A8: C003 | B8: ALL - 1063 - ALL AMERICAN MODERN SPORTS GRILL | C8: 4 | D8: =IFERROR(VLOOKUP(B8,Client_List!$B:$K,4,0)&", "&VLOOKUP(B8,Client_List!$B:$K,5,0)&" AZ","") -> 20751 N PIMA RD #105, Scottsdale AZ | E8: =IFERROR(VLOOKUP(B8,Client_List!$B:$K,7,0)&", "&VLOOKUP(B8,Client_List!$B:$K,8,0),"") -> 33.674519, -111.8880329 | F8: =IFERROR(VLOOKUP(B8,Client_List!$B:$K,9,0),"") -> 900 | G8: =IFERROR(AVERAGEIFS(Delivery_Log!$I$4:$I$5000,Delivery_Log!$B$4:$B$5000,B8,Delivery_Log!$I$4:$I$5000,">"&0),"") -> 50.074835 | H8: =IFERROR(VLOOKUP(B8,Client_List!$B:$K,10,0),"") -> CANOLA OIL | I8: =IFERROR(_xlfn.MAXIFS(Delivery_Log!$A$4:$A$5000,Delivery_Log!$B$4:$B$5000,B8),"—") -> 46112 | J8: =IFERROR(IF(I8="—","",TODAY()-I8),"") -> 17 | K8: =IFERROR(IF(OR(J8="",G8=""),"",MAX(F8*0.03,F8-J8*G8)),"") -> 48.727811 | L8: =IFERROR(IF(K8="","",F8-K8),"") -> 851.27219 | M8: =IFERROR(IF(OR(K8="",G8=""),"",MIN(21,MAX(0,(K8-F8*$B$2)/G8))),"") -> 0.97309979 | N8: =IFERROR(IF(M8="","—",IF(M8<=$D$2,"YES","—")),"—") -> YES | O8: STABLE | P8: 7
A9: C004 | B9: AME - 1073 - AMELIO C ENTERPRISES, INC (CACTUS CANDY) | C9: 4 | D9: =IFERROR(VLOOKUP(B9,Client_List!$B:$K,4,0)&", "&VLOOKUP(B9,Client_List!$B:$K,5,0)&" AZ","") -> 2656 N 37TH DR, PHOENIX AZ | E9: =IFERROR(VLOOKUP(B9,Client_List!$B:$K,7,0)&", "&VLOOKUP(B9,Client_List!$B:$K,8,0),"") -> 33.4782767, -112.140515 | F9: =IFERROR(VLOOKUP(B9,Client_List!$B:$K,9,0),"") -> 2000 | G9: =IFERROR(AVERAGEIFS(Delivery_Log!$I$4:$I$5000,Delivery_Log!$B$4:$B$5000,B9,Delivery_Log!$I$4:$I$5000,">"&0),"") -> 10.236111 | H9: =IFERROR(VLOOKUP(B9,Client_List!$B:$K,10,0),"") -> CANOLA OIL | I9: =IFERROR(_xlfn.MAXIFS(Delivery_Log!$A$4:$A$5000,Delivery_Log!$B$4:$B$5000,B9),"—") -> 46099 | J9: =IFERROR(IF(I9="—","",TODAY()-I9),"") -> 30 | K9: =IFERROR(IF(OR(J9="",G9=""),"",MAX(F9*0.03,F9-J9*G9)),"") -> 1692.9167 | L9: =IFERROR(IF(K9="","",F9-K9),"") -> 307.08333 | M9: =IFERROR(IF(OR(K9="",G9=""),"",MIN(21,MAX(0,(K9-F9*$B$2)/G9))),"") -> 21 | N9: =IFERROR(IF(M9="","—",IF(M9<=$D$2,"YES","—")),"—") -> — | O9: insufficient data | P9: 2
A10: C005 | B10: ANG - 1054 - ANGRY CRAB SURPRISE | C10: 1 | D10: =IFERROR(VLOOKUP(B10,Client_List!$B:$K,4,0)&", "&VLOOKUP(B10,Client_List!$B:$K,5,0)&" AZ","") -> 11340 W BELL RD SUITE 118, SURPRISE AZ | E10: =IFERROR(VLOOKUP(B10,Client_List!$B:$K,7,0)&", "&VLOOKUP(B10,Client_List!$B:$K,8,0),"") -> 33.6399393, -112.3041939 | F10: =IFERROR(VLOOKUP(B10,Client_List!$B:$K,9,0),"") -> 620 | G10: =IFERROR(AVERAGEIFS(Delivery_Log!$I$4:$I$5000,Delivery_Log!$B$4:$B$5000,B10,Delivery_Log!$I$4:$I$5000,">"&0),"") -> 44.030091 | H10: =IFERROR(VLOOKUP(B10,Client_List!$B:$K,10,0),"") -> FRYERS CHOICE BLEND | I10: =IFERROR(_xlfn.MAXIFS(Delivery_Log!$A$4:$A$5000,Delivery_Log!$B$4:$B$5000,B10),"—") -> 46120 | J10: =IFERROR(IF(I10="—","",TODAY()-I10),"") -> 9 | K10: =IFERROR(IF(OR(J10="",G10=""),"",MAX(F10*0.03,F10-J10*G10)),"") -> 223.72918 | L10: =IFERROR(IF(K10="","",F10-K10),"") -> 396.27082 | M10: =IFERROR(IF(OR(K10="",G10=""),"",MIN(21,MAX(0,(K10-F10*$B$2)/G10))),"") -> 5.0812792 | N10: =IFERROR(IF(M10="","—",IF(M10<=$D$2,"YES","—")),"—") -> YES | O10: STABLE | P10: 8
A11: C006 | B11: ANOVA | C11: 1 | D11: =IFERROR(VLOOKUP(B11,Client_List!$B:$K,4,0)&", "&VLOOKUP(B11,Client_List!$B:$K,5,0)&" AZ","") | E11: =IFERROR(VLOOKUP(B11,Client_List!$B:$K,7,0)&", "&VLOOKUP(B11,Client_List!$B:$K,8,0),"") | F11: =IFERROR(VLOOKUP(B11,Client_List!$B:$K,9,0),"") | G11: =IFERROR(AVERAGEIFS(Delivery_Log!$I$4:$I$5000,Delivery_Log!$B$4:$B$5000,B11,Delivery_Log!$I$4:$I$5000,">"&0),"") | H11: =IFERROR(VLOOKUP(B11,Client_List!$B:$K,10,0),"") | I11: =IFERROR(_xlfn.MAXIFS(Delivery_Log!$A$4:$A$5000,Delivery_Log!$B$4:$B$5000,B11),"—") -> 0 | J11: =IFERROR(IF(I11="—","",TODAY()-I11),"") -> 46129 | K11: =IFERROR(IF(OR(J11="",G11=""),"",MAX(F11*0.03,F11-J11*G11)),"") | L11: =IFERROR(IF(K11="","",F11-K11),"") | M11: =IFERROR(IF(OR(K11="",G11=""),"",MIN(21,MAX(0,(K11-F11*$B$2)/G11))),"") | N11: =IFERROR(IF(M11="","—",IF(M11<=$D$2,"YES","—")),"—") -> — | O11: INCREASING | P11: 23
A12: C007 | B12: ARR79 - 1000 - ARRIBAS 79TH AVE. | C12: 2 | D12: =IFERROR(VLOOKUP(B12,Client_List!$B:$K,4,0)&", "&VLOOKUP(B12,Client_List!$B:$K,5,0)&" AZ","") -> 17211 N 79Th Ave, Glendale AZ | E12: =IFERROR(VLOOKUP(B12,Client_List!$B:$K,7,0)&", "&VLOOKUP(B12,Client_List!$B:$K,8,0),"") -> 33.6402137, -112.2294109 | F12: =IFERROR(VLOOKUP(B12,Client_List!$B:$K,9,0),"") -> 950 | G12: =IFERROR(AVERAGEIFS(Delivery_Log!$I$4:$I$5000,Delivery_Log!$B$4:$B$5000,B12,Delivery_Log!$I$4:$I$5000,">"&0),"") -> 73.041975 | H12: =IFERROR(VLOOKUP(B12,Client_List!$B:$K,10,0),"") -> CANOLA OIL | I12: =IFERROR(_xlfn.MAXIFS(Delivery_Log!$A$4:$A$5000,Delivery_Log!$B$4:$B$5000,B12),"—") -> 46120 | J12: =IFERROR(IF(I12="—","",TODAY()-I12),"") -> 9 | K12: =IFERROR(IF(OR(J12="",G12=""),"",MAX(F12*0.03,F12-J12*G12)),"") -> 292.62222 | L12: =IFERROR(IF(K12="","",F12-K12),"") -> 657.37778 | M12: =IFERROR(IF(OR(K12="",G12=""),"",MIN(21,MAX(0,(K12-F12*$B$2)/G12))),"") -> 4.00622 | N12: =IFERROR(IF(M12="","—",IF(M12<=$D$2,"YES","—")),"—") -> YES | O12: STABLE | P12: 9
A13: C008 | B13: ARRC - 1001 - ARRIBAS CAMELBACK | C13: 3 | D13: =IFERROR(VLOOKUP(B13,Client_List!$B:$K,4,0)&", "&VLOOKUP(B13,Client_List!$B:$K,5,0)&" AZ","") -> 1812 E Camelback Rd, Phoenix AZ | E13: =IFERROR(VLOOKUP(B13,Client_List!$B:$K,7,0)&", "&VLOOKUP(B13,Client_List!$B:$K,8,0),"") -> 33.50958, -112.042591 | F13: =IFERROR(VLOOKUP(B13,Client_List!$B:$K,9,0),"") -> 700 | G13: =IFERROR(AVERAGEIFS(Delivery_Log!$I$4:$I$5000,Delivery_Log!$B$4:$B$5000,B13,Delivery_Log!$I$4:$I$5000,">"&0),"") -> 61.722134 | H13: =IFERROR(VLOOKUP(B13,Client_List!$B:$K,10,0),"") -> CANOLA OIL | I13: =IFERROR(_xlfn.MAXIFS(Delivery_Log!$A$4:$A$5000,Delivery_Log!$B$4:$B$5000,B13),"—") -> 46119 | J13: =IFERROR(IF(I13="—","",TODAY()-I13),"") -> 10 | K13: =IFERROR(IF(OR(J13="",G13=""),"",MAX(F13*0.03,F13-J13*G13)),"") -> 82.778659 | L13: =IFERROR(IF(K13="","",F13-K13),"") -> 617.22134 | M13: =IFERROR(IF(OR(K13="",G13=""),"",MIN(21,MAX(0,(K13-F13*$B$2)/G13))),"") -> 1.3411503 | N13: =IFERROR(IF(M13="","—",IF(M13<=$D$2,"YES","—")),"—") -> YES | O13: STABLE | P13: 8
A14: C009 | B14: ARRC - 1011 - ARRIBAS CHANDLER | C14: 4 | D14: =IFERROR(VLOOKUP(B14,Client_List!$B:$K,4,0)&", "&VLOOKUP(B14,Client_List!$B:$K,5,0)&" AZ","") -> 4649 E Chandler Blvd, Phoenix AZ | E14: =IFERROR(VLOOKUP(B14,Client_List!$B:$K,7,0)&", "&VLOOKUP(B14,Client_List!$B:$K,8,0),"") -> 33.3048264, -111.9816146 | F14: =IFERROR(VLOOKUP(B14,Client_List!$B:$K,9,0),"") -> 1000 | G14: =IFERROR(AVERAGEIFS(Delivery_Log!$I$4:$I$5000,Delivery_Log!$B$4:$B$5000,B14,Delivery_Log!$I$4:$I$5000,">"&0),"") -> 68.782313 | H14: =IFERROR(VLOOKUP(B14,Client_List!$B:$K,10,0),"") -> CANOLA OIL | I14: =IFERROR(_xlfn.MAXIFS(Delivery_Log!$A$4:$A$5000,Delivery_Log!$B$4:$B$5000,B14),"—") -> 46122 | J14: =IFERROR(IF(I14="—","",TODAY()-I14),"") -> 7 | K14: =IFERROR(IF(OR(J14="",G14=""),"",MAX(F14*0.03,F14-J14*G14)),"") -> 518.52381 | L14: =IFERROR(IF(K14="","",F14-K14),"") -> 481.47619 | M14: =IFERROR(IF(OR(K14="",G14=""),"",MIN(21,MAX(0,(K14-F14*$B$2)/G14))),"") -> 7.5386213 | N14: =IFERROR(IF(M14="","—",IF(M14<=$D$2,"YES","—")),"—") -> — | O14: STABLE | P14: 7
A15: C010 | B15: ARRC - 1014 - ARRIBA GILBERT | C15: 5 | D15: =IFERROR(VLOOKUP(B15,Client_List!$B:$K,4,0)&", "&VLOOKUP(B15,Client_List!$B:$K,5,0)&" AZ","") -> 2855 S Market St, Gilbert, AZ 85295, Gilbert AZ | E15: =IFERROR(VLOOKUP(B15,Client_List!$B:$K,7,0)&", "&VLOOKUP(B15,Client_List!$B:$K,8,0),"") -> 33.29809, -111.744273 | F15: =IFERROR(VLOOKUP(B15,Client_List!$B:$K,9,0),"") -> 900 | G15: =IFERROR(AVERAGEIFS(Delivery_Log!$I$4:$I$5000,Delivery_Log!$B$4:$B$5000,B15,Delivery_Log!$I$4:$I$5000,">"&0),"") -> 58.116937 | H15: =IFERROR(VLOOKUP(B15,Client_List!$B:$K,10,0),"") -> CANOLA OIL | I15: =IFERROR(_xlfn.MAXIFS(Delivery_Log!$A$4:$A$5000,Delivery_Log!$B$4:$B$5000,B15),"—") -> 46119 | J15: =IFERROR(IF(I15="—","",TODAY()-I15),"") -> 10 | K15: =IFERROR(IF(OR(J15="",G15=""),"",MAX(F15*0.03,F15-J15*G15)),"") -> 318.83063 | L15: =IFERROR(IF(K15="","",F15-K15),"") -> 581.16937 | M15: =IFERROR(IF(OR(K15="",G15=""),"",MIN(21,MAX(0,(K15-F15*$B$2)/G15))),"") -> 5.4860191 | N15: =IFERROR(IF(M15="","—",IF(M15<=$D$2,"YES","—")),"—") -> YES | O15: STABLE | P15: 7
A16: C011 | B16: ARRM - 1013 - ARRIBAS GOODYEAR | C16: 1 | D16: =IFERROR(VLOOKUP(B16,Client_List!$B:$K,4,0)&", "&VLOOKUP(B16,Client_List!$B:$K,5,0)&" AZ","") -> 15370 W McDowell Rd, Goodyear AZ | E16: =IFERROR(VLOOKUP(B16,Client_List!$B:$K,7,0)&", "&VLOOKUP(B16,Client_List!$B:$K,8,0),"") -> 33.46499, -112.389902 | F16: =IFERROR(VLOOKUP(B16,Client_List!$B:$K,9,0),"") -> 900 | G16: =IFERROR(AVERAGEIFS(Delivery_Log!$I$4:$I$5000,Delivery_Log!$B$4:$B$5000,B16,Delivery_Log!$I$4:$I$5000,">"&0),"") -> 78.960185 | H16: =IFERROR(VLOOKUP(B16,Client_List!$B:$K,10,0),"") -> CANOLA OIL | I16: =IFERROR(_xlfn.MAXIFS(Delivery_Log!$A$4:$A$5000,Delivery_Log!$B$4:$B$5000,B16),"—") -> 46119 | J16: =IFERROR(IF(I16="—","",TODAY()-I16),"") -> 10 | K16: =IFERROR(IF(OR(J16="",G16=""),"",MAX(F16*0.03,F16-J16*G16)),"") -> 110.39815 | L16: =IFERROR(IF(K16="","",F16-K16),"") -> 789.60185 | M16: =IFERROR(IF(OR(K16="",G16=""),"",MIN(21,MAX(0,(K16-F16*$B$2)/G16))),"") -> 1.3981496 | N16: =IFERROR(IF(M16="","—",IF(M16<=$D$2,"YES","—")),"—") -> YES | O16: STABLE | P16: 9
A17: C012 | B17: ATL - 1081 - ATL WINGS ROOSEVELT | C17: 3 | D17: =IFERROR(VLOOKUP(B17,Client_List!$B:$K,4,0)&", "&VLOOKUP(B17,Client_List!$B:$K,5,0)&" AZ","") -> 330 E ROOSEVELT RD, PHOENIX AZ | E17: =IFERROR(VLOOKUP(B17,Client_List!$B:$K,7,0)&", "&VLOOKUP(B17,Client_List!$B:$K,8,0),"") -> 33.4589406, -112.0685493 | F17: =IFERROR(VLOOKUP(B17,Client_List!$B:$K,9,0),"") -> 350 | G17: =IFERROR(AVERAGEIFS(Delivery_Log!$I$4:$I$5000,Delivery_Log!$B$4:$B$5000,B17,Delivery_Log!$I$4:$I$5000,">"&0),"") -> 42.610863 | H17: =IFERROR(VLOOKUP(B17,Client_List!$B:$K,10,0),"") -> CANOLA OIL | I17: =IFERROR(_xlfn.MAXIFS(Delivery_Log!$A$4:$A$5000,Delivery_Log!$B$4:$B$5000,B17),"—") -> 46098 | J17: =IFERROR(IF(I17="—","",TODAY()-I17),"") -> 31 | K17: =IFERROR(IF(OR(J17="",G17=""),"",MAX(F17*0.03,F17-J17*G17)),"") -> 10.5 | L17: =IFERROR(IF(K17="","",F17-K17),"") -> 339.5 | M17: =IFERROR(IF(OR(K17="",G17=""),"",MIN(21,MAX(0,(K17-F17*$B$2)/G17))),"") -> 0.24641604 | N17: =IFERROR(IF(M17="","—",IF(M17<=$D$2,"YES","—")),"—") -> YES | O17: STABLE | P17: 11
... A162: C157 | B162: anova | C162: 4 | D162: =IFERROR(VLOOKUP(B162,Client_List!$B:$K,4,0)&", "&VLOOKUP(B162,Client_List!$B:$K,5,0)&" AZ","") | E162: =IFERROR(VLOOKUP(B162,Client_List!$B:$K,7,0)&", "&VLOOKUP(B162,Client_List!$B:$K,8,0),"") | F162: =IFERROR(VLOOKUP(B162,Client_List!$B:$K,9,0),"") | G162: =IFERROR(AVERAGEIFS(Delivery_Log!$I$4:$I$5000,Delivery_Log!$B$4:$B$5000,B162,Delivery_Log!$I$4:$I$5000,">"&0),"") | H162: =IFERROR(VLOOKUP(B162,Client_List!$B:$K,10,0),"") | I162: =IFERROR(_xlfn.MAXIFS(Delivery_Log!$A$4:$A$5000,Delivery_Log!$B$4:$B$5000,B162),"—") -> 0 | J162: =IFERROR(IF(I162="—","",TODAY()-I162),"") -> 46129 | K162: =IFERROR(IF(OR(J162="",G162=""),"",MAX(F162*0.03,F162-J162*G162)),"") | L162: =IFERROR(IF(K162="","",F162-K162),"") | M162: =IFERROR(IF(OR(K162="",G162=""),"",MIN(21,MAX(0,(K162-F162*$B$2)/G162))),"") | N162: =IFERROR(IF(M162="","—",IF(M162<=$D$2,"YES","—")),"—") -> — | O162: STABLE | P162: 5

Sheet Client_Time_Windows
A1: Client Time Windows — one row per (client, day) pair. Leave empty if no restrictions.
A2: Blank = client is open all shift. Add rows only for clients with restricted hours.
A3: Client_ID | B3: Day_of_Week | C3: Open_HHMM | D3: Close_HHMM | E3: Notes
A4: EXAMPLE_C042 | B4: Tue | C4: 10:00 | D4: 14:00 | E4: No deliveries during lunch rush (example — delete this row)

Sheet Client_Closures
A1: Client Closures — date-range closures (vacations, renovations, etc.)
A2: Inclusive on both ends. Solver skips these clients on those days.
A3: Client_ID | B3: Start_Date | C3: End_Date | D3: Reason
A4: EXAMPLE_C042 | B4: 2026-04-20 | C4: 2026-04-27 | D4: Renovations (example — delete this row)

Sheet Trucks
A1: Truck Configuration
A2: Truck_Name | B2: Capacity_lbs | C2: Pump_Rate_lbs_per_min | D2: Fixed_Setup_min
A3: Truck2 | B3: 10000 | C3: 152.6 | D3: 18
A4: Truck9 | B4: 10000 | C4: 206 | D4: 18

Sheet Depot
A1: Depot Configuration (key-value pairs)
A2: Key | B2: Value
A3: Depot_Lat | B3: 33.5152
A4: Depot_Lon | B4: -112.1674
A5: Shift_Start_HHMM | B5: 06:00
A6: Shift_End_HHMM | B6: 16:00
A7: Morning_Load_Min | B7: 30
A8: Evening_Unload_Min | B8: 15
A9: Work_Days | B9: Tue,Wed,Thu,Fri,Sat
