Workbook

Sheet Delivery_Log
A1: S&K OIL SALES — DELIVERY LOG ↓ Append new deliveries below. Column B = Customer # (numeric ID). Column D = lbs delivered.
A2: Columns C, E–K auto-calculate. Do NOT re-sort rows.
A3: Date | B3: Customer # | C3: Customer Name ←auto | D3: Qty Delivered (lbs) | E3: Zone ←auto | F3: Zone Code ←auto | G3: Product ←auto | H3: Tank (lbs) ←auto | I3: Days Since Last ←auto | J3: Lbs/Day ←auto | K3: Running Avg Lbs/Day ←auto
A4: 45955 | B4: 1073 | D4: 1903
A5: 45965 | B5: 19107 | D5: 228
A6: 46024 | B6: 1083 | D6: 354
A7: 46024 | B7: 3063 | D7: 1596
A8: 46024 | B8: 4037 | D8: 361
A9: 46024 | B9: 8031 | D9: 705
A10: 46024 | B10: 10001 | D10: 882
A11: 46024 | B11: 14008 | D11: 1151
A12: 46024 | B12: 15035 | D12: 1401
A13: 46024 | B13: 16010 | D13: 1737
A14: 46025 | B14: 1057 | D14: 591
A15: 46025 | B15: 2016 | D15: 265
... A81: 46031 | B81: 2067 | D81: 789
A82: 46031 | B82: 4015A | D82: 480
A83: 46031 | B83: 7001 | D83: 1347
A84: 46031 | B84: 13009 | D84: 832
A85: 46031 | B85: 15016 | D85: 340
A86: 46031 | B86: 16015 | D86: 1514
A87: 46031 | B87: 22006 | D87: 676
A88: 46032 | B88: 11005 | D88: 639
A89: 46032 | B89: 12021 | D89: 348
A90: 46032 | B90: 15004 | D90: 386
A91: 46032 | B91: 15032 | D91: 632
A92: 46033 | B92: 1000 | D92: 938
A93: 46033 | B93: 1081 | D93: 307
A94: 46033 | B94: 4026 | D94: 336
... A238: 46045 | B238: 4009 | D238: 677
A239: 46045 | B239: 4015A | D239: 490
A240: 46045 | B240: 6101 | D240: 641
A241: 46045 | B241: 8034 | D241: 609
A242: 46045 | B242: 12025 | D242: 381
A243: 46045 | B243: 13015 | D243: 946
A244: 46045 | B244: 13061 | D244: 340
A245: 46045 | B245: 13069 | D245: 958
A246: 46045 | B246: 15016 | D246: 318
A247: 46045 | B247: 16007 | D247: 494
A248: 46045 | B248: 16009 | D248: 1484
...

Sheet Client_List
A1: S&K CLIENT LIST — Edit Address, Lat, Lon, Tank Size and Product here
A2: YELLOW columns = edit freely. Changes here flow automatically into Optimizer_Input via VLOOKUP. Customer name in col B must match Delivery_Log exactly.
A3: ID | B3: Customer Name | C3: Zone | D3: Zone Code | E3: Street Address | F3: City | G3: State | H3: Latitude | I3: Longitude | J3: Tank Size (lbs) | K3: Product | O3: ANOVA | P3: Notes | Q3: Do_Not_Schedule | R3: RTU ID | S3: Anova Level (lbs) | T3: Anova % Full | U3: Anova Last Reading | V3: Anova Deliverable | W3: Anova Age (hrs) | X3: Anova Source
A4: 1 | B4: 51ST - 0001 - 51ST AVE CAFE | C4: 2 | D4: 2D | E4: 5511 N 51St Ave | F4: Glendale | G4: AZ | H4: 33.517199 | I4: -112.16811 | J4: 350 | K4: FRYERS CHOICE BLEND | N4: 254-237-3350 | R4: =IFERROR(_xlfn.XLOOKUP($A4,Anova_Live!$B$2:$B$60,Anova_Live!$A$2:$A$60,""),"") | S4: =IFERROR(_xlfn.XLOOKUP($A4,Anova_Live!$B$2:$B$60,Anova_Live!$E$2:$E$60,""),"") | T4: =IFERROR(_xlfn.XLOOKUP($A4,Anova_Live!$B$2:$B$60,Anova_Live!$K$2:$K$60,""),"") | U4: =IFERROR(_xlfn.XLOOKUP($A4,Anova_Live!$B$2:$B$60,Anova_Live!$H$2:$H$60,""),"") | V4: =IFERROR(_xlfn.XLOOKUP($A4,Anova_Live!$B$2:$B$60,Anova_Live!$L$2:$L$60,""),"") | W4: =IFERROR(_xlfn.XLOOKUP($A4,Anova_Live!$B$2:$B$60,Anova_Live!$M$2:$M$60,""),"") | X4: =IFERROR(_xlfn.XLOOKUP($A4,Anova_Live!$B$2:$B$60,Anova_Live!$N$2:$N$60,""),"")
A5: 1018 | B5: AJO - 1018 - AJO ALS BELL | C5: 2 | D5: 2C | E5: 7458 W Bell Rd | F5: Glendale | G5: AZ | H5: 33.639017 | I5: -112.21978 | J5: 950 | K5: CANOLA OIL | N5: 623-334-9899 | R5: =IFERROR(_xlfn.XLOOKUP($A5,Anova_Live!$B$2:$B$60,Anova_Live!$A$2:$A$60,""),"") | S5: =IFERROR(_xlfn.XLOOKUP($A5,Anova_Live!$B$2:$B$60,Anova_Live!$E$2:$E$60,""),"") | T5: =IFERROR(_xlfn.XLOOKUP($A5,Anova_Live!$B$2:$B$60,Anova_Live!$K$2:$K$60,""),"") | U5: =IFERROR(_xlfn.XLOOKUP($A5,Anova_Live!$B$2:$B$60,Anova_Live!$H$2:$H$60,""),"") | V5: =IFERROR(_xlfn.XLOOKUP($A5,Anova_Live!$B$2:$B$60,Anova_Live!$L$2:$L$60,""),"") | W5: =IFERROR(_xlfn.XLOOKUP($A5,Anova_Live!$B$2:$B$60,Anova_Live!$M$2:$M$60,""),"") | X5: =IFERROR(_xlfn.XLOOKUP($A5,Anova_Live!$B$2:$B$60,Anova_Live!$N$2:$N$60,""),"")
A6: 1063 | B6: ALL - 1063 - ALL AMERICAN MODERN SPORTS GRILL | C6: 4 | D6: 4C | E6: 20751 N PIMA RD #105 | F6: Scottsdale | G6: AZ | H6: 33.674519 | I6: -111.88803 | J6: 900 | K6: CANOLA OIL | N6: (480) 887-0652 | R6: =IFERROR(_xlfn.XLOOKUP($A6,Anova_Live!$B$2:$B$60,Anova_Live!$A$2:$A$60,""),"") | S6: =IFERROR(_xlfn.XLOOKUP($A6,Anova_Live!$B$2:$B$60,Anova_Live!$E$2:$E$60,""),"") | T6: =IFERROR(_xlfn.XLOOKUP($A6,Anova_Live!$B$2:$B$60,Anova_Live!$K$2:$K$60,""),"") | U6: =IFERROR(_xlfn.XLOOKUP($A6,Anova_Live!$B$2:$B$60,Anova_Live!$H$2:$H$60,""),"") | V6: =IFERROR(_xlfn.XLOOKUP($A6,Anova_Live!$B$2:$B$60,Anova_Live!$L$2:$L$60,""),"") | W6: =IFERROR(_xlfn.XLOOKUP($A6,Anova_Live!$B$2:$B$60,Anova_Live!$M$2:$M$60,""),"") | X6: =IFERROR(_xlfn.XLOOKUP($A6,Anova_Live!$B$2:$B$60,Anova_Live!$N$2:$N$60,""),"")
A7: 1073 | B7: AME - 1073 - AMELIO C ENTERPRISES, INC (CACTUS CANDY) | C7: 4 | D7: 4C | E7: 2656 N 37TH DR | F7: PHOENIX | G7: AZ | H7: 33.478277 | I7: -112.14051 | J7: 2000 | K7: CANOLA OIL | N7: (602) 956-4833 | P7: DO NOT PUT IN ROUTE SCHEDULE | Q7: Y | R7: =IFERROR(_xlfn.XLOOKUP($A7,Anova_Live!$B$2:$B$60,Anova_Live!$A$2:$A$60,""),"") | S7: =IFERROR(_xlfn.XLOOKUP($A7,Anova_Live!$B$2:$B$60,Anova_Live!$E$2:$E$60,""),"") | T7: =IFERROR(_xlfn.XLOOKUP($A7,Anova_Live!$B$2:$B$60,Anova_Live!$K$2:$K$60,""),"") | U7: =IFERROR(_xlfn.XLOOKUP($A7,Anova_Live!$B$2:$B$60,Anova_Live!$H$2:$H$60,""),"") | V7: =IFERROR(_xlfn.XLOOKUP($A7,Anova_Live!$B$2:$B$60,Anova_Live!$L$2:$L$60,""),"") | W7: =IFERROR(_xlfn.XLOOKUP($A7,Anova_Live!$B$2:$B$60,Anova_Live!$M$2:$M$60,""),"") | X7: =IFERROR(_xlfn.XLOOKUP($A7,Anova_Live!$B$2:$B$60,Anova_Live!$N$2:$N$60,""),"")
A8: 1054 | B8: ANG - 1054 - ANGRY CRAB SURPRISE | C8: 1 | D8: 1C | E8: 11340 W BELL RD SUITE 118 | F8: SURPRISE | G8: AZ | H8: 33.639939 | I8: -112.30419 | J8: 620 | K8: FRYERS CHOICE BLEND | N8: (623) 248-9190 | R8: =IFERROR(_xlfn.XLOOKUP($A8,Anova_Live!$B$2:$B$60,Anova_Live!$A$2:$A$60,""),"") -> 124697513 | S8: =IFERROR(_xlfn.XLOOKUP($A8,Anova_Live!$B$2:$B$60,Anova_Live!$E$2:$E$60,""),"") -> 325.48623 | T8: =IFERROR(_xlfn.XLOOKUP($A8,Anova_Live!$B$2:$B$60,Anova_Live!$K$2:$K$60,""),"") -> 52.5 | U8: =IFERROR(_xlfn.XLOOKUP($A8,Anova_Live!$B$2:$B$60,Anova_Live!$H$2:$H$60,""),"") -> 2026-05-06T11:00:25Z | V8: =IFERROR(_xlfn.XLOOKUP($A8,Anova_Live!$B$2:$B$60,Anova_Live!$L$2:$L$60,""),"") -> 295 | W8: =IFERROR(_xlfn.XLOOKUP($A8,Anova_Live!$B$2:$B$60,Anova_Live!$M$2:$M$60,""),"") | X8: =IFERROR(_xlfn.XLOOKUP($A8,Anova_Live!$B$2:$B$60,Anova_Live!$N$2:$N$60,""),"") -> push
A9: 1000 | B9: ARR79 - 1000 - ARRIBAS 79TH AVE. | C9: 2 | D9: 2C | E9: 17211 N 79Th Ave | F9: Glendale | G9: AZ | H9: 33.640214 | I9: -112.22941 | J9: 950 | K9: CANOLA OIL | N9: 623-878-5777 | R9: =IFERROR(_xlfn.XLOOKUP($A9,Anova_Live!$B$2:$B$60,Anova_Live!$A$2:$A$60,""),"") | S9: =IFERROR(_xlfn.XLOOKUP($A9,Anova_Live!$B$2:$B$60,Anova_Live!$E$2:$E$60,""),"") | T9: =IFERROR(_xlfn.XLOOKUP($A9,Anova_Live!$B$2:$B$60,Anova_Live!$K$2:$K$60,""),"") | U9: =IFERROR(_xlfn.XLOOKUP($A9,Anova_Live!$B$2:$B$60,Anova_Live!$H$2:$H$60,""),"") | V9: =IFERROR(_xlfn.XLOOKUP($A9,Anova_Live!$B$2:$B$60,Anova_Live!$L$2:$L$60,""),"") | W9: =IFERROR(_xlfn.XLOOKUP($A9,Anova_Live!$B$2:$B$60,Anova_Live!$M$2:$M$60,""),"") | X9: =IFERROR(_xlfn.XLOOKUP($A9,Anova_Live!$B$2:$B$60,Anova_Live!$N$2:$N$60,""),"")
A10: 1001 | B10: ARRC - 1001 - ARRIBAS CAMELBACK | C10: 3 | D10: 3D | E10: 1812 E Camelback Rd | F10: Phoenix | G10: AZ | H10: 33.50958 | I10: -112.04259 | J10: 700 | K10: CANOLA OIL | N10: 480-948-9969 | R10: =IFERROR(_xlfn.XLOOKUP($A10,Anova_Live!$B$2:$B$60,Anova_Live!$A$2:$A$60,""),"") | S10: =IFERROR(_xlfn.XLOOKUP($A10,Anova_Live!$B$2:$B$60,Anova_Live!$E$2:$E$60,""),"") | T10: =IFERROR(_xlfn.XLOOKUP($A10,Anova_Live!$B$2:$B$60,Anova_Live!$K$2:$K$60,""),"") | U10: =IFERROR(_xlfn.XLOOKUP($A10,Anova_Live!$B$2:$B$60,Anova_Live!$H$2:$H$60,""),"") | V10: =IFERROR(_xlfn.XLOOKUP($A10,Anova_Live!$B$2:$B$60,Anova_Live!$L$2:$L$60,""),"") | W10: =IFERROR(_xlfn.XLOOKUP($A10,Anova_Live!$B$2:$B$60,Anova_Live!$M$2:$M$60,""),"") | X10: =IFERROR(_xlfn.XLOOKUP($A10,Anova_Live!$B$2:$B$60,Anova_Live!$N$2:$N$60,""),"")
A11: 1011 | B11: ARRC - 1011 - ARRIBAS CHANDLER | C11: 4 | D11: 4F | E11: 4649 E Chandler Blvd | F11: Phoenix | G11: AZ | H11: 33.304826 | I11: -111.98161 | J11: 1000 | K11: CANOLA OIL | N11: 623-878-5777 | R11: =IFERROR(_xlfn.XLOOKUP($A11,Anova_Live!$B$2:$B$60,Anova_Live!$A$2:$A$60,""),"") | S11: =IFERROR(_xlfn.XLOOKUP($A11,Anova_Live!$B$2:$B$60,Anova_Live!$E$2:$E$60,""),"") | T11: =IFERROR(_xlfn.XLOOKUP($A11,Anova_Live!$B$2:$B$60,Anova_Live!$K$2:$K$60,""),"") | U11: =IFERROR(_xlfn.XLOOKUP($A11,Anova_Live!$B$2:$B$60,Anova_Live!$H$2:$H$60,""),"") | V11: =IFERROR(_xlfn.XLOOKUP($A11,Anova_Live!$B$2:$B$60,Anova_Live!$L$2:$L$60,""),"") | W11: =IFERROR(_xlfn.XLOOKUP($A11,Anova_Live!$B$2:$B$60,Anova_Live!$M$2:$M$60,""),"") | X11: =IFERROR(_xlfn.XLOOKUP($A11,Anova_Live!$B$2:$B$60,Anova_Live!$N$2:$N$60,""),"")
A12: 1014 | B12: ARRC - 1014 - ARRIBA GILBERT | C12: 5 | D12: 5F | E12: 2855 S Market St, Gilbert, AZ 85295 | F12: Gilbert | G12: AZ | H12: 33.29809 | I12: -111.74427 | J12: 900 | K12: CANOLA OIL | N12: 480-899-7337 | R12: =IFERROR(_xlfn.XLOOKUP($A12,Anova_Live!$B$2:$B$60,Anova_Live!$A$2:$A$60,""),"") | S12: =IFERROR(_xlfn.XLOOKUP($A12,Anova_Live!$B$2:$B$60,Anova_Live!$E$2:$E$60,""),"") | T12: =IFERROR(_xlfn.XLOOKUP($A12,Anova_Live!$B$2:$B$60,Anova_Live!$K$2:$K$60,""),"") | U12: =IFERROR(_xlfn.XLOOKUP($A12,Anova_Live!$B$2:$B$60,Anova_Live!$H$2:$H$60,""),"") | V12: =IFERROR(_xlfn.XLOOKUP($A12,Anova_Live!$B$2:$B$60,Anova_Live!$L$2:$L$60,""),"") | W12: =IFERROR(_xlfn.XLOOKUP($A12,Anova_Live!$B$2:$B$60,Anova_Live!$M$2:$M$60,""),"") | X12: =IFERROR(_xlfn.XLOOKUP($A12,Anova_Live!$B$2:$B$60,Anova_Live!$N$2:$N$60,""),"")
A13: 1013 | B13: ARRM - 1013 - ARRIBAS GOODYEAR | C13: 1 | D13: 1D | E13: 15370 W McDowell Rd | F13: Goodyear | G13: AZ | H13: 33.46499 | I13: -112.3899 | J13: 900 | K13: CANOLA OIL | N13: 623-223-1735 | P13: SCHEDULE 4/30 | R13: =IFERROR(_xlfn.XLOOKUP($A13,Anova_Live!$B$2:$B$60,Anova_Live!$A$2:$A$60,""),"") | S13: =IFERROR(_xlfn.XLOOKUP($A13,Anova_Live!$B$2:$B$60,Anova_Live!$E$2:$E$60,""),"") | T13: =IFERROR(_xlfn.XLOOKUP($A13,Anova_Live!$B$2:$B$60,Anova_Live!$K$2:$K$60,""),"") | U13: =IFERROR(_xlfn.XLOOKUP($A13,Anova_Live!$B$2:$B$60,Anova_Live!$H$2:$H$60,""),"") | V13: =IFERROR(_xlfn.XLOOKUP($A13,Anova_Live!$B$2:$B$60,Anova_Live!$L$2:$L$60,""),"") | W13: =IFERROR(_xlfn.XLOOKUP($A13,Anova_Live!$B$2:$B$60,Anova_Live!$M$2:$M$60,""),"") | X13: =IFERROR(_xlfn.XLOOKUP($A13,Anova_Live!$B$2:$B$60,Anova_Live!$N$2:$N$60,""),"")
A14: 1081 | B14: ATL - 1081 - ATL WINGS ROOSEVELT | C14: 3 | D14: 3D | E14: 330 E ROOSEVELT RD | F14: PHOENIX | G14: AZ | H14: 33.458941 | I14: -112.06855 | J14: 350 | K14: CANOLA OIL | N14: (602) 741-9554 | P14: SCHEDULE 4/29 | R14: =IFERROR(_xlfn.XLOOKUP($A14,Anova_Live!$B$2:$B$60,Anova_Live!$A$2:$A$60,""),"") | S14: =IFERROR(_xlfn.XLOOKUP($A14,Anova_Live!$B$2:$B$60,Anova_Live!$E$2:$E$60,""),"") | T14: =IFERROR(_xlfn.XLOOKUP($A14,Anova_Live!$B$2:$B$60,Anova_Live!$K$2:$K$60,""),"") | U14: =IFERROR(_xlfn.XLOOKUP($A14,Anova_Live!$B$2:$B$60,Anova_Live!$H$2:$H$60,""),"") | V14: =IFERROR(_xlfn.XLOOKUP($A14,Anova_Live!$B$2:$B$60,Anova_Live!$L$2:$L$60,""),"") | W14: =IFERROR(_xlfn.XLOOKUP($A14,Anova_Live!$B$2:$B$60,Anova_Live!$M$2:$M$60,""),"") | X14: =IFERROR(_xlfn.XLOOKUP($A14,Anova_Live!$B$2:$B$60,Anova_Live!$N$2:$N$60,""),"")
A15: 1083 | B15: ATL - 1083 - ATL WINGS MESA | C15: 5 | D15: 5D | E15: 6837 E MAIN ST | F15: Mesa | G15: AZ | H15: 33.415147 | I15: -111.68318 | J15: 425 | K15: CANOLA OIL | N15: (480) 722-9464 | P15: SCHEDULE 4/28 | R15: =IFERROR(_xlfn.XLOOKUP($A15,Anova_Live!$B$2:$B$60,Anova_Live!$A$2:$A$60,""),"") | S15: =IFERROR(_xlfn.XLOOKUP($A15,Anova_Live!$B$2:$B$60,Anova_Live!$E$2:$E$60,""),"") | T15: =IFERROR(_xlfn.XLOOKUP($A15,Anova_Live!$B$2:$B$60,Anova_Live!$K$2:$K$60,""),"") | U15: =IFERROR(_xlfn.XLOOKUP($A15,Anova_Live!$B$2:$B$60,Anova_Live!$H$2:$H$60,""),"") | V15: =IFERROR(_xlfn.XLOOKUP($A15,Anova_Live!$B$2:$B$60,Anova_Live!$L$2:$L$60,""),"") | W15: =IFERROR(_xlfn.XLOOKUP($A15,Anova_Live!$B$2:$B$60,Anova_Live!$M$2:$M$60,""),"") | X15: =IFERROR(_xlfn.XLOOKUP($A15,Anova_Live!$B$2:$B$60,Anova_Live!$N$2:$N$60,""),"")
A16: 19039 | B16: BAC - 19039 - BACKYARD GILBERT | C16: 5 | D16: 5F | E16: BACKYARD (SANDBAR) GILBERT | F16: Gilbert | G16: AZ | H16: 33.306216 | I16: -111.74755 | J16: 1050 | K16: FRYERS CHOICE BLEND | N16: 480-822-6921 | O16: Y | R16: =IFERROR(_xlfn.XLOOKUP($A16,Anova_Live!$B$2:$B$60,Anova_Live!$A$2:$A$60,""),"") | S16: =IFERROR(_xlfn.XLOOKUP($A16,Anova_Live!$B$2:$B$60,Anova_Live!$E$2:$E$60,""),"") | T16: =IFERROR(_xlfn.XLOOKUP($A16,Anova_Live!$B$2:$B$60,Anova_Live!$K$2:$K$60,""),"") | U16: =IFERROR(_xlfn.XLOOKUP($A16,Anova_Live!$B$2:$B$60,Anova_Live!$H$2:$H$60,""),"") | V16: =IFERROR(_xlfn.XLOOKUP($A16,Anova_Live!$B$2:$B$60,Anova_Live!$L$2:$L$60,""),"") | W16: =IFERROR(_xlfn.XLOOKUP($A16,Anova_Live!$B$2:$B$60,Anova_Live!$M$2:$M$60,""),"") | X16: =IFERROR(_xlfn.XLOOKUP($A16,Anova_Live!$B$2:$B$60,Anova_Live!$N$2:$N$60,""),"")
A17: 2067 | B17: BAC - 2067 - BACKYARD - DESERT RIDGE | C17: 5 | D17: 5F | E17: 21001 N Tatum Blvd | F17: Phoenix | G17: AZ | H17: 33.676643 | I17: -111.97461 | J17: 950 | K17: CANOLA OIL | N17: 480-585-5900 | O17: Y | R17: =IFERROR(_xlfn.XLOOKUP($A17,Anova_Live!$B$2:$B$60,Anova_Live!$A$2:$A$60,""),"") | S17: =IFERROR(_xlfn.XLOOKUP($A17,Anova_Live!$B$2:$B$60,Anova_Live!$E$2:$E$60,""),"") | T17: =IFERROR(_xlfn.XLOOKUP($A17,Anova_Live!$B$2:$B$60,Anova_Live!$K$2:$K$60,""),"") | U17: =IFERROR(_xlfn.XLOOKUP($A17,Anova_Live!$B$2:$B$60,Anova_Live!$H$2:$H$60,""),"") | V17: =IFERROR(_xlfn.XLOOKUP($A17,Anova_Live!$B$2:$B$60,Anova_Live!$L$2:$L$60,""),"") | W17: =IFERROR(_xlfn.XLOOKUP($A17,Anova_Live!$B$2:$B$60,Anova_Live!$M$2:$M$60,""),"") | X17: =IFERROR(_xlfn.XLOOKUP($A17,Anova_Live!$B$2:$B$60,Anova_Live!$N$2:$N$60,""),"")
A18: 2053 | B18: BAJ - 2053 - BAJA JOES | C18: 5 | D18: 5D | E18: 1927 N Gilbert Road | F18: Gilbert | G18: AZ | H18: 33.450725 | I18: -111.78643 | J18: 1050 | K18: CANOLA OIL | N18: (480) 655-1828 | O18: Y | R18: =IFERROR(_xlfn.XLOOKUP($A18,Anova_Live!$B$2:$B$60,Anova_Live!$A$2:$A$60,""),"") | S18: =IFERROR(_xlfn.XLOOKUP($A18,Anova_Live!$B$2:$B$60,Anova_Live!$E$2:$E$60,""),"") | T18: =IFERROR(_xlfn.XLOOKUP($A18,Anova_Live!$B$2:$B$60,Anova_Live!$K$2:$K$60,""),"") | U18: =IFERROR(_xlfn.XLOOKUP($A18,Anova_Live!$B$2:$B$60,Anova_Live!$H$2:$H$60,""),"") | V18: =IFERROR(_xlfn.XLOOKUP($A18,Anova_Live!$B$2:$B$60,Anova_Live!$L$2:$L$60,""),"") | W18: =IFERROR(_xlfn.XLOOKUP($A18,Anova_Live!$B$2:$B$60,Anova_Live!$M$2:$M$60,""),"") | X18: =IFERROR(_xlfn.XLOOKUP($A18,Anova_Live!$B$2:$B$60,Anova_Live!$N$2:$N$60,""),"")
A19: 2045 | B19: BAR - 2045 - BARRIO BREWING | C19: 5 | D19: 5F | E19: 5803 S Sossaman Rd | F19: Mesa | G19: AZ | H19: 33.310743 | I19: -111.66987 | J19: 350 | K19: CANOLA OIL | N19: (480) 988-7171 | R19: =IFERROR(_xlfn.XLOOKUP($A19,Anova_Live!$B$2:$B$60,Anova_Live!$A$2:$A$60,""),"") | S19: =IFERROR(_xlfn.XLOOKUP($A19,Anova_Live!$B$2:$B$60,Anova_Live!$E$2:$E$60,""),"") | T19: =IFERROR(_xlfn.XLOOKUP($A19,Anova_Live!$B$2:$B$60,Anova_Live!$K$2:$K$60,""),"") | U19: =IFERROR(_xlfn.XLOOKUP($A19,Anova_Live!$B$2:$B$60,Anova_Live!$H$2:$H$60,""),"") | V19: =IFERROR(_xlfn.XLOOKUP($A19,Anova_Live!$B$2:$B$60,Anova_Live!$L$2:$L$60,""),"") | W19: =IFERROR(_xlfn.XLOOKUP($A19,Anova_Live!$B$2:$B$60,Anova_Live!$M$2:$M$60,""),"") | X19: =IFERROR(_xlfn.XLOOKUP($A19,Anova_Live!$B$2:$B$60,Anova_Live!$N$2:$N$60,""),"")
A20: 2038 | B20: BEL - 2038 - BELLE'S NASHVILLE KITCHEN | C20: 4 | D20: 4D | E20: 7212 E MAIN ST | F20: Scottsdale | G20: A Z | H20: 33.493391 | I20: -111.92563 | J20: 620 | K20: CANOLA OIL | N20: (916) 730-3071 | R20: =IFERROR(_xlfn.XLOOKUP($A20,Anova_Live!$B$2:$B$60,Anova_Live!$A$2:$A$60,""),"") | S20: =IFERROR(_xlfn.XLOOKUP($A20,Anova_Live!$B$2:$B$60,Anova_Live!$E$2:$E$60,""),"") | T20: =IFERROR(_xlfn.XLOOKUP($A20,Anova_Live!$B$2:$B$60,Anova_Live!$K$2:$K$60,""),"") | U20: =IFERROR(_xlfn.XLOOKUP($A20,Anova_Live!$B$2:$B$60,Anova_Live!$H$2:$H$60,""),"") | V20: =IFERROR(_xlfn.XLOOKUP($A20,Anova_Live!$B$2:$B$60,Anova_Live!$L$2:$L$60,""),"") | W20: =IFERROR(_xlfn.XLOOKUP($A20,Anova_Live!$B$2:$B$60,Anova_Live!$M$2:$M$60,""),"") | X20: =IFERROR(_xlfn.XLOOKUP($A20,Anova_Live!$B$2:$B$60,Anova_Live!$N$2:$N$60,""),"")
A21: 2023 | B21: BOO - 2023 - BOOTY GOODYEAR | C21: 1 | D21: 1D | E21: 13375 W MCDOWELL RD STE 101 | F21: GOODYEAR | G21: AZ | H21: 33.463417 | I21: -112.3468 | J21: 620 | K21: CANOLA OIL | N21: 999-999-9999 | P21: SCHEDULE 4/29 | R21: =IFERROR(_xlfn.XLOOKUP($A21,Anova_Live!$B$2:$B$60,Anova_Live!$A$2:$A$60,""),"") | S21: =IFERROR(_xlfn.XLOOKUP($A21,Anova_Live!$B$2:$B$60,Anova_Live!$E$2:$E$60,""),"") | T21: =IFERROR(_xlfn.XLOOKUP($A21,Anova_Live!$B$2:$B$60,Anova_Live!$K$2:$K$60,""),"") | U21: =IFERROR(_xlfn.XLOOKUP($A21,Anova_Live!$B$2:$B$60,Anova_Live!$H$2:$H$60,""),"") | V21: =IFERROR(_xlfn.XLOOKUP($A21,Anova_Live!$B$2:$B$60,Anova_Live!$L$2:$L$60,""),"") | W21: =IFERROR(_xlfn.XLOOKUP($A21,Anova_Live!$B$2:$B$60,Anova_Live!$M$2:$M$60,""),"") | X21: =IFERROR(_xlfn.XLOOKUP($A21,Anova_Live!$B$2:$B$60,Anova_Live!$N$2:$N$60,""),"")
A22: 2017 | B22: BOOW - 2017 - BOOTY'S WATSON | C22: 1 | D22: 1D | E22: 1300 S Watson Rd Ste 109 | F22: Buckeye | G22: AZ | H22: 33.434781 | I22: -112.5586 | J22: 620 | K22: CANOLA OIL | N22: 623-386-3080 | O22: Y | R22: =IFERROR(_xlfn.XLOOKUP($A22,Anova_Live!$B$2:$B$60,Anova_Live!$A$2:$A$60,""),"") | S22: =IFERROR(_xlfn.XLOOKUP($A22,Anova_Live!$B$2:$B$60,Anova_Live!$E$2:$E$60,""),"") | T22: =IFERROR(_xlfn.XLOOKUP($A22,Anova_Live!$B$2:$B$60,Anova_Live!$K$2:$K$60,""),"") | U22: =IFERROR(_xlfn.XLOOKUP($A22,Anova_Live!$B$2:$B$60,Anova_Live!$H$2:$H$60,""),"") | V22: =IFERROR(_xlfn.XLOOKUP($A22,Anova_Live!$B$2:$B$60,Anova_Live!$L$2:$L$60,""),"") | W22: =IFERROR(_xlfn.XLOOKUP($A22,Anova_Live!$B$2:$B$60,Anova_Live!$M$2:$M$60,""),"") | X22: =IFERROR(_xlfn.XLOOKUP($A22,Anova_Live!$B$2:$B$60,Anova_Live!$N$2:$N$60,""),"")
A23: 2013 | B23: BOT - 2013 - BOTTLED BLONDE | C23: 4 | D23: 4D | E23: 7340 E Indian Plz | F23: Scottsdale | G23: AZ | H23: 33.501653 | I23: -111.92273 | J23: 500 | K23: CANOLA OIL | N23: 480-970-1112 | R23: =IFERROR(_xlfn.XLOOKUP($A23,Anova_Live!$B$2:$B$60,Anova_Live!$A$2:$A$60,""),"") | S23: =IFERROR(_xlfn.XLOOKUP($A23,Anova_Live!$B$2:$B$60,Anova_Live!$E$2:$E$60,""),"") | T23: =IFERROR(_xlfn.XLOOKUP($A23,Anova_Live!$B$2:$B$60,Anova_Live!$K$2:$K$60,""),"") | U23: =IFERROR(_xlfn.XLOOKUP($A23,Anova_Live!$B$2:$B$60,Anova_Live!$H$2:$H$60,""),"") | V23: =IFERROR(_xlfn.XLOOKUP($A23,Anova_Live!$B$2:$B$60,Anova_Live!$L$2:$L$60,""),"") | W23: =IFERROR(_xlfn.XLOOKUP($A23,Anova_Live!$B$2:$B$60,Anova_Live!$M$2:$M$60,""),"") | X23: =IFERROR(_xlfn.XLOOKUP($A23,Anova_Live!$B$2:$B$60,Anova_Live!$N$2:$N$60,""),"")
A24: 2078 | B24: BRO - 2078 - BROTHER'S PIZZA INDIAN SCHOOL | C24: 3 | D24: 3E | E24: 10720 W Indian School Rd | F24: Phoenix | G24: AZ | H24: 33.495318 | I24: -112.2907 | J24: 350 | K24: CANOLA OIL | N24: (602) 320-8496 | P24: CLOSED ON TUESDAYS | R24: =IFERROR(_xlfn.XLOOKUP($A24,Anova_Live!$B$2:$B$60,Anova_Live!$A$2:$A$60,""),"") | S24: =IFERROR(_xlfn.XLOOKUP($A24,Anova_Live!$B$2:$B$60,Anova_Live!$E$2:$E$60,""),"") | T24: =IFERROR(_xlfn.XLOOKUP($A24,Anova_Live!$B$2:$B$60,Anova_Live!$K$2:$K$60,""),"") | U24: =IFERROR(_xlfn.XLOOKUP($A24,Anova_Live!$B$2:$B$60,Anova_Live!$H$2:$H$60,""),"") | V24: =IFERROR(_xlfn.XLOOKUP($A24,Anova_Live!$B$2:$B$60,Anova_Live!$L$2:$L$60,""),"") | W24: =IFERROR(_xlfn.XLOOKUP($A24,Anova_Live!$B$2:$B$60,Anova_Live!$M$2:$M$60,""),"") | X24: =IFERROR(_xlfn.XLOOKUP($A24,Anova_Live!$B$2:$B$60,Anova_Live!$N$2:$N$60,""),"")
A25: 2073 | B25: BRU - 2073 - BRUNCH SNOB | C25: 4 | D25: 4D | E25: 1920 W GERMANN RD | F25: CHANDLER | G25: AZ | H25: 33.276945 | I25: -111.87477 | J25: 350 | K25: FRYERS CHOICE BLEND | N25: (816) 803-1258 | P25: SCHEDULE 4/28 | R25: =IFERROR(_xlfn.XLOOKUP($A25,Anova_Live!$B$2:$B$60,Anova_Live!$A$2:$A$60,""),"") | S25: =IFERROR(_xlfn.XLOOKUP($A25,Anova_Live!$B$2:$B$60,Anova_Live!$E$2:$E$60,""),"") | T25: =IFERROR(_xlfn.XLOOKUP($A25,Anova_Live!$B$2:$B$60,Anova_Live!$K$2:$K$60,""),"") | U25: =IFERROR(_xlfn.XLOOKUP($A25,Anova_Live!$B$2:$B$60,Anova_Live!$H$2:$H$60,""),"") | V25: =IFERROR(_xlfn.XLOOKUP($A25,Anova_Live!$B$2:$B$60,Anova_Live!$L$2:$L$60,""),"") | W25: =IFERROR(_xlfn.XLOOKUP($A25,Anova_Live!$B$2:$B$60,Anova_Live!$M$2:$M$60,""),"") | X25: =IFERROR(_xlfn.XLOOKUP($A25,Anova_Live!$B$2:$B$60,Anova_Live!$N$2:$N$60,""),"")
A26: 4038 | B26: BUR - 4038 - BURGERS & BREWS GLENDALE | C26: 2 | D26: 2C | E26: 6670 W CACTUS RD | F26: GLENDALE | G26: AZ | H26: 33.597456 | I26: -112.20202 | J26: 1050 | K26: CANOLA OIL | N26: (623) 776-2266 | O26: Y | R26: =IFERROR(_xlfn.XLOOKUP($A26,Anova_Live!$B$2:$B$60,Anova_Live!$A$2:$A$60,""),"") | S26: =IFERROR(_xlfn.XLOOKUP($A26,Anova_Live!$B$2:$B$60,Anova_Live!$E$2:$E$60,""),"") | T26: =IFERROR(_xlfn.XLOOKUP($A26,Anova_Live!$B$2:$B$60,Anova_Live!$K$2:$K$60,""),"") | U26: =IFERROR(_xlfn.XLOOKUP($A26,Anova_Live!$B$2:$B$60,Anova_Live!$H$2:$H$60,""),"") | V26: =IFERROR(_xlfn.XLOOKUP($A26,Anova_Live!$B$2:$B$60,Anova_Live!$L$2:$L$60,""),"") | W26: =IFERROR(_xlfn.XLOOKUP($A26,Anova_Live!$B$2:$B$60,Anova_Live!$M$2:$M$60,""),"") | X26: =IFERROR(_xlfn.XLOOKUP($A26,Anova_Live!$B$2:$B$60,Anova_Live!$N$2:$N$60,""),"")
A27: 3063 | B27: CAR - 3063 - CARDINAL STADIUM | C27: 2 | D27: 2D | E27: 1 CARDINAL DR | F27: GLENDALE | G27: ARIZONA | H27: 33.526233 | I27: -112.26611 | J27: 2500 | K27: CANOLA OIL | O27: Y | R27: =IFERROR(_xlfn.XLOOKUP($A27,Anova_Live!$B$2:$B$60,Anova_Live!$A$2:$A$60,""),"") | S27: =IFERROR(_xlfn.XLOOKUP($A27,Anova_Live!$B$2:$B$60,Anova_Live!$E$2:$E$60,""),"") | T27: =IFERROR(_xlfn.XLOOKUP($A27,Anova_Live!$B$2:$B$60,Anova_Live!$K$2:$K$60,""),"") | U27: =IFERROR(_xlfn.XLOOKUP($A27,Anova_Live!$B$2:$B$60,Anova_Live!$H$2:$H$60,""),"") | V27: =IFERROR(_xlfn.XLOOKUP($A27,Anova_Live!$B$2:$B$60,Anova_Live!$L$2:$L$60,""),"") | W27: =IFERROR(_xlfn.XLOOKUP($A27,Anova_Live!$B$2:$B$60,Anova_Live!$M$2:$M$60,""),"") | X27: =IFERROR(_xlfn.XLOOKUP($A27,Anova_Live!$B$2:$B$60,Anova_Live!$N$2:$N$60,""),"")
A28: 3069 | B28: CAS - 3069 - CASA DE FALAFEL | C28: 2 | D28: 2C | E28: 4920 W Thunderbird Rd | F28: Glendale | G28: AZ | H28: 33.611633 | I28: -112.16541 | J28: 1000 | K28: CANOLA OIL | N28: (480) 689-0514 | O28: Y | R28: =IFERROR(_xlfn.XLOOKUP($A28,Anova_Live!$B$2:$B$60,Anova_Live!$A$2:$A$60,""),"") | S28: =IFERROR(_xlfn.XLOOKUP($A28,Anova_Live!$B$2:$B$60,Anova_Live!$E$2:$E$60,""),"") | T28: =IFERROR(_xlfn.XLOOKUP($A28,Anova_Live!$B$2:$B$60,Anova_Live!$K$2:$K$60,""),"") | U28: =IFERROR(_xlfn.XLOOKUP($A28,Anova_Live!$B$2:$B$60,Anova_Live!$H$2:$H$60,""),"") | V28: =IFERROR(_xlfn.XLOOKUP($A28,Anova_Live!$B$2:$B$60,Anova_Live!$L$2:$L$60,""),"") | W28: =IFERROR(_xlfn.XLOOKUP($A28,Anova_Live!$B$2:$B$60,Anova_Live!$M$2:$M$60,""),"") | X28: =IFERROR(_xlfn.XLOOKUP($A28,Anova_Live!$B$2:$B$60,Anova_Live!$N$2:$N$60,""),"")
A29: 3021 | B29: CRA - 3021 - JC FOOD TRADING/GLEN | C29: 2 | D29: 2C | E29: CRAZY MIKES CHICKEN | F29: Glendale | G29: AZ | H29: 33.639787 | I29: -112.17386 | J29: 450 | K29: CANOLA OIL | N29: 623-463-6881 | R29: =IFERROR(_xlfn.XLOOKUP($A29,Anova_Live!$B$2:$B$60,Anova_Live!$A$2:$A$60,""),"") | S29: =IFERROR(_xlfn.XLOOKUP($A29,Anova_Live!$B$2:$B$60,Anova_Live!$E$2:$E$60,""),"") | T29: =IFERROR(_xlfn.XLOOKUP($A29,Anova_Live!$B$2:$B$60,Anova_Live!$K$2:$K$60,""),"") | U29: =IFERROR(_xlfn.XLOOKUP($A29,Anova_Live!$B$2:$B$60,Anova_Live!$H$2:$H$60,""),"") | V29: =IFERROR(_xlfn.XLOOKUP($A29,Anova_Live!$B$2:$B$60,Anova_Live!$L$2:$L$60,""),"") | W29: =IFERROR(_xlfn.XLOOKUP($A29,Anova_Live!$B$2:$B$60,Anova_Live!$M$2:$M$60,""),"") | X29: =IFERROR(_xlfn.XLOOKUP($A29,Anova_Live!$B$2:$B$60,Anova_Live!$N$2:$N$60,""),"")
A30: 3046 | B30: CRA - 3046 - JC FOOD TRADING /GOODYEAR | C30: 2 | D30: 2C | E30: CRAZY MIKE'S GOODYEAR | F30: Goodyear | G30: AZ | H30: 33.483996 | I30: -112.36512 | J30: 1000 | K30: CANOLA OIL | N30: 213-700-4092 | R30: =IFERROR(_xlfn.XLOOKUP($A30,Anova_Live!$B$2:$B$60,Anova_Live!$A$2:$A$60,""),"") | S30: =IFERROR(_xlfn.XLOOKUP($A30,Anova_Live!$B$2:$B$60,Anova_Live!$E$2:$E$60,""),"") | T30: =IFERROR(_xlfn.XLOOKUP($A30,Anova_Live!$B$2:$B$60,Anova_Live!$K$2:$K$60,""),"") | U30: =IFERROR(_xlfn.XLOOKUP($A30,Anova_Live!$B$2:$B$60,Anova_Live!$H$2:$H$60,""),"") | V30: =IFERROR(_xlfn.XLOOKUP($A30,Anova_Live!$B$2:$B$60,Anova_Live!$L$2:$L$60,""),"") | W30: =IFERROR(_xlfn.XLOOKUP($A30,Anova_Live!$B$2:$B$60,Anova_Live!$M$2:$M$60,""),"") | X30: =IFERROR(_xlfn.XLOOKUP($A30,Anova_Live!$B$2:$B$60,Anova_Live!$N$2:$N$60,""),"")
A31: 3065 | B31: CRA - 3065 - CRAFTED CUISINE | C31: 4 | D31: 4D | E31: 6736 E Avalon Dr | F31: Scottsdale | G31: AZ | H31: 33.483076 | I31: -111.93581 | J31: 350 | K31: CANOLA OIL | N31: (210) 529-1900 | R31: =IFERROR(_xlfn.XLOOKUP($A31,Anova_Live!$B$2:$B$60,Anova_Live!$A$2:$A$60,""),"") | S31: =IFERROR(_xlfn.XLOOKUP($A31,Anova_Live!$B$2:$B$60,Anova_Live!$E$2:$E$60,""),"") | T31: =IFERROR(_xlfn.XLOOKUP($A31,Anova_Live!$B$2:$B$60,Anova_Live!$K$2:$K$60,""),"") | U31: =IFERROR(_xlfn.XLOOKUP($A31,Anova_Live!$B$2:$B$60,Anova_Live!$H$2:$H$60,""),"") | V31: =IFERROR(_xlfn.XLOOKUP($A31,Anova_Live!$B$2:$B$60,Anova_Live!$L$2:$L$60,""),"") | W31: =IFERROR(_xlfn.XLOOKUP($A31,Anova_Live!$B$2:$B$60,Anova_Live!$M$2:$M$60,""),"") | X31: =IFERROR(_xlfn.XLOOKUP($A31,Anova_Live!$B$2:$B$60,Anova_Live!$N$2:$N$60,""),"")
A32: 3064 | B32: CRO - 3064 - CROWNE PLAZA RESORT | C32: 4 | D32: 4F | E32: One N San Marcos Pl | F32: Chandler | G32: Arizona | H32: 33.320637 | I32: -111.84377 | J32: 700 | K32: CANOLA OIL | N32: (480) 812-0900 | O32: Y | P32: DAI - 4015A - DAIRY QUEEN BELL | R32: =IFERROR(_xlfn.XLOOKUP($A32,Anova_Live!$B$2:$B$60,Anova_Live!$A$2:$A$60,""),"") | S32: =IFERROR(_xlfn.XLOOKUP($A32,Anova_Live!$B$2:$B$60,Anova_Live!$E$2:$E$60,""),"") | T32: =IFERROR(_xlfn.XLOOKUP($A32,Anova_Live!$B$2:$B$60,Anova_Live!$K$2:$K$60,""),"") | U32: =IFERROR(_xlfn.XLOOKUP($A32,Anova_Live!$B$2:$B$60,Anova_Live!$H$2:$H$60,""),"") | V32: =IFERROR(_xlfn.XLOOKUP($A32,Anova_Live!$B$2:$B$60,Anova_Live!$L$2:$L$60,""),"") | W32: =IFERROR(_xlfn.XLOOKUP($A32,Anova_Live!$B$2:$B$60,Anova_Live!$M$2:$M$60,""),"") | X32: =IFERROR(_xlfn.XLOOKUP($A32,Anova_Live!$B$2:$B$60,Anova_Live!$N$2:$N$60,""),"")
A33: 4015A | B33: DAI - 4015A - DAIRY QUEEN BELL | C33: 3 | D33: 3C | E33: 3550 E BELL ROAD | F33: PHOENIX | G33: AZ | H33: 33.641001 | I33: -112.00519 | J33: 500 | K33: CANOLA OIL | N33: 602-788-0261 (JACIE M | R33: =IFERROR(_xlfn.XLOOKUP($A33,Anova_Live!$B$2:$B$60,Anova_Live!$A$2:$A$60,""),"") | S33: =IFERROR(_xlfn.XLOOKUP($A33,Anova_Live!$B$2:$B$60,Anova_Live!$E$2:$E$60,""),"") | T33: =IFERROR(_xlfn.XLOOKUP($A33,Anova_Live!$B$2:$B$60,Anova_Live!$K$2:$K$60,""),"") | U33: =IFERROR(_xlfn.XLOOKUP($A33,Anova_Live!$B$2:$B$60,Anova_Live!$H$2:$H$60,""),"") | V33: =IFERROR(_xlfn.XLOOKUP($A33,Anova_Live!$B$2:$B$60,Anova_Live!$L$2:$L$60,""),"") | W33: =IFERROR(_xlfn.XLOOKUP($A33,Anova_Live!$B$2:$B$60,Anova_Live!$M$2:$M$60,""),"") | X33: =IFERROR(_xlfn.XLOOKUP($A33,Anova_Live!$B$2:$B$60,Anova_Live!$N$2:$N$60,""),"")
A34: 4026 | B34: DAR - 4026 - DARUMA BY RIE | C34: 4 | D34: 4E | E34: 1116 E DOBSON RD | F34: MESA | G34: AZ | H34: 33.39476 | I34: -111.87536 | J34: 350 | K34: CANOLA OIL | N34: (480) 590-7979 | P34: CLOSED EVERY TUESDAY | DAR 4037 - DARUMA RAMEN AND BOWL | CLOSED ON TUESDAY | R34: =IFERROR(_xlfn.XLOOKUP($A34,Anova_Live!$B$2:$B$60,Anova_Live!$A$2:$A$60,""),"") | S34: =IFERROR(_xlfn.XLOOKUP($A34,Anova_Live!$B$2:$B$60,Anova_Live!$E$2:$E$60,""),"") | T34: =IFERROR(_xlfn.XLOOKUP($A34,Anova_Live!$B$2:$B$60,Anova_Live!$K$2:$K$60,""),"") | U34: =IFERROR(_xlfn.XLOOKUP($A34,Anova_Live!$B$2:$B$60,Anova_Live!$H$2:$H$60,""),"") | V34: =IFERROR(_xlfn.XLOOKUP($A34,Anova_Live!$B$2:$B$60,Anova_Live!$L$2:$L$60,""),"") | W34: =IFERROR(_xlfn.XLOOKUP($A34,Anova_Live!$B$2:$B$60,Anova_Live!$M$2:$M$60,""),"") | X34: =IFERROR(_xlfn.XLOOKUP($A34,Anova_Live!$B$2:$B$60,Anova_Live!$N$2:$N$60,""),"")
A35: 4037 | B35: DAR - 4037 - DARUMA RAMEN AND BOWL | C35: 4 | D35: 4E | E35: 2650 E UNIVERSITY DR | F35: MESA | G35: AZ | H35: 33.423457 | I35: -111.7736 | J35: 350 | K35: CANOLA OIL | N35: (562) 760-8262 | R35: =IFERROR(_xlfn.XLOOKUP($A35,Anova_Live!$B$2:$B$60,Anova_Live!$A$2:$A$60,""),"") | S35: =IFERROR(_xlfn.XLOOKUP($A35,Anova_Live!$B$2:$B$60,Anova_Live!$E$2:$E$60,""),"") | T35: =IFERROR(_xlfn.XLOOKUP($A35,Anova_Live!$B$2:$B$60,Anova_Live!$K$2:$K$60,""),"") | U35: =IFERROR(_xlfn.XLOOKUP($A35,Anova_Live!$B$2:$B$60,Anova_Live!$H$2:$H$60,""),"") | V35: =IFERROR(_xlfn.XLOOKUP($A35,Anova_Live!$B$2:$B$60,Anova_Live!$L$2:$L$60,""),"") | W35: =IFERROR(_xlfn.XLOOKUP($A35,Anova_Live!$B$2:$B$60,Anova_Live!$M$2:$M$60,""),"") | X35: =IFERROR(_xlfn.XLOOKUP($A35,Anova_Live!$B$2:$B$60,Anova_Live!$N$2:$N$60,""),"")
A36: 4009 | B36: DIL - 4009 - DILLONS BBQ | C36: 1 | D36: 1D | E36: 16335 W Northern Ave | F36: Litchfield Pk | G36: AZ | H36: 33.549985 | I36: -112.41071 | J36: 1050 | K36: FRYERS CHOICE BLEND | N36: 623-535-4249 | R36: =IFERROR(_xlfn.XLOOKUP($A36,Anova_Live!$B$2:$B$60,Anova_Live!$A$2:$A$60,""),"") | S36: =IFERROR(_xlfn.XLOOKUP($A36,Anova_Live!$B$2:$B$60,Anova_Live!$E$2:$E$60,""),"") | T36: =IFERROR(_xlfn.XLOOKUP($A36,Anova_Live!$B$2:$B$60,Anova_Live!$K$2:$K$60,""),"") | U36: =IFERROR(_xlfn.XLOOKUP($A36,Anova_Live!$B$2:$B$60,Anova_Live!$H$2:$H$60,""),"") | V36: =IFERROR(_xlfn.XLOOKUP($A36,Anova_Live!$B$2:$B$60,Anova_Live!$L$2:$L$60,""),"") | W36: =IFERROR(_xlfn.XLOOKUP($A36,Anova_Live!$B$2:$B$60,Anova_Live!$M$2:$M$60,""),"") | X36: =IFERROR(_xlfn.XLOOKUP($A36,Anova_Live!$B$2:$B$60,Anova_Live!$N$2:$N$60,""),"")
A37: C173 | B37: PIN - 16058 - PINYON RESTAURANT | C37: 4 | D37: 4D | E37: 7363 E Scottsdale Mall | F37: Scottsdale | G37: AZ | H37: 33.4925 | I37: -111.92301 | J37: 950 | K37: FRYERS CHOICE | R37: =IFERROR(_xlfn.XLOOKUP($A37,Anova_Live!$B$2:$B$60,Anova_Live!$A$2:$A$60,""),"") | S37: =IFERROR(_xlfn.XLOOKUP($A37,Anova_Live!$B$2:$B$60,Anova_Live!$E$2:$E$60,""),"") | T37: =IFERROR(_xlfn.XLOOKUP($A37,Anova_Live!$B$2:$B$60,Anova_Live!$K$2:$K$60,""),"") | U37: =IFERROR(_xlfn.XLOOKUP($A37,Anova_Live!$B$2:$B$60,Anova_Live!$H$2:$H$60,""),"") | V37: =IFERROR(_xlfn.XLOOKUP($A37,Anova_Live!$B$2:$B$60,Anova_Live!$L$2:$L$60,""),"") | W37: =IFERROR(_xlfn.XLOOKUP($A37,Anova_Live!$B$2:$B$60,Anova_Live!$M$2:$M$60,""),"") | X37: =IFERROR(_xlfn.XLOOKUP($A37,Anova_Live!$B$2:$B$60,Anova_Live!$N$2:$N$60,""),"")
A38: 4014 | B38: DIL- 4014 - DILLONS BAYOU | C38: 2 | D38: 2A | E38: 40202 N 87Th Ave | F38: Peoria | G38: AZ | H38: 33.852793 | I38: -112.24698 | J38: 450 | K38: FRYERS CHOICE BLEND | N38: 623-498-5427 | R38: =IFERROR(_xlfn.XLOOKUP($A38,Anova_Live!$B$2:$B$60,Anova_Live!$A$2:$A$60,""),"") | S38: =IFERROR(_xlfn.XLOOKUP($A38,Anova_Live!$B$2:$B$60,Anova_Live!$E$2:$E$60,""),"") | T38: =IFERROR(_xlfn.XLOOKUP($A38,Anova_Live!$B$2:$B$60,Anova_Live!$K$2:$K$60,""),"") | U38: =IFERROR(_xlfn.XLOOKUP($A38,Anova_Live!$B$2:$B$60,Anova_Live!$H$2:$H$60,""),"") | V38: =IFERROR(_xlfn.XLOOKUP($A38,Anova_Live!$B$2:$B$60,Anova_Live!$L$2:$L$60,""),"") | W38: =IFERROR(_xlfn.XLOOKUP($A38,Anova_Live!$B$2:$B$60,Anova_Live!$M$2:$M$60,""),"") | X38: =IFERROR(_xlfn.XLOOKUP($A38,Anova_Live!$B$2:$B$60,Anova_Live!$N$2:$N$60,""),"")
A39: 4010 | B39: DIL59 - 4010 - DILLONS 59TH AVE | C39: 2 | D39: 2A | E39: 20585 N 59Th Ave | F39: Glendale | G39: AZ | H39: 33.67218 | I39: -112.18631 | J39: 500 | K39: FRYERS CHOICE BLEND | N39: 623-979-5353 | R39: =IFERROR(_xlfn.XLOOKUP($A39,Anova_Live!$B$2:$B$60,Anova_Live!$A$2:$A$60,""),"") | S39: =IFERROR(_xlfn.XLOOKUP($A39,Anova_Live!$B$2:$B$60,Anova_Live!$E$2:$E$60,""),"") | T39: =IFERROR(_xlfn.XLOOKUP($A39,Anova_Live!$B$2:$B$60,Anova_Live!$K$2:$K$60,""),"") | U39: =IFERROR(_xlfn.XLOOKUP($A39,Anova_Live!$B$2:$B$60,Anova_Live!$H$2:$H$60,""),"") | V39: =IFERROR(_xlfn.XLOOKUP($A39,Anova_Live!$B$2:$B$60,Anova_Live!$L$2:$L$60,""),"") | W39: =IFERROR(_xlfn.XLOOKUP($A39,Anova_Live!$B$2:$B$60,Anova_Live!$M$2:$M$60,""),"") | X39: =IFERROR(_xlfn.XLOOKUP($A39,Anova_Live!$B$2:$B$60,Anova_Live!$N$2:$N$60,""),"")
A40: 4027 | B40: DIR - 4027 - DIRTWATER | C40: 5 | D40: 5E | E40: 586 W APACHE | F40: APACHE JUNCTION | G40: AZ | H40: 33.415492 | I40: -111.55237 | J40: 900 | K40: FRYERS CHOICE BLEND | N40: 480-983-3478 | R40: =IFERROR(_xlfn.XLOOKUP($A40,Anova_Live!$B$2:$B$60,Anova_Live!$A$2:$A$60,""),"") | S40: =IFERROR(_xlfn.XLOOKUP($A40,Anova_Live!$B$2:$B$60,Anova_Live!$E$2:$E$60,""),"") | T40: =IFERROR(_xlfn.XLOOKUP($A40,Anova_Live!$B$2:$B$60,Anova_Live!$K$2:$K$60,""),"") | U40: =IFERROR(_xlfn.XLOOKUP($A40,Anova_Live!$B$2:$B$60,Anova_Live!$H$2:$H$60,""),"") | V40: =IFERROR(_xlfn.XLOOKUP($A40,Anova_Live!$B$2:$B$60,Anova_Live!$L$2:$L$60,""),"") | W40: =IFERROR(_xlfn.XLOOKUP($A40,Anova_Live!$B$2:$B$60,Anova_Live!$M$2:$M$60,""),"") | X40: =IFERROR(_xlfn.XLOOKUP($A40,Anova_Live!$B$2:$B$60,Anova_Live!$N$2:$N$60,""),"")
...

Sheet Optimizer_Input
B1: S&K OIL SALES — OPTIMIZER INPUT (all calculations auto-update from Delivery_Log)
B2: Min Oil % | C2: 0.15 | D2: Visit Window (days) | E2: 7 | F2: Shift Min | G2: 600 | H2: Svc Min/Stop | I2: 20 | O2: # of Deliveries since: | Q2: 46023
B3: ■ Red=Critical(≤2d) ■ Amber=Urgent(3–5d) ■ Green=Normal(6–7d) ■ Grey=Not needed │ Blue italic = live formula pulling from Delivery_Log
B4: CLIENT & LOCATION | G4: TANK & CONSUMPTION | J4: LAST DELIVERY ← from log | L4: CALCULATED
A5: Num. | B5: ID | C5: Customer | D5: Zone | E5: Address | F5: Lat / Lon | G5: Tank (lbs) | H5: Last Per Day Cons (lbs/day) | I5: Product | J5: Last Delivery | K5: Days Since | L5: Est. Current (lbs) | M5: Refill (lbs) | N5: Days Until Empty | O5: Next Delivery By: | P5: ="Next "&E2& " Days?" -> Next 7 Days? | Q5: ="# Deliveries since "& TEXT(Q2,"mm/dd/yyyy") -> # Deliveries since 01/01/2026 | R5: Notes | S5: Anova Level (lbs) | T5: Anova Updated | U5: Anova Status
A6: 1 | B6: 0001 | C6: 51ST - 0001 - 51ST AVE CAFE | D6: 2 | E6: =IFERROR(VLOOKUP(C6,Client_List!$B:$K,4,0)&", "&VLOOKUP(C6,Client_List!$B:$K,5,0)&" AZ","") -> 5511 N 51St Ave, Glendale AZ | F6: =IFERROR(VLOOKUP(C6,Client_List!$B:$K,7,0)&", "&VLOOKUP(C6,Client_List!$B:$K,8,0),"") -> 33.5171994, -112.1681115 | G6: =IFERROR(VLOOKUP(C6,Client_List!$B:$K,9,0),"") -> 350 | H6: =IFERROR(LOOKUP(2,1/((Delivery_Log!$B$4:$B$4998=B6)*(ISNUMBER(Delivery_Log!$J$4:$J$4998))*(Delivery_Log!$J$4:$J$4998>0)),Delivery_Log!$J$4:$J$4998),"") | I6: =IFERROR(VLOOKUP(C6,Client_List!$B:$K,10,0),"") -> FRYERS CHOICE BLEND | J6: =IFERROR(_xlfn.MAXIFS(Delivery_Log!$A$4:$A$4998,Delivery_Log!$B$4:$B$4998,B6),"—") -> 46084 | K6: =IFERROR(IF(J6="—","",TODAY()-J6),"") -> 64 | L6: =IFERROR(IF(OR(K6="",H6=""),"",MAX(G6*0.03,G6-K6*H6)),"") | M6: =IFERROR(IF(L6="","",G6-L6),"") | N6: =IFERROR(IF(OR(L6="",H6=""),"",MIN(21,MAX(0,(L6-G6*$C$2)/H6))),"") | O6: =TODAY()+ROUNDUP(N6,0) -> #VALUE! | P6: =IFERROR(IF(N6="","—",IF(N6<=$E$2,"YES","—")),"—") -> — | Q6: =COUNTIFS(Delivery_Log!$B$4:$B$5998,B6,Delivery_Log!$A$4:$A$5998,">="&$Q$2) -> 2 | S6: =IFERROR(_xlfn.XLOOKUP(B6,Client_List!$A$4:$A$200,Client_List!$S$4:$S$200,""),"") | T6: =IFERROR(_xlfn.XLOOKUP(B6,Client_List!$A$4:$A$200,Client_List!$U$4:$U$200,""),"") | U6: =IFERROR(IF(S6="","",IF(_xlfn.XLOOKUP(B6,Client_List!$A$4:$A$200,Client_List!$W$4:$W$200,999)<=24,"LIVE",IF(_xlfn.XLOOKUP(B6,Client_List!$A$4:$A$200,Client_List!$W$4:$W$200,999)<=72,"STALE","OLD"))),"")
A7: 2 | B7: 1018 | C7: AJO - 1018 - AJO ALS BELL | D7: 2 | E7: =IFERROR(VLOOKUP(C7,Client_List!$B:$K,4,0)&", "&VLOOKUP(C7,Client_List!$B:$K,5,0)&" AZ","") -> 7458 W Bell Rd, Glendale AZ | F7: =IFERROR(VLOOKUP(C7,Client_List!$B:$K,7,0)&", "&VLOOKUP(C7,Client_List!$B:$K,8,0),"") -> 33.6390173, -112.2197838 | G7: =IFERROR(VLOOKUP(C7,Client_List!$B:$K,9,0),"") -> 950 | H7: =IFERROR(LOOKUP(2,1/((Delivery_Log!$B$4:$B$4998=B7)*(ISNUMBER(Delivery_Log!$J$4:$J$4998))*(Delivery_Log!$J$4:$J$4998>0)),Delivery_Log!$J$4:$J$4998),"") | I7: =IFERROR(VLOOKUP(C7,Client_List!$B:$K,10,0),"") -> CANOLA OIL | J7: =IFERROR(_xlfn.MAXIFS(Delivery_Log!$A$4:$A$4998,Delivery_Log!$B$4:$B$4998,B7),"—") -> 46141 | K7: =IFERROR(IF(J7="—","",TODAY()-J7),"") -> 7 | L7: =IFERROR(IF(OR(K7="",H7=""),"",MAX(G7*0.03,G7-K7*H7)),"") | M7: =IFERROR(IF(L7="","",G7-L7),"") | N7: =IFERROR(IF(OR(L7="",H7=""),"",MIN(21,MAX(0,(L7-G7*$C$2)/H7))),"") | O7: =TODAY()+ROUNDUP(N7,0) -> #VALUE! | P7: =IFERROR(IF(N7="","—",IF(N7<=$E$2,"YES","—")),"—") -> — | Q7: =COUNTIFS(Delivery_Log!$B$4:$B$5998,B7,Delivery_Log!$A$4:$A$5998,">="&$Q$2) -> 12 | S7: =IFERROR(_xlfn.XLOOKUP(B7,Client_List!$A$4:$A$200,Client_List!$S$4:$S$200,""),"") | T7: =IFERROR(_xlfn.XLOOKUP(B7,Client_List!$A$4:$A$200,Client_List!$U$4:$U$200,""),"") | U7: =IFERROR(IF(S7="","",IF(_xlfn.XLOOKUP(B7,Client_List!$A$4:$A$200,Client_List!$W$4:$W$200,999)<=24,"LIVE",IF(_xlfn.XLOOKUP(B7,Client_List!$A$4:$A$200,Client_List!$W$4:$W$200,999)<=72,"STALE","OLD"))),"")
A8: 3 | B8: 1063 | C8: ALL - 1063 - ALL AMERICAN MODERN SPORTS GRILL | D8: 4 | E8: =IFERROR(VLOOKUP(C8,Client_List!$B:$K,4,0)&", "&VLOOKUP(C8,Client_List!$B:$K,5,0)&" AZ","") -> 20751 N PIMA RD #105, Scottsdale AZ | F8: =IFERROR(VLOOKUP(C8,Client_List!$B:$K,7,0)&", "&VLOOKUP(C8,Client_List!$B:$K,8,0),"") -> 33.674519, -111.8880329 | G8: =IFERROR(VLOOKUP(C8,Client_List!$B:$K,9,0),"") -> 900 | H8: =IFERROR(LOOKUP(2,1/((Delivery_Log!$B$4:$B$4998=B8)*(ISNUMBER(Delivery_Log!$J$4:$J$4998))*(Delivery_Log!$J$4:$J$4998>0)),Delivery_Log!$J$4:$J$4998),"") | I8: =IFERROR(VLOOKUP(C8,Client_List!$B:$K,10,0),"") -> CANOLA OIL | J8: =IFERROR(_xlfn.MAXIFS(Delivery_Log!$A$4:$A$4998,Delivery_Log!$B$4:$B$4998,B8),"—") -> 46143 | K8: =IFERROR(IF(J8="—","",TODAY()-J8),"") -> 5 | L8: =IFERROR(IF(OR(K8="",H8=""),"",MAX(G8*0.03,G8-K8*H8)),"") | M8: =IFERROR(IF(L8="","",G8-L8),"") | N8: =IFERROR(IF(OR(L8="",H8=""),"",MIN(21,MAX(0,(L8-G8*$C$2)/H8))),"") | O8: =TODAY()+ROUNDUP(N8,0) -> #VALUE! | P8: =IFERROR(IF(N8="","—",IF(N8<=$E$2,"YES","—")),"—") -> — | Q8: =COUNTIFS(Delivery_Log!$B$4:$B$5998,B8,Delivery_Log!$A$4:$A$5998,">="&$Q$2) -> 9 | S8: =IFERROR(_xlfn.XLOOKUP(B8,Client_List!$A$4:$A$200,Client_List!$S$4:$S$200,""),"") | T8: =IFERROR(_xlfn.XLOOKUP(B8,Client_List!$A$4:$A$200,Client_List!$U$4:$U$200,""),"") | U8: =IFERROR(IF(S8="","",IF(_xlfn.XLOOKUP(B8,Client_List!$A$4:$A$200,Client_List!$W$4:$W$200,999)<=24,"LIVE",IF(_xlfn.XLOOKUP(B8,Client_List!$A$4:$A$200,Client_List!$W$4:$W$200,999)<=72,"STALE","OLD"))),"")
A9: 4 | B9: 1073 | C9: AME - 1073 - AMELIO C ENTERPRISES, INC (CACTUS CANDY) | D9: 4 | E9: =IFERROR(VLOOKUP(C9,Client_List!$B:$K,4,0)&", "&VLOOKUP(C9,Client_List!$B:$K,5,0)&" AZ","") -> 2656 N 37TH DR, PHOENIX AZ | F9: =IFERROR(VLOOKUP(C9,Client_List!$B:$K,7,0)&", "&VLOOKUP(C9,Client_List!$B:$K,8,0),"") -> 33.4782767, -112.140515 | G9: =IFERROR(VLOOKUP(C9,Client_List!$B:$K,9,0),"") -> 2000 | H9: =IFERROR(LOOKUP(2,1/((Delivery_Log!$B$4:$B$4998=B9)*(ISNUMBER(Delivery_Log!$J$4:$J$4998))*(Delivery_Log!$J$4:$J$4998>0)),Delivery_Log!$J$4:$J$4998),"") | I9: =IFERROR(VLOOKUP(C9,Client_List!$B:$K,10,0),"") -> CANOLA OIL | J9: =IFERROR(_xlfn.MAXIFS(Delivery_Log!$A$4:$A$4998,Delivery_Log!$B$4:$B$4998,B9),"—") -> 46099 | K9: =IFERROR(IF(J9="—","",TODAY()-J9),"") -> 49 | L9: =IFERROR(IF(OR(K9="",H9=""),"",MAX(G9*0.03,G9-K9*H9)),"") | M9: =IFERROR(IF(L9="","",G9-L9),"") | N9: =IFERROR(IF(OR(L9="",H9=""),"",MIN(21,MAX(0,(L9-G9*$C$2)/H9))),"") | O9: =TODAY()+ROUNDUP(N9,0) -> #VALUE! | P9: =IFERROR(IF(N9="","—",IF(N9<=$E$2,"YES","—")),"—") -> — | Q9: =COUNTIFS(Delivery_Log!$B$4:$B$5998,B9,Delivery_Log!$A$4:$A$5998,">="&$Q$2) -> 1 | S9: =IFERROR(_xlfn.XLOOKUP(B9,Client_List!$A$4:$A$200,Client_List!$S$4:$S$200,""),"") | T9: =IFERROR(_xlfn.XLOOKUP(B9,Client_List!$A$4:$A$200,Client_List!$U$4:$U$200,""),"") | U9: =IFERROR(IF(S9="","",IF(_xlfn.XLOOKUP(B9,Client_List!$A$4:$A$200,Client_List!$W$4:$W$200,999)<=24,"LIVE",IF(_xlfn.XLOOKUP(B9,Client_List!$A$4:$A$200,Client_List!$W$4:$W$200,999)<=72,"STALE","OLD"))),"")
A10: 5 | B10: 1054 | C10: ANG - 1054 - ANGRY CRAB SURPRISE | D10: 1 | E10: =IFERROR(VLOOKUP(C10,Client_List!$B:$K,4,0)&", "&VLOOKUP(C10,Client_List!$B:$K,5,0)&" AZ","") -> 11340 W BELL RD SUITE 118, SURPRISE AZ | F10: =IFERROR(VLOOKUP(C10,Client_List!$B:$K,7,0)&", "&VLOOKUP(C10,Client_List!$B:$K,8,0),"") -> 33.6399393, -112.3041939 | G10: =IFERROR(VLOOKUP(C10,Client_List!$B:$K,9,0),"") -> 620 | H10: =IFERROR(LOOKUP(2,1/((Delivery_Log!$B$4:$B$4998=B10)*(ISNUMBER(Delivery_Log!$J$4:$J$4998))*(Delivery_Log!$J$4:$J$4998>0)),Delivery_Log!$J$4:$J$4998),"") | I10: =IFERROR(VLOOKUP(C10,Client_List!$B:$K,10,0),"") -> FRYERS CHOICE BLEND | J10: =IFERROR(_xlfn.MAXIFS(Delivery_Log!$A$4:$A$4998,Delivery_Log!$B$4:$B$4998,B10),"—") -> 46141 | K10: =IFERROR(IF(J10="—","",TODAY()-J10),"") -> 7 | L10: =IFERROR(IF(OR(K10="",H10=""),"",MAX(G10*0.03,G10-K10*H10)),"") | M10: =IFERROR(IF(L10="","",G10-L10),"") | N10: =IFERROR(IF(OR(L10="",H10=""),"",MIN(21,MAX(0,(L10-G10*$C$2)/H10))),"") | O10: =TODAY()+ROUNDUP(N10,0) -> #VALUE! | P10: =IFERROR(IF(N10="","—",IF(N10<=$E$2,"YES","—")),"—") -> — | Q10: =COUNTIFS(Delivery_Log!$B$4:$B$5998,B10,Delivery_Log!$A$4:$A$5998,">="&$Q$2) -> 11 | S10: =IFERROR(_xlfn.XLOOKUP(B10,Client_List!$A$4:$A$200,Client_List!$S$4:$S$200,""),"") -> 325.48623 | T10: =IFERROR(_xlfn.XLOOKUP(B10,Client_List!$A$4:$A$200,Client_List!$U$4:$U$200,""),"") -> 2026-05-06T11:00:25Z | U10: =IFERROR(IF(S10="","",IF(_xlfn.XLOOKUP(B10,Client_List!$A$4:$A$200,Client_List!$W$4:$W$200,999)<=24,"LIVE",IF(_xlfn.XLOOKUP(B10,Client_List!$A$4:$A$200,Client_List!$W$4:$W$200,999)<=72,"STALE","OLD"))),"") -> OLD
A11: 6 | B11: 1000 | C11: ARR79 - 1000 - ARRIBAS 79TH AVE. | D11: 2 | E11: =IFERROR(VLOOKUP(C11,Client_List!$B:$K,4,0)&", "&VLOOKUP(C11,Client_List!$B:$K,5,0)&" AZ","") -> 17211 N 79Th Ave, Glendale AZ | F11: =IFERROR(VLOOKUP(C11,Client_List!$B:$K,7,0)&", "&VLOOKUP(C11,Client_List!$B:$K,8,0),"") -> 33.6402137, -112.2294109 | G11: =IFERROR(VLOOKUP(C11,Client_List!$B:$K,9,0),"") -> 950 | H11: =IFERROR(LOOKUP(2,1/((Delivery_Log!$B$4:$B$4998=B11)*(ISNUMBER(Delivery_Log!$J$4:$J$4998))*(Delivery_Log!$J$4:$J$4998>0)),Delivery_Log!$J$4:$J$4998),"") | I11: =IFERROR(VLOOKUP(C11,Client_List!$B:$K,10,0),"") -> CANOLA OIL | J11: =IFERROR(_xlfn.MAXIFS(Delivery_Log!$A$4:$A$4998,Delivery_Log!$B$4:$B$4998,B11),"—") -> 46143 | K11: =IFERROR(IF(J11="—","",TODAY()-J11),"") -> 5 | L11: =IFERROR(IF(OR(K11="",H11=""),"",MAX(G11*0.03,G11-K11*H11)),"") | M11: =IFERROR(IF(L11="","",G11-L11),"") | N11: =IFERROR(IF(OR(L11="",H11=""),"",MIN(21,MAX(0,(L11-G11*$C$2)/H11))),"") | O11: =TODAY()+ROUNDUP(N11,0) -> #VALUE! | P11: =IFERROR(IF(N11="","—",IF(N11<=$E$2,"YES","—")),"—") -> — | Q11: =COUNTIFS(Delivery_Log!$B$4:$B$5998,B11,Delivery_Log!$A$4:$A$5998,">="&$Q$2) -> 12 | S11: =IFERROR(_xlfn.XLOOKUP(B11,Client_List!$A$4:$A$200,Client_List!$S$4:$S$200,""),"") | T11: =IFERROR(_xlfn.XLOOKUP(B11,Client_List!$A$4:$A$200,Client_List!$U$4:$U$200,""),"") | U11: =IFERROR(IF(S11="","",IF(_xlfn.XLOOKUP(B11,Client_List!$A$4:$A$200,Client_List!$W$4:$W$200,999)<=24,"LIVE",IF(_xlfn.XLOOKUP(B11,Client_List!$A$4:$A$200,Client_List!$W$4:$W$200,999)<=72,"STALE","OLD"))),"")
A12: 7 | B12: 1001 | C12: ARRC - 1001 - ARRIBAS CAMELBACK | D12: 3 | E12: =IFERROR(VLOOKUP(C12,Client_List!$B:$K,4,0)&", "&VLOOKUP(C12,Client_List!$B:$K,5,0)&" AZ","") -> 1812 E Camelback Rd, Phoenix AZ | F12: =IFERROR(VLOOKUP(C12,Client_List!$B:$K,7,0)&", "&VLOOKUP(C12,Client_List!$B:$K,8,0),"") -> 33.50958, -112.042591 | G12: =IFERROR(VLOOKUP(C12,Client_List!$B:$K,9,0),"") -> 700 | H12: =IFERROR(LOOKUP(2,1/((Delivery_Log!$B$4:$B$4998=B12)*(ISNUMBER(Delivery_Log!$J$4:$J$4998))*(Delivery_Log!$J$4:$J$4998>0)),Delivery_Log!$J$4:$J$4998),"") | I12: =IFERROR(VLOOKUP(C12,Client_List!$B:$K,10,0),"") -> CANOLA OIL | J12: =IFERROR(_xlfn.MAXIFS(Delivery_Log!$A$4:$A$4998,Delivery_Log!$B$4:$B$4998,B12),"—") -> 46140 | K12: =IFERROR(IF(J12="—","",TODAY()-J12),"") -> 8 | L12: =IFERROR(IF(OR(K12="",H12=""),"",MAX(G12*0.03,G12-K12*H12)),"") | M12: =IFERROR(IF(L12="","",G12-L12),"") | N12: =IFERROR(IF(OR(L12="",H12=""),"",MIN(21,MAX(0,(L12-G12*$C$2)/H12))),"") | O12: =TODAY()+ROUNDUP(N12,0) -> #VALUE! | P12: =IFERROR(IF(N12="","—",IF(N12<=$E$2,"YES","—")),"—") -> — | Q12: =COUNTIFS(Delivery_Log!$B$4:$B$5998,B12,Delivery_Log!$A$4:$A$5998,">="&$Q$2) -> 11 | S12: =IFERROR(_xlfn.XLOOKUP(B12,Client_List!$A$4:$A$200,Client_List!$S$4:$S$200,""),"") | T12: =IFERROR(_xlfn.XLOOKUP(B12,Client_List!$A$4:$A$200,Client_List!$U$4:$U$200,""),"") | U12: =IFERROR(IF(S12="","",IF(_xlfn.XLOOKUP(B12,Client_List!$A$4:$A$200,Client_List!$W$4:$W$200,999)<=24,"LIVE",IF(_xlfn.XLOOKUP(B12,Client_List!$A$4:$A$200,Client_List!$W$4:$W$200,999)<=72,"STALE","OLD"))),"")
A13: 8 | B13: 1011 | C13: ARRC - 1011 - ARRIBAS CHANDLER | D13: 4 | E13: =IFERROR(VLOOKUP(C13,Client_List!$B:$K,4,0)&", "&VLOOKUP(C13,Client_List!$B:$K,5,0)&" AZ","") -> 4649 E Chandler Blvd, Phoenix AZ | F13: =IFERROR(VLOOKUP(C13,Client_List!$B:$K,7,0)&", "&VLOOKUP(C13,Client_List!$B:$K,8,0),"") -> 33.3048264, -111.9816146 | G13: =IFERROR(VLOOKUP(C13,Client_List!$B:$K,9,0),"") -> 1000 | H13: =IFERROR(LOOKUP(2,1/((Delivery_Log!$B$4:$B$4998=B13)*(ISNUMBER(Delivery_Log!$J$4:$J$4998))*(Delivery_Log!$J$4:$J$4998>0)),Delivery_Log!$J$4:$J$4998),"") | I13: =IFERROR(VLOOKUP(C13,Client_List!$B:$K,10,0),"") -> CANOLA OIL | J13: =IFERROR(_xlfn.MAXIFS(Delivery_Log!$A$4:$A$4998,Delivery_Log!$B$4:$B$4998,B13),"—") -> 46144 | K13: =IFERROR(IF(J13="—","",TODAY()-J13),"") -> 4 | L13: =IFERROR(IF(OR(K13="",H13=""),"",MAX(G13*0.03,G13-K13*H13)),"") | M13: =IFERROR(IF(L13="","",G13-L13),"") | N13: =IFERROR(IF(OR(L13="",H13=""),"",MIN(21,MAX(0,(L13-G13*$C$2)/H13))),"") | O13: =TODAY()+ROUNDUP(N13,0) -> #VALUE! | P13: =IFERROR(IF(N13="","—",IF(N13<=$E$2,"YES","—")),"—") -> — | Q13: =COUNTIFS(Delivery_Log!$B$4:$B$5998,B13,Delivery_Log!$A$4:$A$5998,">="&$Q$2) -> 10 | S13: =IFERROR(_xlfn.XLOOKUP(B13,Client_List!$A$4:$A$200,Client_List!$S$4:$S$200,""),"") | T13: =IFERROR(_xlfn.XLOOKUP(B13,Client_List!$A$4:$A$200,Client_List!$U$4:$U$200,""),"") | U13: =IFERROR(IF(S13="","",IF(_xlfn.XLOOKUP(B13,Client_List!$A$4:$A$200,Client_List!$W$4:$W$200,999)<=24,"LIVE",IF(_xlfn.XLOOKUP(B13,Client_List!$A$4:$A$200,Client_List!$W$4:$W$200,999)<=72,"STALE","OLD"))),"")
A14: 9 | B14: 1014 | C14: ARRC - 1014 - ARRIBA GILBERT | D14: 5 | E14: =IFERROR(VLOOKUP(C14,Client_List!$B:$K,4,0)&", "&VLOOKUP(C14,Client_List!$B:$K,5,0)&" AZ","") -> 2855 S Market St, Gilbert, AZ 85295, Gilbert AZ | F14: =IFERROR(VLOOKUP(C14,Client_List!$B:$K,7,0)&", "&VLOOKUP(C14,Client_List!$B:$K,8,0),"") -> 33.29809, -111.744273 | G14: =IFERROR(VLOOKUP(C14,Client_List!$B:$K,9,0),"") -> 900 | H14: =IFERROR(LOOKUP(2,1/((Delivery_Log!$B$4:$B$4998=B14)*(ISNUMBER(Delivery_Log!$J$4:$J$4998))*(Delivery_Log!$J$4:$J$4998>0)),Delivery_Log!$J$4:$J$4998),"") | I14: =IFERROR(VLOOKUP(C14,Client_List!$B:$K,10,0),"") -> CANOLA OIL | J14: =IFERROR(_xlfn.MAXIFS(Delivery_Log!$A$4:$A$4998,Delivery_Log!$B$4:$B$4998,B14),"—") -> 46142 | K14: =IFERROR(IF(J14="—","",TODAY()-J14),"") -> 6 | L14: =IFERROR(IF(OR(K14="",H14=""),"",MAX(G14*0.03,G14-K14*H14)),"") | M14: =IFERROR(IF(L14="","",G14-L14),"") | N14: =IFERROR(IF(OR(L14="",H14=""),"",MIN(21,MAX(0,(L14-G14*$C$2)/H14))),"") | O14: =TODAY()+ROUNDUP(N14,0) -> #VALUE! | P14: =IFERROR(IF(N14="","—",IF(N14<=$E$2,"YES","—")),"—") -> — | Q14: =COUNTIFS(Delivery_Log!$B$4:$B$5998,B14,Delivery_Log!$A$4:$A$5998,">="&$Q$2) -> 10 | S14: =IFERROR(_xlfn.XLOOKUP(B14,Client_List!$A$4:$A$200,Client_List!$S$4:$S$200,""),"") | T14: =IFERROR(_xlfn.XLOOKUP(B14,Client_List!$A$4:$A$200,Client_List!$U$4:$U$200,""),"") | U14: =IFERROR(IF(S14="","",IF(_xlfn.XLOOKUP(B14,Client_List!$A$4:$A$200,Client_List!$W$4:$W$200,999)<=24,"LIVE",IF(_xlfn.XLOOKUP(B14,Client_List!$A$4:$A$200,Client_List!$W$4:$W$200,999)<=72,"STALE","OLD"))),"")
A15: 10 | B15: 1013 | C15: ARRM - 1013 - ARRIBAS GOODYEAR | D15: 1 | E15: =IFERROR(VLOOKUP(C15,Client_List!$B:$K,4,0)&", "&VLOOKUP(C15,Client_List!$B:$K,5,0)&" AZ","") -> 15370 W McDowell Rd, Goodyear AZ | F15: =IFERROR(VLOOKUP(C15,Client_List!$B:$K,7,0)&", "&VLOOKUP(C15,Client_List!$B:$K,8,0),"") -> 33.46499, -112.389902 | G15: =IFERROR(VLOOKUP(C15,Client_List!$B:$K,9,0),"") -> 900 | H15: =IFERROR(LOOKUP(2,1/((Delivery_Log!$B$4:$B$4998=B15)*(ISNUMBER(Delivery_Log!$J$4:$J$4998))*(Delivery_Log!$J$4:$J$4998>0)),Delivery_Log!$J$4:$J$4998),"") | I15: =IFERROR(VLOOKUP(C15,Client_List!$B:$K,10,0),"") -> CANOLA OIL | J15: =IFERROR(_xlfn.MAXIFS(Delivery_Log!$A$4:$A$4998,Delivery_Log!$B$4:$B$4998,B15),"—") -> 46141 | K15: =IFERROR(IF(J15="—","",TODAY()-J15),"") -> 7 | L15: =IFERROR(IF(OR(K15="",H15=""),"",MAX(G15*0.03,G15-K15*H15)),"") | M15: =IFERROR(IF(L15="","",G15-L15),"") | N15: =IFERROR(IF(OR(L15="",H15=""),"",MIN(21,MAX(0,(L15-G15*$C$2)/H15))),"") | O15: =TODAY()+ROUNDUP(N15,0) -> #VALUE! | P15: =IFERROR(IF(N15="","—",IF(N15<=$E$2,"YES","—")),"—") -> — | Q15: =COUNTIFS(Delivery_Log!$B$4:$B$5998,B15,Delivery_Log!$A$4:$A$5998,">="&$Q$2) -> 13 | S15: =IFERROR(_xlfn.XLOOKUP(B15,Client_List!$A$4:$A$200,Client_List!$S$4:$S$200,""),"") | T15: =IFERROR(_xlfn.XLOOKUP(B15,Client_List!$A$4:$A$200,Client_List!$U$4:$U$200,""),"") | U15: =IFERROR(IF(S15="","",IF(_xlfn.XLOOKUP(B15,Client_List!$A$4:$A$200,Client_List!$W$4:$W$200,999)<=24,"LIVE",IF(_xlfn.XLOOKUP(B15,Client_List!$A$4:$A$200,Client_List!$W$4:$W$200,999)<=72,"STALE","OLD"))),"")
A16: 11 | B16: 1081 | C16: ATL - 1081 - ATL WINGS ROOSEVELT | D16: 3 | E16: =IFERROR(VLOOKUP(C16,Client_List!$B:$K,4,0)&", "&VLOOKUP(C16,Client_List!$B:$K,5,0)&" AZ","") -> 330 E ROOSEVELT RD, PHOENIX AZ | F16: =IFERROR(VLOOKUP(C16,Client_List!$B:$K,7,0)&", "&VLOOKUP(C16,Client_List!$B:$K,8,0),"") -> 33.4589406, -112.0685493 | G16: =IFERROR(VLOOKUP(C16,Client_List!$B:$K,9,0),"") -> 350 | H16: =IFERROR(LOOKUP(2,1/((Delivery_Log!$B$4:$B$4998=B16)*(ISNUMBER(Delivery_Log!$J$4:$J$4998))*(Delivery_Log!$J$4:$J$4998>0)),Delivery_Log!$J$4:$J$4998),"") | I16: =IFERROR(VLOOKUP(C16,Client_List!$B:$K,10,0),"") -> CANOLA OIL | J16: =IFERROR(_xlfn.MAXIFS(Delivery_Log!$A$4:$A$4998,Delivery_Log!$B$4:$B$4998,B16),"—") -> 46141 | K16: =IFERROR(IF(J16="—","",TODAY()-J16),"") -> 7 | L16: =IFERROR(IF(OR(K16="",H16=""),"",MAX(G16*0.03,G16-K16*H16)),"") | M16: =IFERROR(IF(L16="","",G16-L16),"") | N16: =IFERROR(IF(OR(L16="",H16=""),"",MIN(21,MAX(0,(L16-G16*$C$2)/H16))),"") | O16: =TODAY()+ROUNDUP(N16,0) -> #VALUE! | P16: =IFERROR(IF(N16="","—",IF(N16<=$E$2,"YES","—")),"—") -> — | Q16: =COUNTIFS(Delivery_Log!$B$4:$B$5998,B16,Delivery_Log!$A$4:$A$5998,">="&$Q$2) -> 16 | S16: =IFERROR(_xlfn.XLOOKUP(B16,Client_List!$A$4:$A$200,Client_List!$S$4:$S$200,""),"") | T16: =IFERROR(_xlfn.XLOOKUP(B16,Client_List!$A$4:$A$200,Client_List!$U$4:$U$200,""),"") | U16: =IFERROR(IF(S16="","",IF(_xlfn.XLOOKUP(B16,Client_List!$A$4:$A$200,Client_List!$W$4:$W$200,999)<=24,"LIVE",IF(_xlfn.XLOOKUP(B16,Client_List!$A$4:$A$200,Client_List!$W$4:$W$200,999)<=72,"STALE","OLD"))),"")
A17: 12 | B17: 1083 | C17: ATL - 1083 - ATL WINGS MESA | D17: 5 | E17: =IFERROR(VLOOKUP(C17,Client_List!$B:$K,4,0)&", "&VLOOKUP(C17,Client_List!$B:$K,5,0)&" AZ","") -> 6837 E MAIN ST, Mesa AZ | F17: =IFERROR(VLOOKUP(C17,Client_List!$B:$K,7,0)&", "&VLOOKUP(C17,Client_List!$B:$K,8,0),"") -> 33.4151472, -111.6831813 | G17: =IFERROR(VLOOKUP(C17,Client_List!$B:$K,9,0),"") -> 425 | H17: =IFERROR(LOOKUP(2,1/((Delivery_Log!$B$4:$B$4998=B17)*(ISNUMBER(Delivery_Log!$J$4:$J$4998))*(Delivery_Log!$J$4:$J$4998>0)),Delivery_Log!$J$4:$J$4998),"") | I17: =IFERROR(VLOOKUP(C17,Client_List!$B:$K,10,0),"") -> CANOLA OIL | J17: =IFERROR(_xlfn.MAXIFS(Delivery_Log!$A$4:$A$4998,Delivery_Log!$B$4:$B$4998,B17),"—") -> 46140 | K17: =IFERROR(IF(J17="—","",TODAY()-J17),"") -> 8 | L17: =IFERROR(IF(OR(K17="",H17=""),"",MAX(G17*0.03,G17-K17*H17)),"") | M17: =IFERROR(IF(L17="","",G17-L17),"") | N17: =IFERROR(IF(OR(L17="",H17=""),"",MIN(21,MAX(0,(L17-G17*$C$2)/H17))),"") | O17: =TODAY()+ROUNDUP(N17,0) -> #VALUE! | P17: =IFERROR(IF(N17="","—",IF(N17<=$E$2,"YES","—")),"—") -> — | Q17: =COUNTIFS(Delivery_Log!$B$4:$B$5998,B17,Delivery_Log!$A$4:$A$5998,">="&$Q$2) -> 18 | S17: =IFERROR(_xlfn.XLOOKUP(B17,Client_List!$A$4:$A$200,Client_List!$S$4:$S$200,""),"") | T17: =IFERROR(_xlfn.XLOOKUP(B17,Client_List!$A$4:$A$200,Client_List!$U$4:$U$200,""),"") | U17: =IFERROR(IF(S17="","",IF(_xlfn.XLOOKUP(B17,Client_List!$A$4:$A$200,Client_List!$W$4:$W$200,999)<=24,"LIVE",IF(_xlfn.XLOOKUP(B17,Client_List!$A$4:$A$200,Client_List!$W$4:$W$200,999)<=72,"STALE","OLD"))),"")
A18: 13 | B18: 19039 | C18: BAC - 19039 - BACKYARD GILBERT | D18: 5 | E18: =IFERROR(VLOOKUP(C18,Client_List!$B:$K,4,0)&", "&VLOOKUP(C18,Client_List!$B:$K,5,0)&" AZ","") -> BACKYARD (SANDBAR) GILBERT, Gilbert AZ | F18: =IFERROR(VLOOKUP(C18,Client_List!$B:$K,7,0)&", "&VLOOKUP(C18,Client_List!$B:$K,8,0),"") -> 33.3062162, -111.7475515 | G18: =IFERROR(VLOOKUP(C18,Client_List!$B:$K,9,0),"") -> 1050 | H18: =IFERROR(LOOKUP(2,1/((Delivery_Log!$B$4:$B$4998=B18)*(ISNUMBER(Delivery_Log!$J$4:$J$4998))*(Delivery_Log!$J$4:$J$4998>0)),Delivery_Log!$J$4:$J$4998),"") | I18: =IFERROR(VLOOKUP(C18,Client_List!$B:$K,10,0),"") -> FRYERS CHOICE BLEND | J18: =IFERROR(_xlfn.MAXIFS(Delivery_Log!$A$4:$A$4998,Delivery_Log!$B$4:$B$4998,B18),"—") -> 46137 | K18: =IFERROR(IF(J18="—","",TODAY()-J18),"") -> 11 | L18: =IFERROR(IF(OR(K18="",H18=""),"",MAX(G18*0.03,G18-K18*H18)),"") | M18: =IFERROR(IF(L18="","",G18-L18),"") | N18: =IFERROR(IF(OR(L18="",H18=""),"",MIN(21,MAX(0,(L18-G18*$C$2)/H18))),"") | O18: =TODAY()+ROUNDUP(N18,0) -> #VALUE! | P18: =IFERROR(IF(N18="","—",IF(N18<=$E$2,"YES","—")),"—") -> — | Q18: =COUNTIFS(Delivery_Log!$B$4:$B$5998,B18,Delivery_Log!$A$4:$A$5998,">="&$Q$2) -> 8 | S18: =IFERROR(_xlfn.XLOOKUP(B18,Client_List!$A$4:$A$200,Client_List!$S$4:$S$200,""),"") | T18: =IFERROR(_xlfn.XLOOKUP(B18,Client_List!$A$4:$A$200,Client_List!$U$4:$U$200,""),"") | U18: =IFERROR(IF(S18="","",IF(_xlfn.XLOOKUP(B18,Client_List!$A$4:$A$200,Client_List!$W$4:$W$200,999)<=24,"LIVE",IF(_xlfn.XLOOKUP(B18,Client_List!$A$4:$A$200,Client_List!$W$4:$W$200,999)<=72,"STALE","OLD"))),"")
... A33: 28 | B33: 3064 | C33: CRO - 3064 - CROWNE PLAZA RESORT | D33: 4 | E33: =IFERROR(VLOOKUP(C33,Client_List!$B:$K,4,0)&", "&VLOOKUP(C33,Client_List!$B:$K,5,0)&" AZ","") -> One N San Marcos Pl, Chandler AZ | F33: =IFERROR(VLOOKUP(C33,Client_List!$B:$K,7,0)&", "&VLOOKUP(C33,Client_List!$B:$K,8,0),"") -> 33.3206372, -111.8437719 | G33: =IFERROR(VLOOKUP(C33,Client_List!$B:$K,9,0),"") -> 700 | H33: =IFERROR(LOOKUP(2,1/((Delivery_Log!$B$4:$B$4998=B33)*(ISNUMBER(Delivery_Log!$J$4:$J$4998))*(Delivery_Log!$J$4:$J$4998>0)),Delivery_Log!$J$4:$J$4998),"") | I33: =IFERROR(VLOOKUP(C33,Client_List!$B:$K,10,0),"") -> CANOLA OIL | J33: =IFERROR(_xlfn.MAXIFS(Delivery_Log!$A$4:$A$4998,Delivery_Log!$B$4:$B$4998,B33),"—") -> 46142 | K33: =IFERROR(IF(J33="—","",TODAY()-J33),"") -> 6 | L33: =IFERROR(IF(OR(K33="",H33=""),"",MAX(G33*0.03,G33-K33*H33)),"") | M33: =IFERROR(IF(L33="","",G33-L33),"") | N33: =IFERROR(IF(OR(L33="",H33=""),"",MIN(21,MAX(0,(L33-G33*$C$2)/H33))),"") | O33: =TODAY()+ROUNDUP(N33,0) -> #VALUE! | P33: =IFERROR(IF(N33="","—",IF(N33<=$E$2,"YES","—")),"—") -> — | Q33: =COUNTIFS(Delivery_Log!$B$4:$B$5998,B33,Delivery_Log!$A$4:$A$5998,">="&$Q$2) -> 6 | S33: =IFERROR(_xlfn.XLOOKUP(B33,Client_List!$A$4:$A$200,Client_List!$S$4:$S$200,""),"") | T33: =IFERROR(_xlfn.XLOOKUP(B33,Client_List!$A$4:$A$200,Client_List!$U$4:$U$200,""),"") | U33: =IFERROR(IF(S33="","",IF(_xlfn.XLOOKUP(B33,Client_List!$A$4:$A$200,Client_List!$W$4:$W$200,999)<=24,"LIVE",IF(_xlfn.XLOOKUP(B33,Client_List!$A$4:$A$200,Client_List!$W$4:$W$200,999)<=72,"STALE","OLD"))),"")
A34: 29 | B34: 4015A | C34: DAI - 4015A - DAIRY QUEEN BELL | D34: 3 | E34: =IFERROR(VLOOKUP(C34,Client_List!$B:$K,4,0)&", "&VLOOKUP(C34,Client_List!$B:$K,5,0)&" AZ","") -> 3550 E BELL ROAD, PHOENIX AZ | F34: =IFERROR(VLOOKUP(C34,Client_List!$B:$K,7,0)&", "&VLOOKUP(C34,Client_List!$B:$K,8,0),"") -> 33.6410013, -112.0051915 | G34: =IFERROR(VLOOKUP(C34,Client_List!$B:$K,9,0),"") -> 500 | H34: =IFERROR(LOOKUP(2,1/((Delivery_Log!$B$4:$B$4998=B34)*(ISNUMBER(Delivery_Log!$J$4:$J$4998))*(Delivery_Log!$J$4:$J$4998>0)),Delivery_Log!$J$4:$J$4998),"") | I34: =IFERROR(VLOOKUP(C34,Client_List!$B:$K,10,0),"") -> CANOLA OIL | J34: =IFERROR(_xlfn.MAXIFS(Delivery_Log!$A$4:$A$4998,Delivery_Log!$B$4:$B$4998,B34),"—") -> 46135 | K34: =IFERROR(IF(J34="—","",TODAY()-J34),"") -> 13 | L34: =IFERROR(IF(OR(K34="",H34=""),"",MAX(G34*0.03,G34-K34*H34)),"") | M34: =IFERROR(IF(L34="","",G34-L34),"") | N34: =IFERROR(IF(OR(L34="",H34=""),"",MIN(21,MAX(0,(L34-G34*$C$2)/H34))),"") | O34: =TODAY()+ROUNDUP(N34,0) -> #VALUE! | P34: =IFERROR(IF(N34="","—",IF(N34<=$E$2,"YES","—")),"—") -> — | Q34: =COUNTIFS(Delivery_Log!$B$4:$B$5998,B34,Delivery_Log!$A$4:$A$5998,">="&$Q$2) -> 9 | S34: =IFERROR(_xlfn.XLOOKUP(B34,Client_List!$A$4:$A$200,Client_List!$S$4:$S$200,""),"") | T34: =IFERROR(_xlfn.XLOOKUP(B34,Client_List!$A$4:$A$200,Client_List!$U$4:$U$200,""),"") | U34: =IFERROR(IF(S34="","",IF(_xlfn.XLOOKUP(B34,Client_List!$A$4:$A$200,Client_List!$W$4:$W$200,999)<=24,"LIVE",IF(_xlfn.XLOOKUP(B34,Client_List!$A$4:$A$200,Client_List!$W$4:$W$200,999)<=72,"STALE","OLD"))),"")
A35: 30 | B35: 4026 | C35: DAR - 4026 - DARUMA BY RIE | D35: 4 | E35: =IFERROR(VLOOKUP(C35,Client_List!$B:$K,4,0)&", "&VLOOKUP(C35,Client_List!$B:$K,5,0)&" AZ","") -> 1116 E DOBSON RD, MESA AZ | F35: =IFERROR(VLOOKUP(C35,Client_List!$B:$K,7,0)&", "&VLOOKUP(C35,Client_List!$B:$K,8,0),"") -> 33.3947597, -111.8753592 | G35: =IFERROR(VLOOKUP(C35,Client_List!$B:$K,9,0),"") -> 350 | H35: =IFERROR(LOOKUP(2,1/((Delivery_Log!$B$4:$B$4998=B35)*(ISNUMBER(Delivery_Log!$J$4:$J$4998))*(Delivery_Log!$J$4:$J$4998>0)),Delivery_Log!$J$4:$J$4998),"") | I35: =IFERROR(VLOOKUP(C35,Client_List!$B:$K,10,0),"") -> CANOLA OIL | J35: =IFERROR(_xlfn.MAXIFS(Delivery_Log!$A$4:$A$4998,Delivery_Log!$B$4:$B$4998,B35),"—") -> 46134 | K35: =IFERROR(IF(J35="—","",TODAY()-J35),"") -> 14 | L35: =IFERROR(IF(OR(K35="",H35=""),"",MAX(G35*0.03,G35-K35*H35)),"") | M35: =IFERROR(IF(L35="","",G35-L35),"") | N35: =IFERROR(IF(OR(L35="",H35=""),"",MIN(21,MAX(0,(L35-G35*$C$2)/H35))),"") | O35: =TODAY()+ROUNDUP(N35,0) -> #VALUE! | P35: =IFERROR(IF(N35="","—",IF(N35<=$E$2,"YES","—")),"—") -> — | Q35: =COUNTIFS(Delivery_Log!$B$4:$B$5998,B35,Delivery_Log!$A$4:$A$5998,">="&$Q$2) -> 7 | S35: =IFERROR(_xlfn.XLOOKUP(B35,Client_List!$A$4:$A$200,Client_List!$S$4:$S$200,""),"") | T35: =IFERROR(_xlfn.XLOOKUP(B35,Client_List!$A$4:$A$200,Client_List!$U$4:$U$200,""),"") | U35: =IFERROR(IF(S35="","",IF(_xlfn.XLOOKUP(B35,Client_List!$A$4:$A$200,Client_List!$W$4:$W$200,999)<=24,"LIVE",IF(_xlfn.XLOOKUP(B35,Client_List!$A$4:$A$200,Client_List!$W$4:$W$200,999)<=72,"STALE","OLD"))),"")
