Workbook

Sheet Delivery_Log
A1: S&K OIL SALES — DELIVERY LOG ↓ Append new deliveries below. Column B = Customer # (numeric ID). Column D = lbs delivered.
A2: Columns C, E–K auto-calculate. Do NOT re-sort rows.
A3: Date | B3: Customer # | C3: Customer Name ←auto | D3: Qty Delivered (lbs) | E3: Zone ←auto | F3: Zone Code ←auto | G3: Product ←auto | H3: Tank (lbs) ←auto | I3: Days Since Last ←auto | J3: Lbs/Day ←auto | K3: Running Avg Lbs/Day ←auto
A4: 45955 | B4: 1073 | C4: =IF(B4="","",IFERROR(INDEX(Client_List!$B:$B,MATCH(B4,Client_List!$A:$A,0)),"⚠ NOT FOUND")) | D4: 1903 | E4: =IF(B4="","",IFERROR(INDEX(Client_List!$C:$C,MATCH(VALUE(B4),Client_List!$A:$A,0)),"")) | F4: =IF(B4="","",IFERROR(INDEX(Client_List!$D:$D,MATCH(VALUE(B4),Client_List!$A:$A,0)),"")) | G4: =IF(B4="","",IFERROR(INDEX(Client_List!$K:$K,MATCH(VALUE(B4),Client_List!$A:$A,0)),"")) | H4: =IF(B4="","",IFERROR(INDEX(Client_List!$J:$J,MATCH(VALUE(B4),Client_List!$A:$A,0)),"")) | I4: =IF(B4="","",IFERROR(A4-LOOKUP(2,1/($B3:$B$4=B4),$A3:$A$4),"")) | J4: =IF(B4="","",IFERROR(D4/I4,"")) | K4: =IF(B4="","",IFERROR(AVERAGEIFS($J$4:$J4,$B$4:$B4,B4,$J$4:$J4,">"&0),""))
A5: 45965 | B5: 19107 | C5: =IF(B5="","",IFERROR(INDEX(Client_List!$B:$B,MATCH(B5,Client_List!$A:$A,0)),"⚠ NOT FOUND")) | D5: 228 | E5: =IF(B5="","",IFERROR(INDEX(Client_List!$C:$C,MATCH(VALUE(B5),Client_List!$A:$A,0)),"")) | F5: =IF(B5="","",IFERROR(INDEX(Client_List!$D:$D,MATCH(VALUE(B5),Client_List!$A:$A,0)),"")) | G5: =IF(B5="","",IFERROR(INDEX(Client_List!$K:$K,MATCH(VALUE(B5),Client_List!$A:$A,0)),"")) | H5: =IF(B5="","",IFERROR(INDEX(Client_List!$J:$J,MATCH(VALUE(B5),Client_List!$A:$A,0)),"")) | I5: =IF(B5="","",IFERROR(A5-LOOKUP(2,1/($B4:$B$4=B5),$A4:$A$4),"")) | J5: =IF(B5="","",IFERROR(D5/I5,"")) | K5: =IF(B5="","",IFERROR(AVERAGEIFS($J$4:$J5,$B$4:$B5,B5,$J$4:$J5,">"&0),""))
A6: 46024 | B6: 1083 | C6: =IF(B6="","",IFERROR(INDEX(Client_List!$B:$B,MATCH(B6,Client_List!$A:$A,0)),"⚠ NOT FOUND")) | D6: 354 | E6: =IF(B6="","",IFERROR(INDEX(Client_List!$C:$C,MATCH(VALUE(B6),Client_List!$A:$A,0)),"")) | F6: =IF(B6="","",IFERROR(INDEX(Client_List!$D:$D,MATCH(VALUE(B6),Client_List!$A:$A,0)),"")) | G6: =IF(B6="","",IFERROR(INDEX(Client_List!$K:$K,MATCH(VALUE(B6),Client_List!$A:$A,0)),"")) | H6: =IF(B6="","",IFERROR(INDEX(Client_List!$J:$J,MATCH(VALUE(B6),Client_List!$A:$A,0)),"")) | I6: =IF(B6="","",IFERROR(A6-LOOKUP(2,1/($B$4:$B5=B6),$A$4:$A5),"")) | J6: =IF(B6="","",IFERROR(D6/I6,"")) | K6: =IF(B6="","",IFERROR(AVERAGEIFS($J$4:$J6,$B$4:$B6,B6,$J$4:$J6,">"&0),""))
A7: 46024 | B7: 3063 | C7: =IF(B7="","",IFERROR(INDEX(Client_List!$B:$B,MATCH(B7,Client_List!$A:$A,0)),"⚠ NOT FOUND")) | D7: 1596 | E7: =IF(B7="","",IFERROR(INDEX(Client_List!$C:$C,MATCH(VALUE(B7),Client_List!$A:$A,0)),"")) | F7: =IF(B7="","",IFERROR(INDEX(Client_List!$D:$D,MATCH(VALUE(B7),Client_List!$A:$A,0)),"")) | G7: =IF(B7="","",IFERROR(INDEX(Client_List!$K:$K,MATCH(VALUE(B7),Client_List!$A:$A,0)),"")) | H7: =IF(B7="","",IFERROR(INDEX(Client_List!$J:$J,MATCH(VALUE(B7),Client_List!$A:$A,0)),"")) | I7: =IF(B7="","",IFERROR(A7-LOOKUP(2,1/($B$4:$B6=B7),$A$4:$A6),"")) | J7: =IF(B7="","",IFERROR(D7/I7,"")) | K7: =IF(B7="","",IFERROR(AVERAGEIFS($J$4:$J7,$B$4:$B7,B7,$J$4:$J7,">"&0),""))
A8: 46024 | B8: 4037 | C8: =IF(B8="","",IFERROR(INDEX(Client_List!$B:$B,MATCH(B8,Client_List!$A:$A,0)),"⚠ NOT FOUND")) | D8: 361 | E8: =IF(B8="","",IFERROR(INDEX(Client_List!$C:$C,MATCH(VALUE(B8),Client_List!$A:$A,0)),"")) | F8: =IF(B8="","",IFERROR(INDEX(Client_List!$D:$D,MATCH(VALUE(B8),Client_List!$A:$A,0)),"")) | G8: =IF(B8="","",IFERROR(INDEX(Client_List!$K:$K,MATCH(VALUE(B8),Client_List!$A:$A,0)),"")) | H8: =IF(B8="","",IFERROR(INDEX(Client_List!$J:$J,MATCH(VALUE(B8),Client_List!$A:$A,0)),"")) | I8: =IF(B8="","",IFERROR(A8-LOOKUP(2,1/($B$4:$B7=B8),$A$4:$A7),"")) | J8: =IF(B8="","",IFERROR(D8/I8,"")) | K8: =IF(B8="","",IFERROR(AVERAGEIFS($J$4:$J8,$B$4:$B8,B8,$J$4:$J8,">"&0),""))
A9: 46024 | B9: 8031 | C9: =IF(B9="","",IFERROR(INDEX(Client_List!$B:$B,MATCH(B9,Client_List!$A:$A,0)),"⚠ NOT FOUND")) | D9: 705 | E9: =IF(B9="","",IFERROR(INDEX(Client_List!$C:$C,MATCH(VALUE(B9),Client_List!$A:$A,0)),"")) | F9: =IF(B9="","",IFERROR(INDEX(Client_List!$D:$D,MATCH(VALUE(B9),Client_List!$A:$A,0)),"")) | G9: =IF(B9="","",IFERROR(INDEX(Client_List!$K:$K,MATCH(VALUE(B9),Client_List!$A:$A,0)),"")) | H9: =IF(B9="","",IFERROR(INDEX(Client_List!$J:$J,MATCH(VALUE(B9),Client_List!$A:$A,0)),"")) | I9: =IF(B9="","",IFERROR(A9-LOOKUP(2,1/($B$4:$B8=B9),$A$4:$A8),"")) | J9: =IF(B9="","",IFERROR(D9/I9,"")) | K9: =IF(B9="","",IFERROR(AVERAGEIFS($J$4:$J9,$B$4:$B9,B9,$J$4:$J9,">"&0),""))
A10: 46024 | B10: 10001 | C10: =IF(B10="","",IFERROR(INDEX(Client_List!$B:$B,MATCH(B10,Client_List!$A:$A,0)),"⚠ NOT FOUND")) | D10: 882 | E10: =IF(B10="","",IFERROR(INDEX(Client_List!$C:$C,MATCH(VALUE(B10),Client_List!$A:$A,0)),"")) | F10: =IF(B10="","",IFERROR(INDEX(Client_List!$D:$D,MATCH(VALUE(B10),Client_List!$A:$A,0)),"")) | G10: =IF(B10="","",IFERROR(INDEX(Client_List!$K:$K,MATCH(VALUE(B10),Client_List!$A:$A,0)),"")) | H10: =IF(B10="","",IFERROR(INDEX(Client_List!$J:$J,MATCH(VALUE(B10),Client_List!$A:$A,0)),"")) | I10: =IF(B10="","",IFERROR(A10-LOOKUP(2,1/($B$4:$B9=B10),$A$4:$A9),"")) | J10: =IF(B10="","",IFERROR(D10/I10,"")) | K10: =IF(B10="","",IFERROR(AVERAGEIFS($J$4:$J10,$B$4:$B10,B10,$J$4:$J10,">"&0),""))
A11: 46024 | B11: 14008 | C11: =IF(B11="","",IFERROR(INDEX(Client_List!$B:$B,MATCH(B11,Client_List!$A:$A,0)),"⚠ NOT FOUND")) | D11: 1151 | E11: =IF(B11="","",IFERROR(INDEX(Client_List!$C:$C,MATCH(VALUE(B11),Client_List!$A:$A,0)),"")) | F11: =IF(B11="","",IFERROR(INDEX(Client_List!$D:$D,MATCH(VALUE(B11),Client_List!$A:$A,0)),"")) | G11: =IF(B11="","",IFERROR(INDEX(Client_List!$K:$K,MATCH(VALUE(B11),Client_List!$A:$A,0)),"")) | H11: =IF(B11="","",IFERROR(INDEX(Client_List!$J:$J,MATCH(VALUE(B11),Client_List!$A:$A,0)),"")) | I11: =IF(B11="","",IFERROR(A11-LOOKUP(2,1/($B$4:$B10=B11),$A$4:$A10),"")) | J11: =IF(B11="","",IFERROR(D11/I11,"")) | K11: =IF(B11="","",IFERROR(AVERAGEIFS($J$4:$J11,$B$4:$B11,B11,$J$4:$J11,">"&0),""))
A12: 46024 | B12: 15035 | C12: =IF(B12="","",IFERROR(INDEX(Client_List!$B:$B,MATCH(B12,Client_List!$A:$A,0)),"⚠ NOT FOUND")) | D12: 1401 | E12: =IF(B12="","",IFERROR(INDEX(Client_List!$C:$C,MATCH(VALUE(B12),Client_List!$A:$A,0)),"")) | F12: =IF(B12="","",IFERROR(INDEX(Client_List!$D:$D,MATCH(VALUE(B12),Client_List!$A:$A,0)),"")) | G12: =IF(B12="","",IFERROR(INDEX(Client_List!$K:$K,MATCH(VALUE(B12),Client_List!$A:$A,0)),"")) | H12: =IF(B12="","",IFERROR(INDEX(Client_List!$J:$J,MATCH(VALUE(B12),Client_List!$A:$A,0)),"")) | I12: =IF(B12="","",IFERROR(A12-LOOKUP(2,1/($B$4:$B11=B12),$A$4:$A11),"")) | J12: =IF(B12="","",IFERROR(D12/I12,"")) | K12: =IF(B12="","",IFERROR(AVERAGEIFS($J$4:$J12,$B$4:$B12,B12,$J$4:$J12,">"&0),""))
A13: 46024 | B13: 16010 | C13: =IF(B13="","",IFERROR(INDEX(Client_List!$B:$B,MATCH(B13,Client_List!$A:$A,0)),"⚠ NOT FOUND")) | D13: 1737 | E13: =IF(B13="","",IFERROR(INDEX(Client_List!$C:$C,MATCH(VALUE(B13),Client_List!$A:$A,0)),"")) | F13: =IF(B13="","",IFERROR(INDEX(Client_List!$D:$D,MATCH(VALUE(B13),Client_List!$A:$A,0)),"")) | G13: =IF(B13="","",IFERROR(INDEX(Client_List!$K:$K,MATCH(VALUE(B13),Client_List!$A:$A,0)),"")) | H13: =IF(B13="","",IFERROR(INDEX(Client_List!$J:$J,MATCH(VALUE(B13),Client_List!$A:$A,0)),"")) | I13: =IF(B13="","",IFERROR(A13-LOOKUP(2,1/($B$4:$B12=B13),$A$4:$A12),"")) | J13: =IF(B13="","",IFERROR(D13/I13,"")) | K13: =IF(B13="","",IFERROR(AVERAGEIFS($J$4:$J13,$B$4:$B13,B13,$J$4:$J13,">"&0),""))
A14: 46025 | B14: 1057 | C14: =IF(B14="","",IFERROR(INDEX(Client_List!$B:$B,MATCH(B14,Client_List!$A:$A,0)),"⚠ NOT FOUND")) | D14: 591 | E14: =IF(B14="","",IFERROR(INDEX(Client_List!$C:$C,MATCH(VALUE(B14),Client_List!$A:$A,0)),"")) | F14: =IF(B14="","",IFERROR(INDEX(Client_List!$D:$D,MATCH(VALUE(B14),Client_List!$A:$A,0)),"")) | G14: =IF(B14="","",IFERROR(INDEX(Client_List!$K:$K,MATCH(VALUE(B14),Client_List!$A:$A,0)),"")) | H14: =IF(B14="","",IFERROR(INDEX(Client_List!$J:$J,MATCH(VALUE(B14),Client_List!$A:$A,0)),"")) | I14: =IF(B14="","",IFERROR(A14-LOOKUP(2,1/($B$4:$B13=B14),$A$4:$A13),"")) | J14: =IF(B14="","",IFERROR(D14/I14,"")) | K14: =IF(B14="","",IFERROR(AVERAGEIFS($J$4:$J14,$B$4:$B14,B14,$J$4:$J14,">"&0),""))
A15: 46025 | B15: 2016 | C15: =IF(B15="","",IFERROR(INDEX(Client_List!$B:$B,MATCH(B15,Client_List!$A:$A,0)),"⚠ NOT FOUND")) | D15: 265 | E15: =IF(B15="","",IFERROR(INDEX(Client_List!$C:$C,MATCH(VALUE(B15),Client_List!$A:$A,0)),"")) | F15: =IF(B15="","",IFERROR(INDEX(Client_List!$D:$D,MATCH(VALUE(B15),Client_List!$A:$A,0)),"")) | G15: =IF(B15="","",IFERROR(INDEX(Client_List!$K:$K,MATCH(VALUE(B15),Client_List!$A:$A,0)),"")) | H15: =IF(B15="","",IFERROR(INDEX(Client_List!$J:$J,MATCH(VALUE(B15),Client_List!$A:$A,0)),"")) | I15: =IF(B15="","",IFERROR(A15-LOOKUP(2,1/($B$4:$B14=B15),$A$4:$A14),"")) | J15: =IF(B15="","",IFERROR(D15/I15,"")) | K15: =IF(B15="","",IFERROR(AVERAGEIFS($J$4:$J15,$B$4:$B15,B15,$J$4:$J15,">"&0),""))
A16: 46025 | B16: 3056 | C16: =IF(B16="","",IFERROR(INDEX(Client_List!$B:$B,MATCH(B16,Client_List!$A:$A,0)),"⚠ NOT FOUND")) | D16: 223 | E16: =IF(B16="","",IFERROR(INDEX(Client_List!$C:$C,MATCH(VALUE(B16),Client_List!$A:$A,0)),"")) | F16: =IF(B16="","",IFERROR(INDEX(Client_List!$D:$D,MATCH(VALUE(B16),Client_List!$A:$A,0)),"")) | G16: =IF(B16="","",IFERROR(INDEX(Client_List!$K:$K,MATCH(VALUE(B16),Client_List!$A:$A,0)),"")) | H16: =IF(B16="","",IFERROR(INDEX(Client_List!$J:$J,MATCH(VALUE(B16),Client_List!$A:$A,0)),"")) | I16: =IF(B16="","",IFERROR(A16-LOOKUP(2,1/($B$4:$B15=B16),$A$4:$A15),"")) | J16: =IF(B16="","",IFERROR(D16/I16,"")) | K16: =IF(B16="","",IFERROR(AVERAGEIFS($J$4:$J16,$B$4:$B16,B16,$J$4:$J16,">"&0),""))
A17: 46025 | B17: 4010 | C17: =IF(B17="","",IFERROR(INDEX(Client_List!$B:$B,MATCH(B17,Client_List!$A:$A,0)),"⚠ NOT FOUND")) | D17: 514 | E17: =IF(B17="","",IFERROR(INDEX(Client_List!$C:$C,MATCH(VALUE(B17),Client_List!$A:$A,0)),"")) | F17: =IF(B17="","",IFERROR(INDEX(Client_List!$D:$D,MATCH(VALUE(B17),Client_List!$A:$A,0)),"")) | G17: =IF(B17="","",IFERROR(INDEX(Client_List!$K:$K,MATCH(VALUE(B17),Client_List!$A:$A,0)),"")) | H17: =IF(B17="","",IFERROR(INDEX(Client_List!$J:$J,MATCH(VALUE(B17),Client_List!$A:$A,0)),"")) | I17: =IF(B17="","",IFERROR(A17-LOOKUP(2,1/($B$4:$B16=B17),$A$4:$A16),"")) | J17: =IF(B17="","",IFERROR(D17/I17,"")) | K17: =IF(B17="","",IFERROR(AVERAGEIFS($J$4:$J17,$B$4:$B17,B17,$J$4:$J17,">"&0),""))
... A81: 46031 | B81: 2067 | C81: =IF(B81="","",IFERROR(INDEX(Client_List!$B:$B,MATCH(B81,Client_List!$A:$A,0)),"⚠ NOT FOUND")) | D81: 789 | E81: =IF(B81="","",IFERROR(INDEX(Client_List!$C:$C,MATCH(VALUE(B81),Client_List!$A:$A,0)),"")) | F81: =IF(B81="","",IFERROR(INDEX(Client_List!$D:$D,MATCH(VALUE(B81),Client_List!$A:$A,0)),"")) | G81: =IF(B81="","",IFERROR(INDEX(Client_List!$K:$K,MATCH(VALUE(B81),Client_List!$A:$A,0)),"")) | H81: =IF(B81="","",IFERROR(INDEX(Client_List!$J:$J,MATCH(VALUE(B81),Client_List!$A:$A,0)),"")) | I81: =IF(B81="","",IFERROR(A81-LOOKUP(2,1/($B$4:$B80=B81),$A$4:$A80),"")) | J81: =IF(B81="","",IFERROR(D81/I81,"")) | K81: =IF(B81="","",IFERROR(AVERAGEIFS($J$4:$J81,$B$4:$B81,B81,$J$4:$J81,">"&0),""))
A82: 46031 | B82: 4015A | C82: =IF(B82="","",IFERROR(INDEX(Client_List!$B:$B,MATCH(B82,Client_List!$A:$A,0)),"⚠ NOT FOUND")) | D82: 480 | E82: =IF(B82="","",IFERROR(INDEX(Client_List!$C:$C,MATCH(VALUE(B82),Client_List!$A:$A,0)),"")) | F82: =IF(B82="","",IFERROR(INDEX(Client_List!$D:$D,MATCH(VALUE(B82),Client_List!$A:$A,0)),"")) | G82: =IF(B82="","",IFERROR(INDEX(Client_List!$K:$K,MATCH(VALUE(B82),Client_List!$A:$A,0)),"")) | H82: =IF(B82="","",IFERROR(INDEX(Client_List!$J:$J,MATCH(VALUE(B82),Client_List!$A:$A,0)),"")) | I82: =IF(B82="","",IFERROR(A82-LOOKUP(2,1/($B$4:$B81=B82),$A$4:$A81),"")) | J82: =IF(B82="","",IFERROR(D82/I82,"")) | K82: =IF(B82="","",IFERROR(AVERAGEIFS($J$4:$J82,$B$4:$B82,B82,$J$4:$J82,">"&0),""))
A83: 46031 | B83: 7001 | C83: =IF(B83="","",IFERROR(INDEX(Client_List!$B:$B,MATCH(B83,Client_List!$A:$A,0)),"⚠ NOT FOUND")) | D83: 1347 | E83: =IF(B83="","",IFERROR(INDEX(Client_List!$C:$C,MATCH(VALUE(B83),Client_List!$A:$A,0)),"")) | F83: =IF(B83="","",IFERROR(INDEX(Client_List!$D:$D,MATCH(VALUE(B83),Client_List!$A:$A,0)),"")) | G83: =IF(B83="","",IFERROR(INDEX(Client_List!$K:$K,MATCH(VALUE(B83),Client_List!$A:$A,0)),"")) | H83: =IF(B83="","",IFERROR(INDEX(Client_List!$J:$J,MATCH(VALUE(B83),Client_List!$A:$A,0)),"")) | I83: =IF(B83="","",IFERROR(A83-LOOKUP(2,1/($B$4:$B82=B83),$A$4:$A82),"")) | J83: =IF(B83="","",IFERROR(D83/I83,"")) | K83: =IF(B83="","",IFERROR(AVERAGEIFS($J$4:$J83,$B$4:$B83,B83,$J$4:$J83,">"&0),""))
A84: 46031 | B84: 13009 | C84: =IF(B84="","",IFERROR(INDEX(Client_List!$B:$B,MATCH(B84,Client_List!$A:$A,0)),"⚠ NOT FOUND")) | D84: 832 | E84: =IF(B84="","",IFERROR(INDEX(Client_List!$C:$C,MATCH(VALUE(B84),Client_List!$A:$A,0)),"")) | F84: =IF(B84="","",IFERROR(INDEX(Client_List!$D:$D,MATCH(VALUE(B84),Client_List!$A:$A,0)),"")) | G84: =IF(B84="","",IFERROR(INDEX(Client_List!$K:$K,MATCH(VALUE(B84),Client_List!$A:$A,0)),"")) | H84: =IF(B84="","",IFERROR(INDEX(Client_List!$J:$J,MATCH(VALUE(B84),Client_List!$A:$A,0)),"")) | I84: =IF(B84="","",IFERROR(A84-LOOKUP(2,1/($B$4:$B83=B84),$A$4:$A83),"")) | J84: =IF(B84="","",IFERROR(D84/I84,"")) | K84: =IF(B84="","",IFERROR(AVERAGEIFS($J$4:$J84,$B$4:$B84,B84,$J$4:$J84,">"&0),""))
A85: 46031 | B85: 15016 | C85: =IF(B85="","",IFERROR(INDEX(Client_List!$B:$B,MATCH(B85,Client_List!$A:$A,0)),"⚠ NOT FOUND")) | D85: 340 | E85: =IF(B85="","",IFERROR(INDEX(Client_List!$C:$C,MATCH(VALUE(B85),Client_List!$A:$A,0)),"")) | F85: =IF(B85="","",IFERROR(INDEX(Client_List!$D:$D,MATCH(VALUE(B85),Client_List!$A:$A,0)),"")) | G85: =IF(B85="","",IFERROR(INDEX(Client_List!$K:$K,MATCH(VALUE(B85),Client_List!$A:$A,0)),"")) | H85: =IF(B85="","",IFERROR(INDEX(Client_List!$J:$J,MATCH(VALUE(B85),Client_List!$A:$A,0)),"")) | I85: =IF(B85="","",IFERROR(A85-LOOKUP(2,1/($B$4:$B84=B85),$A$4:$A84),"")) | J85: =IF(B85="","",IFERROR(D85/I85,"")) | K85: =IF(B85="","",IFERROR(AVERAGEIFS($J$4:$J85,$B$4:$B85,B85,$J$4:$J85,">"&0),""))
A86: 46031 | B86: 16015 | C86: =IF(B86="","",IFERROR(INDEX(Client_List!$B:$B,MATCH(B86,Client_List!$A:$A,0)),"⚠ NOT FOUND")) | D86: 1514 | E86: =IF(B86="","",IFERROR(INDEX(Client_List!$C:$C,MATCH(VALUE(B86),Client_List!$A:$A,0)),"")) | F86: =IF(B86="","",IFERROR(INDEX(Client_List!$D:$D,MATCH(VALUE(B86),Client_List!$A:$A,0)),"")) | G86: =IF(B86="","",IFERROR(INDEX(Client_List!$K:$K,MATCH(VALUE(B86),Client_List!$A:$A,0)),"")) | H86: =IF(B86="","",IFERROR(INDEX(Client_List!$J:$J,MATCH(VALUE(B86),Client_List!$A:$A,0)),"")) | I86: =IF(B86="","",IFERROR(A86-LOOKUP(2,1/($B$4:$B85=B86),$A$4:$A85),"")) | J86: =IF(B86="","",IFERROR(D86/I86,"")) | K86: =IF(B86="","",IFERROR(AVERAGEIFS($J$4:$J86,$B$4:$B86,B86,$J$4:$J86,">"&0),""))
A87: 46031 | B87: 22006 | C87: =IF(B87="","",IFERROR(INDEX(Client_List!$B:$B,MATCH(B87,Client_List!$A:$A,0)),"⚠ NOT FOUND")) | D87: 676 | E87: =IF(B87="","",IFERROR(INDEX(Client_List!$C:$C,MATCH(VALUE(B87),Client_List!$A:$A,0)),"")) | F87: =IF(B87="","",IFERROR(INDEX(Client_List!$D:$D,MATCH(VALUE(B87),Client_List!$A:$A,0)),"")) | G87: =IF(B87="","",IFERROR(INDEX(Client_List!$K:$K,MATCH(VALUE(B87),Client_List!$A:$A,0)),"")) | H87: =IF(B87="","",IFERROR(INDEX(Client_List!$J:$J,MATCH(VALUE(B87),Client_List!$A:$A,0)),"")) | I87: =IF(B87="","",IFERROR(A87-LOOKUP(2,1/($B$4:$B86=B87),$A$4:$A86),"")) | J87: =IF(B87="","",IFERROR(D87/I87,"")) | K87: =IF(B87="","",IFERROR(AVERAGEIFS($J$4:$J87,$B$4:$B87,B87,$J$4:$J87,">"&0),""))
A88: 46032 | B88: 11005 | C88: =IF(B88="","",IFERROR(INDEX(Client_List!$B:$B,MATCH(B88,Client_List!$A:$A,0)),"⚠ NOT FOUND")) | D88: 639 | E88: =IF(B88="","",IFERROR(INDEX(Client_List!$C:$C,MATCH(VALUE(B88),Client_List!$A:$A,0)),"")) | F88: =IF(B88="","",IFERROR(INDEX(Client_List!$D:$D,MATCH(VALUE(B88),Client_List!$A:$A,0)),"")) | G88: =IF(B88="","",IFERROR(INDEX(Client_List!$K:$K,MATCH(VALUE(B88),Client_List!$A:$A,0)),"")) | H88: =IF(B88="","",IFERROR(INDEX(Client_List!$J:$J,MATCH(VALUE(B88),Client_List!$A:$A,0)),"")) | I88: =IF(B88="","",IFERROR(A88-LOOKUP(2,1/($B$4:$B87=B88),$A$4:$A87),"")) | J88: =IF(B88="","",IFERROR(D88/I88,"")) | K88: =IF(B88="","",IFERROR(AVERAGEIFS($J$4:$J88,$B$4:$B88,B88,$J$4:$J88,">"&0),""))
A89: 46032 | B89: 12021 | C89: =IF(B89="","",IFERROR(INDEX(Client_List!$B:$B,MATCH(B89,Client_List!$A:$A,0)),"⚠ NOT FOUND")) | D89: 348 | E89: =IF(B89="","",IFERROR(INDEX(Client_List!$C:$C,MATCH(VALUE(B89),Client_List!$A:$A,0)),"")) | F89: =IF(B89="","",IFERROR(INDEX(Client_List!$D:$D,MATCH(VALUE(B89),Client_List!$A:$A,0)),"")) | G89: =IF(B89="","",IFERROR(INDEX(Client_List!$K:$K,MATCH(VALUE(B89),Client_List!$A:$A,0)),"")) | H89: =IF(B89="","",IFERROR(INDEX(Client_List!$J:$J,MATCH(VALUE(B89),Client_List!$A:$A,0)),"")) | I89: =IF(B89="","",IFERROR(A89-LOOKUP(2,1/($B$4:$B88=B89),$A$4:$A88),"")) | J89: =IF(B89="","",IFERROR(D89/I89,"")) | K89: =IF(B89="","",IFERROR(AVERAGEIFS($J$4:$J89,$B$4:$B89,B89,$J$4:$J89,">"&0),""))
A90: 46032 | B90: 15004 | C90: =IF(B90="","",IFERROR(INDEX(Client_List!$B:$B,MATCH(B90,Client_List!$A:$A,0)),"⚠ NOT FOUND")) | D90: 386 | E90: =IF(B90="","",IFERROR(INDEX(Client_List!$C:$C,MATCH(VALUE(B90),Client_List!$A:$A,0)),"")) | F90: =IF(B90="","",IFERROR(INDEX(Client_List!$D:$D,MATCH(VALUE(B90),Client_List!$A:$A,0)),"")) | G90: =IF(B90="","",IFERROR(INDEX(Client_List!$K:$K,MATCH(VALUE(B90),Client_List!$A:$A,0)),"")) | H90: =IF(B90="","",IFERROR(INDEX(Client_List!$J:$J,MATCH(VALUE(B90),Client_List!$A:$A,0)),"")) | I90: =IF(B90="","",IFERROR(A90-LOOKUP(2,1/($B$4:$B89=B90),$A$4:$A89),"")) | J90: =IF(B90="","",IFERROR(D90/I90,"")) | K90: =IF(B90="","",IFERROR(AVERAGEIFS($J$4:$J90,$B$4:$B90,B90,$J$4:$J90,">"&0),""))
A91: 46032 | B91: 15032 | C91: =IF(B91="","",IFERROR(INDEX(Client_List!$B:$B,MATCH(B91,Client_List!$A:$A,0)),"⚠ NOT FOUND")) | D91: 632 | E91: =IF(B91="","",IFERROR(INDEX(Client_List!$C:$C,MATCH(VALUE(B91),Client_List!$A:$A,0)),"")) | F91: =IF(B91="","",IFERROR(INDEX(Client_List!$D:$D,MATCH(VALUE(B91),Client_List!$A:$A,0)),"")) | G91: =IF(B91="","",IFERROR(INDEX(Client_List!$K:$K,MATCH(VALUE(B91),Client_List!$A:$A,0)),"")) | H91: =IF(B91="","",IFERROR(INDEX(Client_List!$J:$J,MATCH(VALUE(B91),Client_List!$A:$A,0)),"")) | I91: =IF(B91="","",IFERROR(A91-LOOKUP(2,1/($B$4:$B90=B91),$A$4:$A90),"")) | J91: =IF(B91="","",IFERROR(D91/I91,"")) | K91: =IF(B91="","",IFERROR(AVERAGEIFS($J$4:$J91,$B$4:$B91,B91,$J$4:$J91,">"&0),""))
A92: 46033 | B92: 1000 | C92: =IF(B92="","",IFERROR(INDEX(Client_List!$B:$B,MATCH(B92,Client_List!$A:$A,0)),"⚠ NOT FOUND")) | D92: 938 | E92: =IF(B92="","",IFERROR(INDEX(Client_List!$C:$C,MATCH(VALUE(B92),Client_List!$A:$A,0)),"")) | F92: =IF(B92="","",IFERROR(INDEX(Client_List!$D:$D,MATCH(VALUE(B92),Client_List!$A:$A,0)),"")) | G92: =IF(B92="","",IFERROR(INDEX(Client_List!$K:$K,MATCH(VALUE(B92),Client_List!$A:$A,0)),"")) | H92: =IF(B92="","",IFERROR(INDEX(Client_List!$J:$J,MATCH(VALUE(B92),Client_List!$A:$A,0)),"")) | I92: =IF(B92="","",IFERROR(A92-LOOKUP(2,1/($B$4:$B91=B92),$A$4:$A91),"")) | J92: =IF(B92="","",IFERROR(D92/I92,"")) | K92: =IF(B92="","",IFERROR(AVERAGEIFS($J$4:$J92,$B$4:$B92,B92,$J$4:$J92,">"&0),""))
A93: 46033 | B93: 1081 | C93: =IF(B93="","",IFERROR(INDEX(Client_List!$B:$B,MATCH(B93,Client_List!$A:$A,0)),"⚠ NOT FOUND")) | D93: 307 | E93: =IF(B93="","",IFERROR(INDEX(Client_List!$C:$C,MATCH(VALUE(B93),Client_List!$A:$A,0)),"")) | F93: =IF(B93="","",IFERROR(INDEX(Client_List!$D:$D,MATCH(VALUE(B93),Client_List!$A:$A,0)),"")) | G93: =IF(B93="","",IFERROR(INDEX(Client_List!$K:$K,MATCH(VALUE(B93),Client_List!$A:$A,0)),"")) | H93: =IF(B93="","",IFERROR(INDEX(Client_List!$J:$J,MATCH(VALUE(B93),Client_List!$A:$A,0)),"")) | I93: =IF(B93="","",IFERROR(A93-LOOKUP(2,1/($B$4:$B92=B93),$A$4:$A92),"")) | J93: =IF(B93="","",IFERROR(D93/I93,"")) | K93: =IF(B93="","",IFERROR(AVERAGEIFS($J$4:$J93,$B$4:$B93,B93,$J$4:$J93,">"&0),""))
A94: 46033 | B94: 4026 | C94: =IF(B94="","",IFERROR(INDEX(Client_List!$B:$B,MATCH(B94,Client_List!$A:$A,0)),"⚠ NOT FOUND")) | D94: 336 | E94: =IF(B94="","",IFERROR(INDEX(Client_List!$C:$C,MATCH(VALUE(B94),Client_List!$A:$A,0)),"")) | F94: =IF(B94="","",IFERROR(INDEX(Client_List!$D:$D,MATCH(VALUE(B94),Client_List!$A:$A,0)),"")) | G94: =IF(B94="","",IFERROR(INDEX(Client_List!$K:$K,MATCH(VALUE(B94),Client_List!$A:$A,0)),"")) | H94: =IF(B94="","",IFERROR(INDEX(Client_List!$J:$J,MATCH(VALUE(B94),Client_List!$A:$A,0)),"")) | I94: =IF(B94="","",IFERROR(A94-LOOKUP(2,1/($B$4:$B93=B94),$A$4:$A93),"")) | J94: =IF(B94="","",IFERROR(D94/I94,"")) | K94: =IF(B94="","",IFERROR(AVERAGEIFS($J$4:$J94,$B$4:$B94,B94,$J$4:$J94,">"&0),""))
... A238: 46045 | B238: 4009 | C238: =IF(B238="","",IFERROR(INDEX(Client_List!$B:$B,MATCH(B238,Client_List!$A:$A,0)),"⚠ NOT FOUND")) | D238: 677 | E238: =IF(B238="","",IFERROR(INDEX(Client_List!$C:$C,MATCH(VALUE(B238),Client_List!$A:$A,0)),"")) | F238: =IF(B238="","",IFERROR(INDEX(Client_List!$D:$D,MATCH(VALUE(B238),Client_List!$A:$A,0)),"")) | G238: =IF(B238="","",IFERROR(INDEX(Client_List!$K:$K,MATCH(VALUE(B238),Client_List!$A:$A,0)),"")) | H238: =IF(B238="","",IFERROR(INDEX(Client_List!$J:$J,MATCH(VALUE(B238),Client_List!$A:$A,0)),"")) | I238: =IF(B238="","",IFERROR(A238-LOOKUP(2,1/($B$4:$B237=B238),$A$4:$A237),"")) | J238: =IF(B238="","",IFERROR(D238/I238,"")) | K238: =IF(B238="","",IFERROR(AVERAGEIFS($J$4:$J238,$B$4:$B238,B238,$J$4:$J238,">"&0),""))
A239: 46045 | B239: 4015A | C239: =IF(B239="","",IFERROR(INDEX(Client_List!$B:$B,MATCH(B239,Client_List!$A:$A,0)),"⚠ NOT FOUND")) | D239: 490 | E239: =IF(B239="","",IFERROR(INDEX(Client_List!$C:$C,MATCH(VALUE(B239),Client_List!$A:$A,0)),"")) | F239: =IF(B239="","",IFERROR(INDEX(Client_List!$D:$D,MATCH(VALUE(B239),Client_List!$A:$A,0)),"")) | G239: =IF(B239="","",IFERROR(INDEX(Client_List!$K:$K,MATCH(VALUE(B239),Client_List!$A:$A,0)),"")) | H239: =IF(B239="","",IFERROR(INDEX(Client_List!$J:$J,MATCH(VALUE(B239),Client_List!$A:$A,0)),"")) | I239: =IF(B239="","",IFERROR(A239-LOOKUP(2,1/($B$4:$B238=B239),$A$4:$A238),"")) | J239: =IF(B239="","",IFERROR(D239/I239,"")) | K239: =IF(B239="","",IFERROR(AVERAGEIFS($J$4:$J239,$B$4:$B239,B239,$J$4:$J239,">"&0),""))
A240: 46045 | B240: 6101 | C240: =IF(B240="","",IFERROR(INDEX(Client_List!$B:$B,MATCH(B240,Client_List!$A:$A,0)),"⚠ NOT FOUND")) | D240: 641 | E240: =IF(B240="","",IFERROR(INDEX(Client_List!$C:$C,MATCH(VALUE(B240),Client_List!$A:$A,0)),"")) | F240: =IF(B240="","",IFERROR(INDEX(Client_List!$D:$D,MATCH(VALUE(B240),Client_List!$A:$A,0)),"")) | G240: =IF(B240="","",IFERROR(INDEX(Client_List!$K:$K,MATCH(VALUE(B240),Client_List!$A:$A,0)),"")) | H240: =IF(B240="","",IFERROR(INDEX(Client_List!$J:$J,MATCH(VALUE(B240),Client_List!$A:$A,0)),"")) | I240: =IF(B240="","",IFERROR(A240-LOOKUP(2,1/($B$4:$B239=B240),$A$4:$A239),"")) | J240: =IF(B240="","",IFERROR(D240/I240,"")) | K240: =IF(B240="","",IFERROR(AVERAGEIFS($J$4:$J240,$B$4:$B240,B240,$J$4:$J240,">"&0),""))
A241: 46045 | B241: 8034 | C241: =IF(B241="","",IFERROR(INDEX(Client_List!$B:$B,MATCH(B241,Client_List!$A:$A,0)),"⚠ NOT FOUND")) | D241: 609 | E241: =IF(B241="","",IFERROR(INDEX(Client_List!$C:$C,MATCH(VALUE(B241),Client_List!$A:$A,0)),"")) | F241: =IF(B241="","",IFERROR(INDEX(Client_List!$D:$D,MATCH(VALUE(B241),Client_List!$A:$A,0)),"")) | G241: =IF(B241="","",IFERROR(INDEX(Client_List!$K:$K,MATCH(VALUE(B241),Client_List!$A:$A,0)),"")) | H241: =IF(B241="","",IFERROR(INDEX(Client_List!$J:$J,MATCH(VALUE(B241),Client_List!$A:$A,0)),"")) | I241: =IF(B241="","",IFERROR(A241-LOOKUP(2,1/($B$4:$B240=B241),$A$4:$A240),"")) | J241: =IF(B241="","",IFERROR(D241/I241,"")) | K241: =IF(B241="","",IFERROR(AVERAGEIFS($J$4:$J241,$B$4:$B241,B241,$J$4:$J241,">"&0),""))
A242: 46045 | B242: 12025 | C242: =IF(B242="","",IFERROR(INDEX(Client_List!$B:$B,MATCH(B242,Client_List!$A:$A,0)),"⚠ NOT FOUND")) | D242: 381 | E242: =IF(B242="","",IFERROR(INDEX(Client_List!$C:$C,MATCH(VALUE(B242),Client_List!$A:$A,0)),"")) | F242: =IF(B242="","",IFERROR(INDEX(Client_List!$D:$D,MATCH(VALUE(B242),Client_List!$A:$A,0)),"")) | G242: =IF(B242="","",IFERROR(INDEX(Client_List!$K:$K,MATCH(VALUE(B242),Client_List!$A:$A,0)),"")) | H242: =IF(B242="","",IFERROR(INDEX(Client_List!$J:$J,MATCH(VALUE(B242),Client_List!$A:$A,0)),"")) | I242: =IF(B242="","",IFERROR(A242-LOOKUP(2,1/($B$4:$B241=B242),$A$4:$A241),"")) | J242: =IF(B242="","",IFERROR(D242/I242,"")) | K242: =IF(B242="","",IFERROR(AVERAGEIFS($J$4:$J242,$B$4:$B242,B242,$J$4:$J242,">"&0),""))
A243: 46045 | B243: 13015 | C243: =IF(B243="","",IFERROR(INDEX(Client_List!$B:$B,MATCH(B243,Client_List!$A:$A,0)),"⚠ NOT FOUND")) | D243: 946 | E243: =IF(B243="","",IFERROR(INDEX(Client_List!$C:$C,MATCH(VALUE(B243),Client_List!$A:$A,0)),"")) | F243: =IF(B243="","",IFERROR(INDEX(Client_List!$D:$D,MATCH(VALUE(B243),Client_List!$A:$A,0)),"")) | G243: =IF(B243="","",IFERROR(INDEX(Client_List!$K:$K,MATCH(VALUE(B243),Client_List!$A:$A,0)),"")) | H243: =IF(B243="","",IFERROR(INDEX(Client_List!$J:$J,MATCH(VALUE(B243),Client_List!$A:$A,0)),"")) | I243: =IF(B243="","",IFERROR(A243-LOOKUP(2,1/($B$4:$B242=B243),$A$4:$A242),"")) | J243: =IF(B243="","",IFERROR(D243/I243,"")) | K243: =IF(B243="","",IFERROR(AVERAGEIFS($J$4:$J243,$B$4:$B243,B243,$J$4:$J243,">"&0),""))
A244: 46045 | B244: 13061 | C244: =IF(B244="","",IFERROR(INDEX(Client_List!$B:$B,MATCH(B244,Client_List!$A:$A,0)),"⚠ NOT FOUND")) | D244: 340 | E244: =IF(B244="","",IFERROR(INDEX(Client_List!$C:$C,MATCH(VALUE(B244),Client_List!$A:$A,0)),"")) | F244: =IF(B244="","",IFERROR(INDEX(Client_List!$D:$D,MATCH(VALUE(B244),Client_List!$A:$A,0)),"")) | G244: =IF(B244="","",IFERROR(INDEX(Client_List!$K:$K,MATCH(VALUE(B244),Client_List!$A:$A,0)),"")) | H244: =IF(B244="","",IFERROR(INDEX(Client_List!$J:$J,MATCH(VALUE(B244),Client_List!$A:$A,0)),"")) | I244: =IF(B244="","",IFERROR(A244-LOOKUP(2,1/($B$4:$B243=B244),$A$4:$A243),"")) | J244: =IF(B244="","",IFERROR(D244/I244,"")) | K244: =IF(B244="","",IFERROR(AVERAGEIFS($J$4:$J244,$B$4:$B244,B244,$J$4:$J244,">"&0),""))
A245: 46045 | B245: 13069 | C245: =IF(B245="","",IFERROR(INDEX(Client_List!$B:$B,MATCH(B245,Client_List!$A:$A,0)),"⚠ NOT FOUND")) | D245: 958 | E245: =IF(B245="","",IFERROR(INDEX(Client_List!$C:$C,MATCH(VALUE(B245),Client_List!$A:$A,0)),"")) | F245: =IF(B245="","",IFERROR(INDEX(Client_List!$D:$D,MATCH(VALUE(B245),Client_List!$A:$A,0)),"")) | G245: =IF(B245="","",IFERROR(INDEX(Client_List!$K:$K,MATCH(VALUE(B245),Client_List!$A:$A,0)),"")) | H245: =IF(B245="","",IFERROR(INDEX(Client_List!$J:$J,MATCH(VALUE(B245),Client_List!$A:$A,0)),"")) | I245: =IF(B245="","",IFERROR(A245-LOOKUP(2,1/($B$4:$B244=B245),$A$4:$A244),"")) | J245: =IF(B245="","",IFERROR(D245/I245,"")) | K245: =IF(B245="","",IFERROR(AVERAGEIFS($J$4:$J245,$B$4:$B245,B245,$J$4:$J245,">"&0),""))
A246: 46045 | B246: 15016 | C246: =IF(B246="","",IFERROR(INDEX(Client_List!$B:$B,MATCH(B246,Client_List!$A:$A,0)),"⚠ NOT FOUND")) | D246: 318 | E246: =IF(B246="","",IFERROR(INDEX(Client_List!$C:$C,MATCH(VALUE(B246),Client_List!$A:$A,0)),"")) | F246: =IF(B246="","",IFERROR(INDEX(Client_List!$D:$D,MATCH(VALUE(B246),Client_List!$A:$A,0)),"")) | G246: =IF(B246="","",IFERROR(INDEX(Client_List!$K:$K,MATCH(VALUE(B246),Client_List!$A:$A,0)),"")) | H246: =IF(B246="","",IFERROR(INDEX(Client_List!$J:$J,MATCH(VALUE(B246),Client_List!$A:$A,0)),"")) | I246: =IF(B246="","",IFERROR(A246-LOOKUP(2,1/($B$4:$B245=B246),$A$4:$A245),"")) | J246: =IF(B246="","",IFERROR(D246/I246,"")) | K246: =IF(B246="","",IFERROR(AVERAGEIFS($J$4:$J246,$B$4:$B246,B246,$J$4:$J246,">"&0),""))
...

Sheet Client_List
A1: S&K CLIENT LIST — Edit Address, Lat, Lon, Tank Size and Product here
A2: YELLOW columns = edit freely. Changes here flow automatically into Optimizer_Input via VLOOKUP. Customer name in col B must match Delivery_Log exactly.
A3: ID | B3: Customer Name | C3: Zone | D3: Zone Code | E3: Street Address | F3: City | G3: State | H3: Latitude | I3: Longitude | J3: Tank Size (lbs) | K3: Product
A4: 1 | B4: 51ST - 0001 - 51ST AVE CAFE | C4: 2 | D4: 2D | E4: 5511 N 51St Ave | F4: Glendale | G4: AZ | H4: 33.517199 | I4: -112.16811 | J4: 350 | K4: FRYERS CHOICE BLEND | N4: 254-237-3350
A5: 1018 | B5: AJO - 1018 - AJO ALS BELL | C5: 2 | D5: 2C | E5: 7458 W Bell Rd | F5: Glendale | G5: AZ | H5: 33.639017 | I5: -112.21978 | J5: 950 | K5: CANOLA OIL | N5: 623-334-9899
A6: 1063 | B6: ALL - 1063 - ALL AMERICAN MODERN SPORTS GRILL | C6: 4 | D6: 4C | E6: 20751 N PIMA RD #105 | F6: Scottsdale | G6: AZ | H6: 33.674519 | I6: -111.88803 | J6: 900 | K6: CANOLA OIL | N6: (480) 887-0652
A7: 1073 | B7: AME - 1073 - AMELIO C ENTERPRISES, INC (CACTUS CANDY) | C7: 4 | D7: 4C | E7: 2656 N 37TH DR | F7: PHOENIX | G7: AZ | H7: 33.478277 | I7: -112.14051 | J7: 2000 | K7: CANOLA OIL | N7: (602) 956-4833
A8: 1054 | B8: ANG - 1054 - ANGRY CRAB SURPRISE | C8: 1 | D8: 1C | E8: 11340 W BELL RD SUITE 118 | F8: SURPRISE | G8: AZ | H8: 33.639939 | I8: -112.30419 | J8: 620 | K8: FRYERS CHOICE BLEND | N8: (623) 248-9190
A9: 1000 | B9: ARR79 - 1000 - ARRIBAS 79TH AVE. | C9: 2 | D9: 2C | E9: 17211 N 79Th Ave | F9: Glendale | G9: AZ | H9: 33.640214 | I9: -112.22941 | J9: 950 | K9: CANOLA OIL | N9: 623-878-5777
A10: 1001 | B10: ARRC - 1001 - ARRIBAS CAMELBACK | C10: 3 | D10: 3D | E10: 1812 E Camelback Rd | F10: Phoenix | G10: AZ | H10: 33.50958 | I10: -112.04259 | J10: 700 | K10: CANOLA OIL | N10: 480-948-9969
A11: 1011 | B11: ARRC - 1011 - ARRIBAS CHANDLER | C11: 4 | D11: 4F | E11: 4649 E Chandler Blvd | F11: Phoenix | G11: AZ | H11: 33.304826 | I11: -111.98161 | J11: 1000 | K11: CANOLA OIL | N11: 623-878-5777
A12: 1014 | B12: ARRC - 1014 - ARRIBA GILBERT | C12: 5 | D12: 5F | E12: 2855 S Market St, Gilbert, AZ 85295 | F12: Gilbert | G12: AZ | H12: 33.29809 | I12: -111.74427 | J12: 900 | K12: CANOLA OIL | N12: 480-899-7337
A13: 1013 | B13: ARRM - 1013 - ARRIBAS GOODYEAR | C13: 1 | D13: 1D | E13: 15370 W McDowell Rd | F13: Goodyear | G13: AZ | H13: 33.46499 | I13: -112.3899 | J13: 900 | K13: CANOLA OIL | N13: 623-223-1735
A14: 1081 | B14: ATL - 1081 - ATL WINGS ROOSEVELT | C14: 3 | D14: 3D | E14: 330 E ROOSEVELT RD | F14: PHOENIX | G14: AZ | H14: 33.458941 | I14: -112.06855 | J14: 350 | K14: CANOLA OIL | N14: (602) 741-9554
A15: 1083 | B15: ATL - 1083 - ATL WINGS MESA | C15: 5 | D15: 5D | E15: 6837 E MAIN ST | F15: Mesa | G15: AZ | H15: 33.415147 | I15: -111.68318 | J15: 425 | K15: CANOLA OIL | N15: (480) 722-9464
... A26: 4038 | B26: BUR - 4038 - BURGERS & BREWS GLENDALE | C26: 2 | D26: 2C | E26: 6670 W CACTUS RD | F26: GLENDALE | G26: AZ | H26: 33.597456 | I26: -112.20202 | J26: 1050 | K26: CANOLA OIL | N26: (623) 776-2266
A27: 3063 | B27: CAR - 3063 - CARDINAL STADIUM | C27: 2 | D27: 2D | E27: 1 CARDINAL DR | F27: GLENDALE | G27: ARIZONA | H27: 33.526233 | I27: -112.26611 | J27: 2500 | K27: CANOLA OIL
A28: 3069 | B28: CAS - 3069 - CASA DE FALAFEL | C28: 2 | D28: 2C | E28: 4920 W Thunderbird Rd | F28: Glendale | G28: AZ | H28: 33.611633 | I28: -112.16541 | J28: 1000 | K28: CANOLA OIL | N28: (480) 689-0514
A29: 3021 | B29: CRA - 3021 - JC FOOD TRADING/GLEN | C29: 2 | D29: 2C | E29: CRAZY MIKES CHICKEN | F29: Glendale | G29: AZ | H29: 33.639787 | I29: -112.17386 | J29: 450 | K29: CANOLA OIL | N29: 623-463-6881
A30: 3046 | B30: CRA - 3046 - JC FOOD TRADING /GOODYEAR | C30: 2 | D30: 2C | E30: CRAZY MIKE'S GOODYEAR | F30: Goodyear | G30: AZ | H30: 33.483996 | I30: -112.36512 | J30: 1000 | K30: CANOLA OIL | N30: 213-700-4092
A31: 3065 | B31: CRA - 3065 - CRAFTED CUISINE | C31: 4 | D31: 4D | E31: 6736 E Avalon Dr | F31: Scottsdale | G31: AZ | H31: 33.483076 | I31: -111.93581 | J31: 350 | K31: CANOLA OIL | N31: (210) 529-1900
A32: 3064 | B32: CRO - 3064 - CROWNE PLAZA RESORT | C32: 4 | D32: 4F | E32: One N San Marcos Pl | F32: Chandler | G32: Arizona | H32: 33.320637 | I32: -111.84377 | J32: 700 | K32: CANOLA OIL | N32: (480) 812-0900
A33: 4015A | B33: DAI - 4015A - DAIRY QUEEN BELL | C33: 3 | D33: 3C | E33: 3550 E BELL ROAD | F33: PHOENIX | G33: AZ | H33: 33.641001 | I33: -112.00519 | J33: 500 | K33: CANOLA OIL | N33: 602-788-0261 (JACIE M
A34: 4026 | B34: DAR - 4026 - DARUMA BY RIE | C34: 4 | D34: 4E | E34: 1116 E DOBSON RD | F34: MESA | G34: AZ | H34: 33.39476 | I34: -111.87536 | J34: 350 | K34: CANOLA OIL | N34: (480) 590-7979
A35: 4037 | B35: DAR - 4037 - DARUMA RAMEN AND BOWL | C35: 4 | D35: 4E | E35: 2650 E UNIVERSITY DR | F35: MESA | G35: AZ | H35: 33.423457 | I35: -111.7736 | J35: 350 | K35: CANOLA OIL | N35: (562) 760-8262
A36: 4009 | B36: DIL - 4009 - DILLONS BBQ | C36: 1 | D36: 1D | E36: 16335 W Northern Ave | F36: Litchfield Pk | G36: AZ | H36: 33.549985 | I36: -112.41071 | J36: 1050 | K36: FRYERS CHOICE BLEND | N36: 623-535-4249
A37: C173 | B37: PIN - 16058 - PINYON RESTAURANT | C37: 4 | D37: 4D | E37: 7363 E Scottsdale Mall | F37: Scottsdale | G37: AZ | H37: 33.4925 | I37: -111.92301 | J37: 950 | K37: FRYERS CHOICE
A38: 4014 | B38: DIL- 4014 - DILLONS BAYOU | C38: 2 | D38: 2A | E38: 40202 N 87Th Ave | F38: Peoria | G38: AZ | H38: 33.852793 | I38: -112.24698 | J38: 450 | K38: FRYERS CHOICE BLEND | N38: 623-498-5427
A39: 4010 | B39: DIL59 - 4010 - DILLONS 59TH AVE | C39: 2 | D39: 2A | E39: 20585 N 59Th Ave | F39: Glendale | G39: AZ | H39: 33.67218 | I39: -112.18631 | J39: 500 | K39: FRYERS CHOICE BLEND | N39: 623-979-5353
A40: 4027 | B40: DIR - 4027 - DIRTWATER | C40: 5 | D40: 5E | E40: 586 W APACHE | F40: APACHE JUNCTION | G40: AZ | H40: 33.415492 | I40: -111.55237 | J40: 900 | K40: FRYERS CHOICE BLEND | N40: 480-983-3478
A41: 4029 | B41: DUR - 4029 - DURVILL FOODS | C41: 4 | D41: 4E | E41: DURVILL FOODS | F41: Phoenix | G41: AZ | H41: 33.406637 | I41: -112.01103 | J41: 2500 | K41: CANOLA OIL
A42: 5006 | B42: ECH - 5006 - ECHO 5 SPORTS BAR | C42: 5 | D42: 5D | E42: ECHO 5 SPORTS BAR | F42: Mesa | G42: AZ | H42: 33.468258 | I42: -111.68292 | J42: 450 | K42: FRYERS CHOICE BLEND | N42: 602-391-7707
A43: 5004 | B43: ELT - 5004 - EL TACO TOTE | C43: 3 | D43: 3D | E43: 3464 W Camelback Rd | F43: Phoenix | G43: AZ | H43: 33.509715 | I43: -112.13384 | J43: 500 | K43: CANOLA OIL | N43: 602-866-8683
A44: 5018 | B44: ENR - 5018 - ENROUTE COFFEE AND TEA | C44: 1 | D44: 1D | E44: 15605 W ROOSEVELT ST | F44: GOODYEAR | G44: AZ | H44: 33.456415 | I44: -112.39449 | J44: 350 | K44: CANOLA OIL | N44: (253) 359-7081
A45: 6101 | B45: FAT - 6101 - FATE BREWERY | C45: 4 | D45: 4D | E45: 1312 N SCOTTSDALE RD | F45: SCOTTSDALE | G45: AZ | H45: 33.462701 | I45: -111.92684 | J45: 700 | K45: CANOLA OIL | N45: 480-656-9100
A46: 6109 | B46: FAT - 6109 - FATE BREWING TEMPE | C46: 4 | D46: 4E | E46: 201 E SOUTHERN AVE | F46: TEMPE | G46: AZ | H46: 33.392382 | I46: -111.93649 | J46: 700 | K46: CANOLA OIL
A47: 6077 | B47: FOU - 6077 - FOUR PEAKS BREWING | C47: 4 | D47: 4E | E47: 1340 E 8Th St | F47: Tempe | G47: AZ | H47: 33.41968 | I47: -111.91592 | J47: 2500 | K47: FRYERS CHOICE BLEND | N47: 480-303-9967
A48: 12047 | B48: FUN - 12047 - FUNKY FRIDAS | C48: 3 | D48: 3C | E48: 4910 E Indian School Rd | F48: Phoenix | G48: AZ | H48: 33.494903 | I48: -111.97541 | J48: 630 | K48: CANOLA OIL | N48: (602) 955-0358
A49: 7001 | B49: GAR - 7001 - GARCIAS MEXICAN RESTAURANT | C49: 3 | D49: 3D | E49: 2212 N 35Th Ave | F49: Phoenix | G49: AZ | H49: 33.471653 | I49: -112.13482 | J49: 1850 | K49: CANOLA OIL | N49: 602-272-5584
A50: 7002 | B50: GIL - 7002 - GILBERT PIZZA | C50: 5 | D50: 5F | E50: GILBERT PIZZA | F50: Gilbert | G50: AZ | H50: 33.328977 | I50: -111.79051 | J50: 480 | K50: FRYERS CHOICE BLEND | N50: 999-999-9999
...

Sheet Optimizer_Input
B1: S&K OIL SALES — OPTIMIZER INPUT (all calculations auto-update from Delivery_Log)
B2: Min Oil % | C2: 0.15 | D2: Visit Window (days) | E2: 7 | F2: Shift Min | G2: 600 | H2: Svc Min/Stop | I2: 20 | O2: # of Deliveries since: | Q2: 46023
B3: ■ Red=Critical(≤2d) ■ Amber=Urgent(3–5d) ■ Green=Normal(6–7d) ■ Grey=Not needed │ Blue italic = live formula pulling from Delivery_Log
B4: CLIENT & LOCATION | G4: TANK & CONSUMPTION | J4: LAST DELIVERY ← from log | L4: CALCULATED
A5: Num. | B5: ID | C5: Customer | D5: Zone | E5: Address | F5: Lat / Lon | G5: Tank (lbs) | H5: Last Per Day Cons (lbs/day) | I5: Product | J5: Last Delivery | K5: Days Since | L5: Est. Current (lbs) | M5: Refill (lbs) | N5: Days Until Empty | O5: Next Delivery By: | P5: ="Next "&E2& " Days?" | Q5: ="# Deliveries since "& TEXT(Q2,"mm/dd/yyyy") | R5: Notes
A6: 1 | B6: 0001 | C6: 51ST - 0001 - 51ST AVE CAFE | D6: 2 | E6: =IFERROR(VLOOKUP(C6,Client_List!$B:$K,4,0)&", "&VLOOKUP(C6,Client_List!$B:$K,5,0)&" AZ","") | F6: =IFERROR(VLOOKUP(C6,Client_List!$B:$K,7,0)&", "&VLOOKUP(C6,Client_List!$B:$K,8,0),"") | G6: =IFERROR(VLOOKUP(C6,Client_List!$B:$K,9,0),"") | H6: =IFERROR(LOOKUP(2,1/((Delivery_Log!$B$4:$B$4998=VALUE(B6))*(ISNUMBER(Delivery_Log!$J$4:$J$4998))*(Delivery_Log!$J$4:$J$4998>0)),Delivery_Log!$J$4:$J$4998),"") | I6: =IFERROR(VLOOKUP(C6,Client_List!$B:$K,10,0),"") | J6: =IFERROR(_xlfn.MAXIFS(Delivery_Log!$A$4:$A$4998,Delivery_Log!$B$4:$B$4998,VALUE(B6)),"—") | K6: =IFERROR(IF(J6="—","",TODAY()-J6),"") | L6: =IFERROR(IF(OR(K6="",H6=""),"",MAX(G6*0.03,G6-K6*H6)),"") | M6: =IFERROR(IF(L6="","",G6-L6),"") | N6: =IFERROR(IF(OR(L6="",H6=""),"",MIN(21,MAX(0,(L6-G6*$C$2)/H6))),"") | O6: =TODAY()+ROUNDUP(N6,0) | P6: =IFERROR(IF(N6="","—",IF(N6<=$E$2,"YES","—")),"—") | Q6: =COUNTIFS(Delivery_Log!$B$4:$B$5998,VALUE(B6),Delivery_Log!$A$4:$A$5998,">="&$Q$2)
A7: 2 | B7: 1018 | C7: AJO - 1018 - AJO ALS BELL | D7: 2 | E7: =IFERROR(VLOOKUP(C7,Client_List!$B:$K,4,0)&", "&VLOOKUP(C7,Client_List!$B:$K,5,0)&" AZ","") | F7: =IFERROR(VLOOKUP(C7,Client_List!$B:$K,7,0)&", "&VLOOKUP(C7,Client_List!$B:$K,8,0),"") | G7: =IFERROR(VLOOKUP(C7,Client_List!$B:$K,9,0),"") | H7: =IFERROR(LOOKUP(2,1/((Delivery_Log!$B$4:$B$4998=VALUE(B7))*(ISNUMBER(Delivery_Log!$J$4:$J$4998))*(Delivery_Log!$J$4:$J$4998>0)),Delivery_Log!$J$4:$J$4998),"") | I7: =IFERROR(VLOOKUP(C7,Client_List!$B:$K,10,0),"") | J7: =IFERROR(_xlfn.MAXIFS(Delivery_Log!$A$4:$A$4998,Delivery_Log!$B$4:$B$4998,VALUE(B7)),"—") | K7: =IFERROR(IF(J7="—","",TODAY()-J7),"") | L7: =IFERROR(IF(OR(K7="",H7=""),"",MAX(G7*0.03,G7-K7*H7)),"") | M7: =IFERROR(IF(L7="","",G7-L7),"") | N7: =IFERROR(IF(OR(L7="",H7=""),"",MIN(21,MAX(0,(L7-G7*$C$2)/H7))),"") | O7: =TODAY()+ROUNDUP(N7,0) | P7: =IFERROR(IF(N7="","—",IF(N7<=$E$2,"YES","—")),"—") | Q7: =COUNTIFS(Delivery_Log!$B$4:$B$5998,VALUE(B7),Delivery_Log!$A$4:$A$5998,">="&$Q$2)
A8: 3 | B8: 1063 | C8: ALL - 1063 - ALL AMERICAN MODERN SPORTS GRILL | D8: 4 | E8: =IFERROR(VLOOKUP(C8,Client_List!$B:$K,4,0)&", "&VLOOKUP(C8,Client_List!$B:$K,5,0)&" AZ","") | F8: =IFERROR(VLOOKUP(C8,Client_List!$B:$K,7,0)&", "&VLOOKUP(C8,Client_List!$B:$K,8,0),"") | G8: =IFERROR(VLOOKUP(C8,Client_List!$B:$K,9,0),"") | H8: =IFERROR(LOOKUP(2,1/((Delivery_Log!$B$4:$B$4998=VALUE(B8))*(ISNUMBER(Delivery_Log!$J$4:$J$4998))*(Delivery_Log!$J$4:$J$4998>0)),Delivery_Log!$J$4:$J$4998),"") | I8: =IFERROR(VLOOKUP(C8,Client_List!$B:$K,10,0),"") | J8: =IFERROR(_xlfn.MAXIFS(Delivery_Log!$A$4:$A$4998,Delivery_Log!$B$4:$B$4998,VALUE(B8)),"—") | K8: =IFERROR(IF(J8="—","",TODAY()-J8),"") | L8: =IFERROR(IF(OR(K8="",H8=""),"",MAX(G8*0.03,G8-K8*H8)),"") | M8: =IFERROR(IF(L8="","",G8-L8),"") | N8: =IFERROR(IF(OR(L8="",H8=""),"",MIN(21,MAX(0,(L8-G8*$C$2)/H8))),"") | O8: =TODAY()+ROUNDUP(N8,0) | P8: =IFERROR(IF(N8="","—",IF(N8<=$E$2,"YES","—")),"—") | Q8: =COUNTIFS(Delivery_Log!$B$4:$B$5998,VALUE(B8),Delivery_Log!$A$4:$A$5998,">="&$Q$2)
A9: 4 | B9: 1073 | C9: AME - 1073 - AMELIO C ENTERPRISES, INC (CACTUS CANDY) | D9: 4 | E9: =IFERROR(VLOOKUP(C9,Client_List!$B:$K,4,0)&", "&VLOOKUP(C9,Client_List!$B:$K,5,0)&" AZ","") | F9: =IFERROR(VLOOKUP(C9,Client_List!$B:$K,7,0)&", "&VLOOKUP(C9,Client_List!$B:$K,8,0),"") | G9: =IFERROR(VLOOKUP(C9,Client_List!$B:$K,9,0),"") | H9: =IFERROR(LOOKUP(2,1/((Delivery_Log!$B$4:$B$4998=VALUE(B9))*(ISNUMBER(Delivery_Log!$J$4:$J$4998))*(Delivery_Log!$J$4:$J$4998>0)),Delivery_Log!$J$4:$J$4998),"") | I9: =IFERROR(VLOOKUP(C9,Client_List!$B:$K,10,0),"") | J9: =IFERROR(_xlfn.MAXIFS(Delivery_Log!$A$4:$A$4998,Delivery_Log!$B$4:$B$4998,VALUE(B9)),"—") | K9: =IFERROR(IF(J9="—","",TODAY()-J9),"") | L9: =IFERROR(IF(OR(K9="",H9=""),"",MAX(G9*0.03,G9-K9*H9)),"") | M9: =IFERROR(IF(L9="","",G9-L9),"") | N9: =IFERROR(IF(OR(L9="",H9=""),"",MIN(21,MAX(0,(L9-G9*$C$2)/H9))),"") | O9: =TODAY()+ROUNDUP(N9,0) | P9: =IFERROR(IF(N9="","—",IF(N9<=$E$2,"YES","—")),"—") | Q9: =COUNTIFS(Delivery_Log!$B$4:$B$5998,VALUE(B9),Delivery_Log!$A$4:$A$5998,">="&$Q$2)
A10: 5 | B10: 1054 | C10: ANG - 1054 - ANGRY CRAB SURPRISE | D10: 1 | E10: =IFERROR(VLOOKUP(C10,Client_List!$B:$K,4,0)&", "&VLOOKUP(C10,Client_List!$B:$K,5,0)&" AZ","") | F10: =IFERROR(VLOOKUP(C10,Client_List!$B:$K,7,0)&", "&VLOOKUP(C10,Client_List!$B:$K,8,0),"") | G10: =IFERROR(VLOOKUP(C10,Client_List!$B:$K,9,0),"") | H10: =IFERROR(LOOKUP(2,1/((Delivery_Log!$B$4:$B$4998=VALUE(B10))*(ISNUMBER(Delivery_Log!$J$4:$J$4998))*(Delivery_Log!$J$4:$J$4998>0)),Delivery_Log!$J$4:$J$4998),"") | I10: =IFERROR(VLOOKUP(C10,Client_List!$B:$K,10,0),"") | J10: =IFERROR(_xlfn.MAXIFS(Delivery_Log!$A$4:$A$4998,Delivery_Log!$B$4:$B$4998,VALUE(B10)),"—") | K10: =IFERROR(IF(J10="—","",TODAY()-J10),"") | L10: =IFERROR(IF(OR(K10="",H10=""),"",MAX(G10*0.03,G10-K10*H10)),"") | M10: =IFERROR(IF(L10="","",G10-L10),"") | N10: =IFERROR(IF(OR(L10="",H10=""),"",MIN(21,MAX(0,(L10-G10*$C$2)/H10))),"") | O10: =TODAY()+ROUNDUP(N10,0) | P10: =IFERROR(IF(N10="","—",IF(N10<=$E$2,"YES","—")),"—") | Q10: =COUNTIFS(Delivery_Log!$B$4:$B$5998,VALUE(B10),Delivery_Log!$A$4:$A$5998,">="&$Q$2)
A11: 6 | B11: 1000 | C11: ARR79 - 1000 - ARRIBAS 79TH AVE. | D11: 2 | E11: =IFERROR(VLOOKUP(C11,Client_List!$B:$K,4,0)&", "&VLOOKUP(C11,Client_List!$B:$K,5,0)&" AZ","") | F11: =IFERROR(VLOOKUP(C11,Client_List!$B:$K,7,0)&", "&VLOOKUP(C11,Client_List!$B:$K,8,0),"") | G11: =IFERROR(VLOOKUP(C11,Client_List!$B:$K,9,0),"") | H11: =IFERROR(LOOKUP(2,1/((Delivery_Log!$B$4:$B$4998=VALUE(B11))*(ISNUMBER(Delivery_Log!$J$4:$J$4998))*(Delivery_Log!$J$4:$J$4998>0)),Delivery_Log!$J$4:$J$4998),"") | I11: =IFERROR(VLOOKUP(C11,Client_List!$B:$K,10,0),"") | J11: =IFERROR(_xlfn.MAXIFS(Delivery_Log!$A$4:$A$4998,Delivery_Log!$B$4:$B$4998,VALUE(B11)),"—") | K11: =IFERROR(IF(J11="—","",TODAY()-J11),"") | L11: =IFERROR(IF(OR(K11="",H11=""),"",MAX(G11*0.03,G11-K11*H11)),"") | M11: =IFERROR(IF(L11="","",G11-L11),"") | N11: =IFERROR(IF(OR(L11="",H11=""),"",MIN(21,MAX(0,(L11-G11*$C$2)/H11))),"") | O11: =TODAY()+ROUNDUP(N11,0) | P11: =IFERROR(IF(N11="","—",IF(N11<=$E$2,"YES","—")),"—") | Q11: =COUNTIFS(Delivery_Log!$B$4:$B$5998,VALUE(B11),Delivery_Log!$A$4:$A$5998,">="&$Q$2)
A12: 7 | B12: 1001 | C12: ARRC - 1001 - ARRIBAS CAMELBACK | D12: 3 | E12: =IFERROR(VLOOKUP(C12,Client_List!$B:$K,4,0)&", "&VLOOKUP(C12,Client_List!$B:$K,5,0)&" AZ","") | F12: =IFERROR(VLOOKUP(C12,Client_List!$B:$K,7,0)&", "&VLOOKUP(C12,Client_List!$B:$K,8,0),"") | G12: =IFERROR(VLOOKUP(C12,Client_List!$B:$K,9,0),"") | H12: =IFERROR(LOOKUP(2,1/((Delivery_Log!$B$4:$B$4998=VALUE(B12))*(ISNUMBER(Delivery_Log!$J$4:$J$4998))*(Delivery_Log!$J$4:$J$4998>0)),Delivery_Log!$J$4:$J$4998),"") | I12: =IFERROR(VLOOKUP(C12,Client_List!$B:$K,10,0),"") | J12: =IFERROR(_xlfn.MAXIFS(Delivery_Log!$A$4:$A$4998,Delivery_Log!$B$4:$B$4998,VALUE(B12)),"—") | K12: =IFERROR(IF(J12="—","",TODAY()-J12),"") | L12: =IFERROR(IF(OR(K12="",H12=""),"",MAX(G12*0.03,G12-K12*H12)),"") | M12: =IFERROR(IF(L12="","",G12-L12),"") | N12: =IFERROR(IF(OR(L12="",H12=""),"",MIN(21,MAX(0,(L12-G12*$C$2)/H12))),"") | O12: =TODAY()+ROUNDUP(N12,0) | P12: =IFERROR(IF(N12="","—",IF(N12<=$E$2,"YES","—")),"—") | Q12: =COUNTIFS(Delivery_Log!$B$4:$B$5998,VALUE(B12),Delivery_Log!$A$4:$A$5998,">="&$Q$2)
A13: 8 | B13: 1011 | C13: ARRC - 1011 - ARRIBAS CHANDLER | D13: 4 | E13: =IFERROR(VLOOKUP(C13,Client_List!$B:$K,4,0)&", "&VLOOKUP(C13,Client_List!$B:$K,5,0)&" AZ","") | F13: =IFERROR(VLOOKUP(C13,Client_List!$B:$K,7,0)&", "&VLOOKUP(C13,Client_List!$B:$K,8,0),"") | G13: =IFERROR(VLOOKUP(C13,Client_List!$B:$K,9,0),"") | H13: =IFERROR(LOOKUP(2,1/((Delivery_Log!$B$4:$B$4998=VALUE(B13))*(ISNUMBER(Delivery_Log!$J$4:$J$4998))*(Delivery_Log!$J$4:$J$4998>0)),Delivery_Log!$J$4:$J$4998),"") | I13: =IFERROR(VLOOKUP(C13,Client_List!$B:$K,10,0),"") | J13: =IFERROR(_xlfn.MAXIFS(Delivery_Log!$A$4:$A$4998,Delivery_Log!$B$4:$B$4998,VALUE(B13)),"—") | K13: =IFERROR(IF(J13="—","",TODAY()-J13),"") | L13: =IFERROR(IF(OR(K13="",H13=""),"",MAX(G13*0.03,G13-K13*H13)),"") | M13: =IFERROR(IF(L13="","",G13-L13),"") | N13: =IFERROR(IF(OR(L13="",H13=""),"",MIN(21,MAX(0,(L13-G13*$C$2)/H13))),"") | O13: =TODAY()+ROUNDUP(N13,0) | P13: =IFERROR(IF(N13="","—",IF(N13<=$E$2,"YES","—")),"—") | Q13: =COUNTIFS(Delivery_Log!$B$4:$B$5998,VALUE(B13),Delivery_Log!$A$4:$A$5998,">="&$Q$2)
A14: 9 | B14: 1014 | C14: ARRC - 1014 - ARRIBA GILBERT | D14: 5 | E14: =IFERROR(VLOOKUP(C14,Client_List!$B:$K,4,0)&", "&VLOOKUP(C14,Client_List!$B:$K,5,0)&" AZ","") | F14: =IFERROR(VLOOKUP(C14,Client_List!$B:$K,7,0)&", "&VLOOKUP(C14,Client_List!$B:$K,8,0),"") | G14: =IFERROR(VLOOKUP(C14,Client_List!$B:$K,9,0),"") | H14: =IFERROR(LOOKUP(2,1/((Delivery_Log!$B$4:$B$4998=VALUE(B14))*(ISNUMBER(Delivery_Log!$J$4:$J$4998))*(Delivery_Log!$J$4:$J$4998>0)),Delivery_Log!$J$4:$J$4998),"") | I14: =IFERROR(VLOOKUP(C14,Client_List!$B:$K,10,0),"") | J14: =IFERROR(_xlfn.MAXIFS(Delivery_Log!$A$4:$A$4998,Delivery_Log!$B$4:$B$4998,VALUE(B14)),"—") | K14: =IFERROR(IF(J14="—","",TODAY()-J14),"") | L14: =IFERROR(IF(OR(K14="",H14=""),"",MAX(G14*0.03,G14-K14*H14)),"") | M14: =IFERROR(IF(L14="","",G14-L14),"") | N14: =IFERROR(IF(OR(L14="",H14=""),"",MIN(21,MAX(0,(L14-G14*$C$2)/H14))),"") | O14: =TODAY()+ROUNDUP(N14,0) | P14: =IFERROR(IF(N14="","—",IF(N14<=$E$2,"YES","—")),"—") | Q14: =COUNTIFS(Delivery_Log!$B$4:$B$5998,VALUE(B14),Delivery_Log!$A$4:$A$5998,">="&$Q$2)
A15: 10 | B15: 1013 | C15: ARRM - 1013 - ARRIBAS GOODYEAR | D15: 1 | E15: =IFERROR(VLOOKUP(C15,Client_List!$B:$K,4,0)&", "&VLOOKUP(C15,Client_List!$B:$K,5,0)&" AZ","") | F15: =IFERROR(VLOOKUP(C15,Client_List!$B:$K,7,0)&", "&VLOOKUP(C15,Client_List!$B:$K,8,0),"") | G15: =IFERROR(VLOOKUP(C15,Client_List!$B:$K,9,0),"") | H15: =IFERROR(LOOKUP(2,1/((Delivery_Log!$B$4:$B$4998=VALUE(B15))*(ISNUMBER(Delivery_Log!$J$4:$J$4998))*(Delivery_Log!$J$4:$J$4998>0)),Delivery_Log!$J$4:$J$4998),"") | I15: =IFERROR(VLOOKUP(C15,Client_List!$B:$K,10,0),"") | J15: =IFERROR(_xlfn.MAXIFS(Delivery_Log!$A$4:$A$4998,Delivery_Log!$B$4:$B$4998,VALUE(B15)),"—") | K15: =IFERROR(IF(J15="—","",TODAY()-J15),"") | L15: =IFERROR(IF(OR(K15="",H15=""),"",MAX(G15*0.03,G15-K15*H15)),"") | M15: =IFERROR(IF(L15="","",G15-L15),"") | N15: =IFERROR(IF(OR(L15="",H15=""),"",MIN(21,MAX(0,(L15-G15*$C$2)/H15))),"") | O15: =TODAY()+ROUNDUP(N15,0) | P15: =IFERROR(IF(N15="","—",IF(N15<=$E$2,"YES","—")),"—") | Q15: =COUNTIFS(Delivery_Log!$B$4:$B$5998,VALUE(B15),Delivery_Log!$A$4:$A$5998,">="&$Q$2)
A16: 11 | B16: 1081 | C16: ATL - 1081 - ATL WINGS ROOSEVELT | D16: 3 | E16: =IFERROR(VLOOKUP(C16,Client_List!$B:$K,4,0)&", "&VLOOKUP(C16,Client_List!$B:$K,5,0)&" AZ","") | F16: =IFERROR(VLOOKUP(C16,Client_List!$B:$K,7,0)&", "&VLOOKUP(C16,Client_List!$B:$K,8,0),"") | G16: =IFERROR(VLOOKUP(C16,Client_List!$B:$K,9,0),"") | H16: =IFERROR(LOOKUP(2,1/((Delivery_Log!$B$4:$B$4998=VALUE(B16))*(ISNUMBER(Delivery_Log!$J$4:$J$4998))*(Delivery_Log!$J$4:$J$4998>0)),Delivery_Log!$J$4:$J$4998),"") | I16: =IFERROR(VLOOKUP(C16,Client_List!$B:$K,10,0),"") | J16: =IFERROR(_xlfn.MAXIFS(Delivery_Log!$A$4:$A$4998,Delivery_Log!$B$4:$B$4998,VALUE(B16)),"—") | K16: =IFERROR(IF(J16="—","",TODAY()-J16),"") | L16: =IFERROR(IF(OR(K16="",H16=""),"",MAX(G16*0.03,G16-K16*H16)),"") | M16: =IFERROR(IF(L16="","",G16-L16),"") | N16: =IFERROR(IF(OR(L16="",H16=""),"",MIN(21,MAX(0,(L16-G16*$C$2)/H16))),"") | O16: =TODAY()+ROUNDUP(N16,0) | P16: =IFERROR(IF(N16="","—",IF(N16<=$E$2,"YES","—")),"—") | Q16: =COUNTIFS(Delivery_Log!$B$4:$B$5998,VALUE(B16),Delivery_Log!$A$4:$A$5998,">="&$Q$2)
A17: 12 | B17: 1083 | C17: ATL - 1083 - ATL WINGS MESA | D17: 5 | E17: =IFERROR(VLOOKUP(C17,Client_List!$B:$K,4,0)&", "&VLOOKUP(C17,Client_List!$B:$K,5,0)&" AZ","") | F17: =IFERROR(VLOOKUP(C17,Client_List!$B:$K,7,0)&", "&VLOOKUP(C17,Client_List!$B:$K,8,0),"") | G17: =IFERROR(VLOOKUP(C17,Client_List!$B:$K,9,0),"") | H17: =IFERROR(LOOKUP(2,1/((Delivery_Log!$B$4:$B$4998=VALUE(B17))*(ISNUMBER(Delivery_Log!$J$4:$J$4998))*(Delivery_Log!$J$4:$J$4998>0)),Delivery_Log!$J$4:$J$4998),"") | I17: =IFERROR(VLOOKUP(C17,Client_List!$B:$K,10,0),"") | J17: =IFERROR(_xlfn.MAXIFS(Delivery_Log!$A$4:$A$4998,Delivery_Log!$B$4:$B$4998,VALUE(B17)),"—") | K17: =IFERROR(IF(J17="—","",TODAY()-J17),"") | L17: =IFERROR(IF(OR(K17="",H17=""),"",MAX(G17*0.03,G17-K17*H17)),"") | M17: =IFERROR(IF(L17="","",G17-L17),"") | N17: =IFERROR(IF(OR(L17="",H17=""),"",MIN(21,MAX(0,(L17-G17*$C$2)/H17))),"") | O17: =TODAY()+ROUNDUP(N17,0) | P17: =IFERROR(IF(N17="","—",IF(N17<=$E$2,"YES","—")),"—") | Q17: =COUNTIFS(Delivery_Log!$B$4:$B$5998,VALUE(B17),Delivery_Log!$A$4:$A$5998,">="&$Q$2)
A18: 13 | B18: 19039 | C18: BAC - 19039 - BACKYARD GILBERT | D18: 5 | E18: =IFERROR(VLOOKUP(C18,Client_List!$B:$K,4,0)&", "&VLOOKUP(C18,Client_List!$B:$K,5,0)&" AZ","") | F18: =IFERROR(VLOOKUP(C18,Client_List!$B:$K,7,0)&", "&VLOOKUP(C18,Client_List!$B:$K,8,0),"") | G18: =IFERROR(VLOOKUP(C18,Client_List!$B:$K,9,0),"") | H18: =IFERROR(LOOKUP(2,1/((Delivery_Log!$B$4:$B$4998=VALUE(B18))*(ISNUMBER(Delivery_Log!$J$4:$J$4998))*(Delivery_Log!$J$4:$J$4998>0)),Delivery_Log!$J$4:$J$4998),"") | I18: =IFERROR(VLOOKUP(C18,Client_List!$B:$K,10,0),"") | J18: =IFERROR(_xlfn.MAXIFS(Delivery_Log!$A$4:$A$4998,Delivery_Log!$B$4:$B$4998,VALUE(B18)),"—") | K18: =IFERROR(IF(J18="—","",TODAY()-J18),"") | L18: =IFERROR(IF(OR(K18="",H18=""),"",MAX(G18*0.03,G18-K18*H18)),"") | M18: =IFERROR(IF(L18="","",G18-L18),"") | N18: =IFERROR(IF(OR(L18="",H18=""),"",MIN(21,MAX(0,(L18-G18*$C$2)/H18))),"") | O18: =TODAY()+ROUNDUP(N18,0) | P18: =IFERROR(IF(N18="","—",IF(N18<=$E$2,"YES","—")),"—") | Q18: =COUNTIFS(Delivery_Log!$B$4:$B$5998,VALUE(B18),Delivery_Log!$A$4:$A$5998,">="&$Q$2)
... A33: 28 | B33: 3064 | C33: CRO - 3064 - CROWNE PLAZA RESORT | D33: 4 | E33: =IFERROR(VLOOKUP(C33,Client_List!$B:$K,4,0)&", "&VLOOKUP(C33,Client_List!$B:$K,5,0)&" AZ","") | F33: =IFERROR(VLOOKUP(C33,Client_List!$B:$K,7,0)&", "&VLOOKUP(C33,Client_List!$B:$K,8,0),"") | G33: =IFERROR(VLOOKUP(C33,Client_List!$B:$K,9,0),"") | H33: =IFERROR(LOOKUP(2,1/((Delivery_Log!$B$4:$B$4998=VALUE(B33))*(ISNUMBER(Delivery_Log!$J$4:$J$4998))*(Delivery_Log!$J$4:$J$4998>0)),Delivery_Log!$J$4:$J$4998),"") | I33: =IFERROR(VLOOKUP(C33,Client_List!$B:$K,10,0),"") | J33: =IFERROR(_xlfn.MAXIFS(Delivery_Log!$A$4:$A$4998,Delivery_Log!$B$4:$B$4998,VALUE(B33)),"—") | K33: =IFERROR(IF(J33="—","",TODAY()-J33),"") | L33: =IFERROR(IF(OR(K33="",H33=""),"",MAX(G33*0.03,G33-K33*H33)),"") | M33: =IFERROR(IF(L33="","",G33-L33),"") | N33: =IFERROR(IF(OR(L33="",H33=""),"",MIN(21,MAX(0,(L33-G33*$C$2)/H33))),"") | O33: =TODAY()+ROUNDUP(N33,0) | P33: =IFERROR(IF(N33="","—",IF(N33<=$E$2,"YES","—")),"—") | Q33: =COUNTIFS(Delivery_Log!$B$4:$B$5998,VALUE(B33),Delivery_Log!$A$4:$A$5998,">="&$Q$2)
A34: 29 | B34: 4015A | C34: DAI - 4015A - DAIRY QUEEN BELL | D34: 3 | E34: =IFERROR(VLOOKUP(C34,Client_List!$B:$K,4,0)&", "&VLOOKUP(C34,Client_List!$B:$K,5,0)&" AZ","") | F34: =IFERROR(VLOOKUP(C34,Client_List!$B:$K,7,0)&", "&VLOOKUP(C34,Client_List!$B:$K,8,0),"") | G34: =IFERROR(VLOOKUP(C34,Client_List!$B:$K,9,0),"") | H34: =IFERROR(LOOKUP(2,1/((Delivery_Log!$B$4:$B$4998=VALUE(B34))*(ISNUMBER(Delivery_Log!$J$4:$J$4998))*(Delivery_Log!$J$4:$J$4998>0)),Delivery_Log!$J$4:$J$4998),"") | I34: =IFERROR(VLOOKUP(C34,Client_List!$B:$K,10,0),"") | J34: =IFERROR(_xlfn.MAXIFS(Delivery_Log!$A$4:$A$4998,Delivery_Log!$B$4:$B$4998,VALUE(B34)),"—") | K34: =IFERROR(IF(J34="—","",TODAY()-J34),"") | L34: =IFERROR(IF(OR(K34="",H34=""),"",MAX(G34*0.03,G34-K34*H34)),"") | M34: =IFERROR(IF(L34="","",G34-L34),"") | N34: =IFERROR(IF(OR(L34="",H34=""),"",MIN(21,MAX(0,(L34-G34*$C$2)/H34))),"") | O34: =TODAY()+ROUNDUP(N34,0) | P34: =IFERROR(IF(N34="","—",IF(N34<=$E$2,"YES","—")),"—") | Q34: =COUNTIFS(Delivery_Log!$B$4:$B$5998,VALUE(B34),Delivery_Log!$A$4:$A$5998,">="&$Q$2)
A35: 30 | B35: 4026 | C35: DAR - 4026 - DARUMA BY RIE | D35: 4 | E35: =IFERROR(VLOOKUP(C35,Client_List!$B:$K,4,0)&", "&VLOOKUP(C35,Client_List!$B:$K,5,0)&" AZ","") | F35: =IFERROR(VLOOKUP(C35,Client_List!$B:$K,7,0)&", "&VLOOKUP(C35,Client_List!$B:$K,8,0),"") | G35: =IFERROR(VLOOKUP(C35,Client_List!$B:$K,9,0),"") | H35: =IFERROR(LOOKUP(2,1/((Delivery_Log!$B$4:$B$4998=VALUE(B35))*(ISNUMBER(Delivery_Log!$J$4:$J$4998))*(Delivery_Log!$J$4:$J$4998>0)),Delivery_Log!$J$4:$J$4998),"") | I35: =IFERROR(VLOOKUP(C35,Client_List!$B:$K,10,0),"") | J35: =IFERROR(_xlfn.MAXIFS(Delivery_Log!$A$4:$A$4998,Delivery_Log!$B$4:$B$4998,VALUE(B35)),"—") | K35: =IFERROR(IF(J35="—","",TODAY()-J35),"") | L35: =IFERROR(IF(OR(K35="",H35=""),"",MAX(G35*0.03,G35-K35*H35)),"") | M35: =IFERROR(IF(L35="","",G35-L35),"") | N35: =IFERROR(IF(OR(L35="",H35=""),"",MIN(21,MAX(0,(L35-G35*$C$2)/H35))),"") | O35: =TODAY()+ROUNDUP(N35,0) | P35: =IFERROR(IF(N35="","—",IF(N35<=$E$2,"YES","—")),"—") | Q35: =COUNTIFS(Delivery_Log!$B$4:$B$5998,VALUE(B35),Delivery_Log!$A$4:$A$5998,">="&$Q$2)
A36: 31 | B36: 4037 | C36: DAR - 4037 - DARUMA RAMEN AND BOWL | D36: 4 | E36: =IFERROR(VLOOKUP(C36,Client_List!$B:$K,4,0)&", "&VLOOKUP(C36,Client_List!$B:$K,5,0)&" AZ","") | F36: =IFERROR(VLOOKUP(C36,Client_List!$B:$K,7,0)&", "&VLOOKUP(C36,Client_List!$B:$K,8,0),"") | G36: =IFERROR(VLOOKUP(C36,Client_List!$B:$K,9,0),"") | H36: =IFERROR(LOOKUP(2,1/((Delivery_Log!$B$4:$B$4998=VALUE(B36))*(ISNUMBER(Delivery_Log!$J$4:$J$4998))*(Delivery_Log!$J$4:$J$4998>0)),Delivery_Log!$J$4:$J$4998),"") | I36: =IFERROR(VLOOKUP(C36,Client_List!$B:$K,10,0),"") | J36: =IFERROR(_xlfn.MAXIFS(Delivery_Log!$A$4:$A$4998,Delivery_Log!$B$4:$B$4998,VALUE(B36)),"—") | K36: =IFERROR(IF(J36="—","",TODAY()-J36),"") | L36: =IFERROR(IF(OR(K36="",H36=""),"",MAX(G36*0.03,G36-K36*H36)),"") | M36: =IFERROR(IF(L36="","",G36-L36),"") | N36: =IFERROR(IF(OR(L36="",H36=""),"",MIN(21,MAX(0,(L36-G36*$C$2)/H36))),"") | O36: =TODAY()+ROUNDUP(N36,0) | P36: =IFERROR(IF(N36="","—",IF(N36<=$E$2,"YES","—")),"—") | Q36: =COUNTIFS(Delivery_Log!$B$4:$B$5998,VALUE(B36),Delivery_Log!$A$4:$A$5998,">="&$Q$2)
A37: 32 | B37: 4009 | C37: DIL - 4009 - DILLONS BBQ | D37: 1 | E37: =IFERROR(VLOOKUP(C37,Client_List!$B:$K,4,0)&", "&VLOOKUP(C37,Client_List!$B:$K,5,0)&" AZ","") | F37: =IFERROR(VLOOKUP(C37,Client_List!$B:$K,7,0)&", "&VLOOKUP(C37,Client_List!$B:$K,8,0),"") | G37: =IFERROR(VLOOKUP(C37,Client_List!$B:$K,9,0),"") | H37: =IFERROR(LOOKUP(2,1/((Delivery_Log!$B$4:$B$4998=VALUE(B37))*(ISNUMBER(Delivery_Log!$J$4:$J$4998))*(Delivery_Log!$J$4:$J$4998>0)),Delivery_Log!$J$4:$J$4998),"") | I37: =IFERROR(VLOOKUP(C37,Client_List!$B:$K,10,0),"") | J37: =IFERROR(_xlfn.MAXIFS(Delivery_Log!$A$4:$A$4998,Delivery_Log!$B$4:$B$4998,VALUE(B37)),"—") | K37: =IFERROR(IF(J37="—","",TODAY()-J37),"") | L37: =IFERROR(IF(OR(K37="",H37=""),"",MAX(G37*0.03,G37-K37*H37)),"") | M37: =IFERROR(IF(L37="","",G37-L37),"") | N37: =IFERROR(IF(OR(L37="",H37=""),"",MIN(21,MAX(0,(L37-G37*$C$2)/H37))),"") | O37: =TODAY()+ROUNDUP(N37,0) | P37: =IFERROR(IF(N37="","—",IF(N37<=$E$2,"YES","—")),"—") | Q37: =COUNTIFS(Delivery_Log!$B$4:$B$5998,VALUE(B37),Delivery_Log!$A$4:$A$5998,">="&$Q$2)
A38: 33 | B38: 4025 | C38: DIL - 4025 - DILLON WESTERN TRAILS | D38: 1 | E38: =IFERROR(VLOOKUP(C38,Client_List!$B:$K,4,0)&", "&VLOOKUP(C38,Client_List!$B:$K,5,0)&" AZ","") | F38: =IFERROR(VLOOKUP(C38,Client_List!$B:$K,7,0)&", "&VLOOKUP(C38,Client_List!$B:$K,8,0),"") | G38: =IFERROR(VLOOKUP(C38,Client_List!$B:$K,9,0),"") | H38: =IFERROR(LOOKUP(2,1/((Delivery_Log!$B$4:$B$4998=VALUE(B38))*(ISNUMBER(Delivery_Log!$J$4:$J$4998))*(Delivery_Log!$J$4:$J$4998>0)),Delivery_Log!$J$4:$J$4998),"") | I38: =IFERROR(VLOOKUP(C38,Client_List!$B:$K,10,0),"") | J38: =IFERROR(_xlfn.MAXIFS(Delivery_Log!$A$4:$A$4998,Delivery_Log!$B$4:$B$4998,VALUE(B38)),"—") | K38: =IFERROR(IF(J38="—","",TODAY()-J38),"") | L38: =IFERROR(IF(OR(K38="",H38=""),"",MAX(G38*0.03,G38-K38*H38)),"") | M38: =IFERROR(IF(L38="","",G38-L38),"") | N38: =IFERROR(IF(OR(L38="",H38=""),"",MIN(21,MAX(0,(L38-G38*$C$2)/H38))),"") | O38: =TODAY()+ROUNDUP(N38,0) | P38: =IFERROR(IF(N38="","—",IF(N38<=$E$2,"YES","—")),"—") | Q38: =COUNTIFS(Delivery_Log!$B$4:$B$5998,VALUE(B38),Delivery_Log!$A$4:$A$5998,">="&$Q$2)
A39: 34 | B39: 4014 | C39: DIL- 4014 - DILLONS BAYOU | D39: 2 | E39: =IFERROR(VLOOKUP(C39,Client_List!$B:$K,4,0)&", "&VLOOKUP(C39,Client_List!$B:$K,5,0)&" AZ","") | F39: =IFERROR(VLOOKUP(C39,Client_List!$B:$K,7,0)&", "&VLOOKUP(C39,Client_List!$B:$K,8,0),"") | G39: =IFERROR(VLOOKUP(C39,Client_List!$B:$K,9,0),"") | H39: =IFERROR(LOOKUP(2,1/((Delivery_Log!$B$4:$B$4998=VALUE(B39))*(ISNUMBER(Delivery_Log!$J$4:$J$4998))*(Delivery_Log!$J$4:$J$4998>0)),Delivery_Log!$J$4:$J$4998),"") | I39: =IFERROR(VLOOKUP(C39,Client_List!$B:$K,10,0),"") | J39: =IFERROR(_xlfn.MAXIFS(Delivery_Log!$A$4:$A$4998,Delivery_Log!$B$4:$B$4998,VALUE(B39)),"—") | K39: =IFERROR(IF(J39="—","",TODAY()-J39),"") | L39: =IFERROR(IF(OR(K39="",H39=""),"",MAX(G39*0.03,G39-K39*H39)),"") | M39: =IFERROR(IF(L39="","",G39-L39),"") | N39: =IFERROR(IF(OR(L39="",H39=""),"",MIN(21,MAX(0,(L39-G39*$C$2)/H39))),"") | O39: =TODAY()+ROUNDUP(N39,0) | P39: =IFERROR(IF(N39="","—",IF(N39<=$E$2,"YES","—")),"—") | Q39: =COUNTIFS(Delivery_Log!$B$4:$B$5998,VALUE(B39),Delivery_Log!$A$4:$A$5998,">="&$Q$2)
A40: 35 | B40: 4010 | C40: DIL59 - 4010 - DILLONS 59TH AVE | D40: 2 | E40: =IFERROR(VLOOKUP(C40,Client_List!$B:$K,4,0)&", "&VLOOKUP(C40,Client_List!$B:$K,5,0)&" AZ","") | F40: =IFERROR(VLOOKUP(C40,Client_List!$B:$K,7,0)&", "&VLOOKUP(C40,Client_List!$B:$K,8,0),"") | G40: =IFERROR(VLOOKUP(C40,Client_List!$B:$K,9,0),"") | H40: =IFERROR(LOOKUP(2,1/((Delivery_Log!$B$4:$B$4998=VALUE(B40))*(ISNUMBER(Delivery_Log!$J$4:$J$4998))*(Delivery_Log!$J$4:$J$4998>0)),Delivery_Log!$J$4:$J$4998),"") | I40: =IFERROR(VLOOKUP(C40,Client_List!$B:$K,10,0),"") | J40: =IFERROR(_xlfn.MAXIFS(Delivery_Log!$A$4:$A$4998,Delivery_Log!$B$4:$B$4998,VALUE(B40)),"—") | K40: =IFERROR(IF(J40="—","",TODAY()-J40),"") | L40: =IFERROR(IF(OR(K40="",H40=""),"",MAX(G40*0.03,G40-K40*H40)),"") | M40: =IFERROR(IF(L40="","",G40-L40),"") | N40: =IFERROR(IF(OR(L40="",H40=""),"",MIN(21,MAX(0,(L40-G40*$C$2)/H40))),"") | O40: =TODAY()+ROUNDUP(N40,0) | P40: =IFERROR(IF(N40="","—",IF(N40<=$E$2,"YES","—")),"—") | Q40: =COUNTIFS(Delivery_Log!$B$4:$B$5998,VALUE(B40),Delivery_Log!$A$4:$A$5998,">="&$Q$2)
A41: 36 | B41: 4027 | C41: DIR - 4027 - DIRTWATER | D41: 5 | E41: =IFERROR(VLOOKUP(C41,Client_List!$B:$K,4,0)&", "&VLOOKUP(C41,Client_List!$B:$K,5,0)&" AZ","") | F41: =IFERROR(VLOOKUP(C41,Client_List!$B:$K,7,0)&", "&VLOOKUP(C41,Client_List!$B:$K,8,0),"") | G41: =IFERROR(VLOOKUP(C41,Client_List!$B:$K,9,0),"") | H41: =IFERROR(LOOKUP(2,1/((Delivery_Log!$B$4:$B$4998=VALUE(B41))*(ISNUMBER(Delivery_Log!$J$4:$J$4998))*(Delivery_Log!$J$4:$J$4998>0)),Delivery_Log!$J$4:$J$4998),"") | I41: =IFERROR(VLOOKUP(C41,Client_List!$B:$K,10,0),"") | J41: =IFERROR(_xlfn.MAXIFS(Delivery_Log!$A$4:$A$4998,Delivery_Log!$B$4:$B$4998,VALUE(B41)),"—") | K41: =IFERROR(IF(J41="—","",TODAY()-J41),"") | L41: =IFERROR(IF(OR(K41="",H41=""),"",MAX(G41*0.03,G41-K41*H41)),"") | M41: =IFERROR(IF(L41="","",G41-L41),"") | N41: =IFERROR(IF(OR(L41="",H41=""),"",MIN(21,MAX(0,(L41-G41*$C$2)/H41))),"") | O41: =TODAY()+ROUNDUP(N41,0) | P41: =IFERROR(IF(N41="","—",IF(N41<=$E$2,"YES","—")),"—") | Q41: =COUNTIFS(Delivery_Log!$B$4:$B$5998,VALUE(B41),Delivery_Log!$A$4:$A$5998,">="&$Q$2)
